2020-12-07 13:59:52,501 - callbacks - DEBUG - {'measurement_time': [6903605414043125760, 6903605414906414080, 6903605415804061696, 6903605416620105728, 6903605417483394048, 6903605418342387712, 6903605419197085696, 6903605420060374016, 6903605420927958016, 6903605421915800576, 6903605422641649664, 6903605423496348672, 6903605424359636992, 6903605425214334976, 6903605426073328640, 6903605426936616960, 6903605427795610624, 6903605428658898944, 6903605429513597952, 6903605430376886272, 6903605431235878912, 6903605432133527552, 6903605432953866240, 6903605433821449216, 6903605434667557888, 6903605435526551552, 6903605436389839872, 6903605437291783168, 6903605438107827200, 6903605438962525184, 6903605439821518848, 6903605440684807168, 6903605441543800832, 6903605442445744128, 6903605443274673152, 6903605444116486144, 6903605444975479808, 6903605445838768128, 6903605446697761792, 6903605447556755456, 6903605448591842304, 6903605449274741760, 6903605450129440768, 6903605450992729088, 6903605451856017408, 6903605452706420736, 6903605453621249024, 6903605454428702720, 6903605455287696384, 6903605456146690048, 6903605457005682688, 6903605457860381696, 6903605458753734656, 6903605459578369024, 6903605460441657344, 6903605461300649984, 6903605462155348992, 6903605463018637312, 6903605463920580608, 6903605464732328960, 6903605465591322624, 6903605466454610944, 6903605467309309952, 6903605468172598272, 6903605469061656576, 6903605470053793792, 6903605470749578240, 6903605471604277248, 6903605472467565568, 6903605473317968896, 6903605474185551872, 6903605475066020864, 6903605475903539200, 6903605476762532864, 6903605477617230848, 6903605478476224512, 6903605479339512832, 6903605480245750784, 6903605481057500160, 6903605481916493824, 6903605482775486464, 6903605483630185472, 6903605484493473792, 6903605485369647104, 6903605486207165440, 6903605487066159104, 6903605487925152768, 6903605488784146432, 6903605489643140096, 6903605490515017728, 6903605491524335616, 6903605492220120064, 6903605493079113728, 6903605493942402048, 6903605494797100032, 6903605495656093696, 6903605496536561664, 6903605497374081024, 6903605498237369344, 6903605499092067328, 6903605499951060992, 6903605500814349312, 6903605501716292608, 6903605502523746304, 6903605503387034624, 6903605504246028288, 6903605505105021952, 6903605505959719936, 6903605506853073920, 6903605507677707264, 6903605508536700928, 6903605509399989248, 6903605510258982912, 6903605511117976576, 6903605512032803840, 6903605512960517120, 6903605513694956544, 6903605514549654528, 6903605515412943872, 6903605516271936512, 6903605517130930176, 6903605518075823104, 6903605518844621824, 6903605519703615488, 6903605520566903808, 6903605521425897472, 6903605522284891136, 6903605523156769792, 6903605524002878464, 6903605524857576448, 6903605525720864768, 6903605526575563776, 6903605527438852096, 6903605528345090048, 6903605529156838400, 6903605530015832064, 6903605530874825728, 6903605531729523712, 6903605532592813056, 6903605533456101376, 6903605534306504704, 6903605535165498368, 6903605536028786688, 6903605536883484672, 6903605537746772992, 6903605538653010944, 6903605539640853504, 6903605540319458304, 6903605541182747648, 6903605542037445632, 6903605542896439296, 6903605543755432960, 6903605544653080576, 6903605545473419264, 6903605546336707584, 6903605547195701248, 6903605548050400256, 6903605548913688576, 6903605549824221184, 6903605550631674880, 6903605551490668544, 6903605552345367552, 6903605553208655872, 6903605554067649536, 6903605554961002496, 6903605555781341184, 6903605556644629504, 6903605557503623168, 6903605558362616832, 6903605559221609472, 6903605560132143104, 6903605561077036032, 6903605561807179776, 6903605562666173440, 6903605563520872448, 6903605564379865088, 6903605565243154432, 6903605566145096704, 6903605566956846080, 6903605567820134400, 6903605568679128064, 6903605569533826048, 6903605570397114368, 6903605571260402688, 6903605572110807040, 6903605572969799680, 6903605573833089024, 6903605574687787008, 6903605575546780672, 6903605576457313280, 6903605577269062656, 6903605578123760640, 6903605578987048960, 6903605579846042624, 6903605580705036288, 6903605581568324608, 6903605582556167168, 6903605583277721600, 6903605584141009920, 6903605584995708928, 6903605585854701568, 6903605586717990912, 6903605587624228864, 6903605588431682560, 6903605589294970880, 6903605590153964544, 6903605591008662528, 6903605591871950848, 6903605592765304832, 6903605593585643520, 6903605594444636160, 6903605595307925504, 6903605596166918144, 6903605597025911808, 6903605597936445440, 6903605598739603456, 6903605599602892800, 6903605600457590784, 6903605601316584448, 6903605602179872768, 6903605603077520384, 6903605603988054016, 6903605604752558080, 6903605605615846400, 6903605606474840064, 6903605607333833728, 6903605608192827392, 6903605609167784960, 6903605609906519040, 6903605610769807360, 6903605611624505344, 6903605612487794688, 6903605613342492672, 6903605614257320960, 6903605615060480000, 6903605615919472640, 6903605616778466304, 6903605617641754624, 6903605618500748288, 6903605619398396928, 6903605620218735616, 6903605621073433600, 6903605621936721920, 6903605622791420928, 6903605623654709248, 6903605624556652544, 6903605625372696576, 6903605626231689216, 6903605627086388224, 6903605627949676544, 6903605628808670208, 6903605629697728512, 6903605630621146112, 6903605631381355520, 6903605632244643840, 6903605633103637504, 6903605633958335488, 6903605634821623808, 6903605635693502464, 6903605636531020800, 6903605637390014464, 6903605638249008128, 6903605639112296448, 6903605639975584768, 6903605640886118400, 6903605641689276416, 6903605642543975424, 6903605643402969088, 6903605644266257408, 6903605645125251072, 6903605646005719040, 6903605646838942720, 6903605647702231040, 6903605648561224704, 6903605649415922688, 6903605650274916352, 6903605651176859648, 6903605652104572928, 6903605652851897344, 6903605653719480320, 6903605654569883648, 6903605655433171968, 6903605656287870976, 6903605657344433152, 6903605658005857280, 6903605658864850944, 6903605659728139264, 6903605660582838272, 6903605661441831936, 6903605662313709568, 6903605663164112896, 6903605664018811904, 6903605664877805568, 6903605665736799232, 6903605666600087552, 6903605667502029824, 6903605668318073856, 6903605669172772864, 6903605670036061184, 6903605670890759168, 6903605671749752832, 6903605672638811136, 6903605673532164096, 6903605674331028480, 6903605675185726464, 6903605676044720128, 6903605676908008448, 6903605677767002112, 6903605678776318976, 6903605679480693760, 6903605680339687424, 6903605681198681088, 6903605682061969408, 6903605682929552384, 6903605683835791360, 6903605684638949376, 6903605685493648384, 6903605686356936704, 6903605687215930368, 6903605688070628352, 6903605688951097344, 6903605689797206016, 6903605690647609344, 6903605691510897664, 6903605692369891328, 6903605693228883968, 6903605694130827264, 6903605694951165952, 6903605695810159616, 6903605696673447936, 6903605697532441600, 6903605698391435264, 6903605699276197888, 6903605700276925440, 6903605700964120576, 6903605701823114240, 6903605702686402560, 6903605703541100544, 6903605704400094208, 6903605705293447168, 6903605706122376192, 6903605706981369856, 6903605707836067840, 6903605708699356160, 6903605709558349824, 6903605710481768448, 6903605711272042496, 6903605712135330816, 6903605712994323456, 6903605713853317120, 6903605714712310784, 6903605715627139072, 6903605716430298112, 6903605717289290752, 6903605718148284416, 6903605719007278080, 6903605719861977088, 6903605720733854720, 6903605721717402624, 6903605722438957056, 6903605723297950720, 6903605724161239040, 6903605725015937024, 6903605725969420288, 6903605726738219008, 6903605727597212672, 6903605728456206336, 6903605729310904320, 6903605730169897984, 6903605731028891648, 6903605731939424256, 6903605732746878976, 6903605733618756608, 6903605734464865280, 6903605735328153600, 6903605736191441920, 6903605737080500224, 6903605737900838912, 6903605738759832576, 6903605739623120896, 6903605740482114560, 6903605741336813568, 6903605742247346176, 6903605743175059456, 6903605743918088192, 6903605744777081856, 6903605745636075520, 6903605746495069184, 6903605747349767168, 6903605748359085056, 6903605749072049152, 6903605749926748160, 6903605750785740800, 6903605751644734464, 6903605752508022784, 6903605753384196096, 6903605754221715456, 6903605755080708096, 6903605755943996416, 6903605756798695424, 6903605757657689088, 6903605758572517376, 6903605759379971072, 6903605760234669056, 6903605761097957376, 6903605761956951040, 6903605762811650048, 6903605763709297664, 6903605764533931008, 6903605765388630016, 6903605766247623680, 6903605767110912000, 6903605767965609984, 6903605768923387904, 6903605769795266560, 6903605770542590976, 6903605771397288960, 6903605772260577280, 6903605773119570944, 6903605773974269952, 6903605774841852928, 6903605775696551936, 6903605776551249920, 6903605777410243584, 6903605778273531904, 6903605779132525568, 6903605780034468864, 6903605780850511872, 6903605781705210880, 6903605782564204544, 6903605783423197184, 6903605784286486528, 6903605785192724480, 6903605786197746688, 6903605786859171840, 6903605787722460160, 6903605788577158144, 6903605789436151808, 6903605790299440128, 6903605791214268416, 6903605792013131776, 6903605792876421120, 6903605793731119104, 6903605794590112768, 6903605795453401088, 6903605796320984064, 6903605797167092736, 6903605798030381056, 6903605798885080064, 6903605799744073728, 6903605800603066368, 6903605801517894656, 6903605802325348352, 6903605803180047360, 6903605804043335680, 6903605804902329344, 6903605805757027328, 6903605806628905984, 6903605807608158208, 6903605808338302976, 6903605809197296640, 6903605810051994624, 6903605810915282944, 6903605811778571264, 6903605812641860608, 6903605813492263936, 6903605814346961920, 6903605815210250240, 6903605816069243904, 6903605816923942912, 6903605817834475520, 6903605818646224896, 6903605819500922880, 6903605820364211200, 6903605821223204864, 6903605822082198528, 6903605822971256832, 6903605823800184832, 6903605824654883840, 6903605825518172160, 6903605826377165824, 6903605827236159488, 6903605828146692096, 6903605829078700032, 6903605829813139456, 6903605830672133120, 6903605831535421440, 6903605832390119424, 6903605833253407744, 6903605834275610624, 6903605834971395072, 6903605835826094080, 6903605836689382400, 6903605837548375040, 6903605838403074048, 6903605839313606656, 6903605840125356032, 6903605840984349696, 6903605841839047680, 6903605842702336000, 6903605843561329664, 6903605844441797632, 6903605845275021312, 6903605846134014976, 6903605846997303296, 6903605847856296960, 6903605848710995968, 6903605849621528576, 6903605850549241856, 6903605851292270592, 6903605852151264256, 6903605853005963264, 6903605853864955904, 6903605854728244224, 6903605855750447104, 6903605856446231552, 6903605857300930560, 6903605858164218880, 6903605859023211520, 6903605859877910528, 6903605860784148480, 6903605861595897856, 6903605862459186176, 6903605863318178816, 6903605864172877824, 6903605865031871488, 6903605865903749120, 6903605866754153472, 6903605867608851456, 6903605868467845120, 6903605869326838784, 6903605870190127104, 6903605871104955392, 6903605872024078336, 6903605872762812416, 6903605873621806080, 6903605874485094400, 6903605875339792384, 6903605876203080704, 6903605877066370048, 6903605877921068032, 6903605878780061696, 6903605879634759680, 6903605880493753344, 6903605881352747008, 6903605882263279616, 6903605883070734336, 6903605883929726976, 6903605884793015296, 6903605885647714304, 6903605886506707968, 6903605887400060928, 6903605888224694272, 6903605889087982592, 6903605889942681600, 6903605890801675264, 6903605891660668928, 6903605892566906880, 6903605893511799808, 6903605894241943552, 6903605895100937216, 6903605895955636224, 6903605896818924544, 6903605897768112128, 6903605898631400448, 6903605899391609856, 6903605900254898176, 6903605901109596160, 6903605901972884480, 6903605902831878144, 6903605903712347136, 6903605904541275136, 6903605905404563456, 6903605906263557120, 6903605907118256128, 6903605907977248768, 6903605908887782400, 6903605909699530752, 6903605910558524416, 6903605911413223424, 6903605912272216064, 6903605913131209728, 6903605914007383040, 6903605914849197056, 6903605915712485376, 6903605916571479040, 6903605917426177024, 6903605918289465344, 6903605919277307904, 6903605920170661888, 6903605920866446336, 6903605921721144320, 6903605922584432640, 6903605923439131648, 6903605924302419968, 6903605925208657920, 6903605926020407296, 6903605926875105280, 6903605927734098944, 6903605928597387264, 6903605929456380928, 6903605930341143552, 6903605931170072576, 6903605932033360896, 6903605932888059904, 6903605933747052544, 6903605934610341888, 6903605935520874496, 6903605936324033536, 6903605937187321856, 6903605938050610176, 6903605938901013504, 6903605939760007168, 6903605940722079744, 6903605941662678016, 6903605942341282816, 6903605943195980800, 6903605944059269120, 6903605944913968128, 6903605945777256448, 6903605946670609408, 6903605947490948096, 6903605948354236416, 6903605949213230080, 6903605950067929088, 6903605950926921728, 6903605951837455360, 6903605952644909056, 6903605953508197376, 6903605954362896384, 6903605955221889024, 6903605956085178368, 6903605956965646336, 6903605957798870016, 6903605958662158336, 6903605959521152000, 6903605960375849984, 6903605961239138304, 6903605962098131968, 6903605963098859520, 6903605963820413952, 6903605964675112960, 6903605965538401280, 6903605966393099264, 6903605967256387584, 6903605968222755840, 6903605968970080256, 6903605969833368576, 6903605970692361216, 6903605971547060224, 6903605972406053888, 6903605973316586496, 6903605974124040192, 6903605974987328512, 6903605975842027520, 6903605976701021184, 6903605977564309504, 6903605978487727104, 6903605979278001152, 6903605980136994816, 6903605980995988480, 6903605981859276800, 6903605982713974784, 6903605983718996992, 6903605984543631360, 6903605985290955776, 6903605986154244096, 6903605987008942080, 6903605987872230400, 6903605988726929408, 6903605989628872704, 6903605990444916736, 6903605991308205056, 6903605992167197696, 6903605993030487040, 6903605993880890368, 6903605994804307968, 6903605995603172352, 6903605996462164992, 6903605997316864000, 6903605998175857664, 6903605999039145984, 6903605999919613952, 6903606000757132288, 6903606001611831296, 6903606002470824960, 6903606003334113280, 6903606004193106944, 6903606005146589184, 6903606006052827136, 6903606006765792256, 6903606007624785920, 6903606008488074240, 6903606009342772224, 6903606010206060544, 6903606011103709184, 6903606011924047872, 6903606012778745856, 6903606013637739520, 6903606014501027840, 6903606015364316160, 6903606016266259456, 6903606017078008832, 6903606017932706816, 6903606018795995136, 6903606019654988800, 6903606020518277120, 6903606021398745088, 6903606022227674112, 6903606023086667776, 6903606023945661440, 6903606024808949760, 6903606025663647744, 6903606026621425664, 6903606027519074304, 6903606028240628736, 6903606029103917056, 6903606029962910720, 6903606030821903360, 6903606031676602368, 6903606032587134976, 6903606033394589696, 6903606034257878016, 6903606035116870656, 6903606035971569664, 6903606036826267648, 6903606037736801280, 6903606038544254976, 6903606039407543296, 6903606040262242304, 6903606041121234944, 6903606041980228608, 6903606042895056896, 6903606043698215936, 6903606044561504256, 6903606045420497920, 6903606046275195904, 6903606047138484224, 6903606048156391424, 6903606048998205440, 6903606049711169536, 6903606050574458880, 6903606051429156864, 6903606052301035520, 6903606053151438848, 6903606054019021824, 6903606054869426176, 6903606055724124160, 6903606056583117824, 6903606057442111488, 6903606058301104128, 6903606059211637760, 6903606060019091456, 6903606060882379776, 6903606061737078784, 6903606062596071424, 6903606063459360768, 6903606064322649088, 6903606065177347072, 6903606066032046080, 6903606066891038720, 6903606067750032384, 6903606068613320704, 6903606069519558656, 6903606070468747264, 6903606071186006016, 6903606072044999680, 6903606072908288000, 6903606073767281664, 6903606074621980672, 6903606075545398272, 6903606076352851968, 6903606077203255296, 6903606078057954304, 6903606078921242624, 6903606079780236288, 6903606080677883904, 6903606081493927936, 6903606082352921600, 6903606083216209920, 6903606084075203584, 6903606084934197248, 6903606085840435200, 6903606086647888896, 6903606087511177216, 6903606088370170880, 6903606089224868864, 6903606090088157184, 6903606091050229760, 6903606091831914496, 6903606092665138176, 6903606093519836160, 6903606094378829824, 6903606095242118144, 6903606096096817152, 6903606097153378304, 6903606097823393792, 6903606098686682112, 6903606099545675776, 6903606100400373760, 6903606101259367424, 6903606102122655744, 6903606102985944064, 6903606103840643072, 6903606104699636736, 6903606105558629376, 6903606106413328384, 6903606107323860992, 6903606108135610368, 6903606108990308352, 6903606109849302016, 6903606110708295680, 6903606111571584000, 6903606112520771584, 6903606113285275648, 6903606114148563968, 6903606115003262976, 6903606115866551296, 6903606116734134272, 6903606117631782912, 6903606118538020864, 6903606119298230272, 6903606120161518592, 6903606121020512256, 6903606121879505920, 6903606122738498560, 6903606123644737536, 6903606124456485888, 6903606125311183872, 6903606126174473216, 6903606127033465856, 6903606127888164864, 6903606128760043520, 6903606129606151168, 6903606130469440512, 6903606131324138496, 6903606132187426816, 6903606133042125824, 6903606133995608064, 6903606134760112128, 6903606135619105792, 6903606136482394112, 6903606137337093120, 6903606138196085760, 6903606139102324736, 6903606140064397312, 6903606140777361408, 6903606141632060416, 6903606142491053056, 6903606143354342400, 6903606144213335040, 6903606145128163328, 6903606145931322368, 6903606146790316032, 6903606147645014016, 6903606148508302336, 6903606149363001344, 6903606150230584320, 6903606151085283328, 6903606151939981312, 6903606152798974976, 6903606153662263296, 6903606154516962304, 6903606155513394176, 6903606156239244288, 6903606157098236928, 6903606157952935936, 6903606158816224256, 6903606159670922240, 6903606160564276224, 6903606161530643456, 6903606162252197888, 6903606163111191552, 6903606163965889536, 6903606164829178880, 6903606165688171520, 6903606166598705152, 6903606167401864192, 6903606168260856832, 6903606169124146176, 6903606169983138816, 6903606170833543168, 6903606171709716480, 6903606172555824128, 6903606173410523136, 6903606174269516800, 6903606175132805120, 6903606175987503104, 6903606176983936000, 6903606177709785088, 6903606178568778752, 6903606179423477760, 6903606180282470400, 6903606181141464064, 6903606182030522368, 6903606182988300288, 6903606183718445056, 6903606184581733376, 6903606185440726016, 6903606186295425024, 6903606187158713344, 6903606188056361984, 6903606188876700672, 6903606189731398656, 6903606190590392320, 6903606191449385984, 6903606192312674304, 6903606193171667968, 6903606194030660608, 6903606194885359616, 6903606195744353280, 6903606196607641600, 6903606197462339584, 6903606198454477824, 6903606199180326912, 6903606200039320576, 6903606200902608896, 6903606201757306880, 6903606202620595200, 6903606203526834176, 6903606204476021760, 6903606205197576192, 6903606206052274176, 6903606206911267840, 6903606207770261504, 6903606208629255168, 6903606209544083456, 6903606210347241472, 6903606211210529792, 6903606212065228800, 6903606212924222464, 6903606213783216128, 6903606214659389440, 6903606215501202432, 6903606216360196096, 6903606217219189760, 6903606218082478080, 6903606218937176064, 6903606219933608960, 6903606220659458048, 6903606221518451712, 6903606222377445376, 6903606223236439040, 6903606224091137024, 6903606225005965312, 6903606225950858240, 6903606226668118016, 6903606227531406336, 6903606228390398976, 6903606229249392640, 6903606230108386304, 6903606231018919936, 6903606231830668288, 6903606232689661952, 6903606233544359936, 6903606234403353600, 6903606235266641920, 6903606236129930240, 6903606236980333568, 6903606237843622912, 6903606238702615552, 6903606239557314560, 6903606240420602880, 6903606241442804736, 6903606242138590208, 6903606242997582848, 6903606243852281856, 6903606244715570176, 6903606245570268160, 6903606246472211456, 6903606247374154752, 6903606248147249152, 6903606249010537472, 6903606249869531136, 6903606250724229120, 6903606251583222784, 6903606252498051072, 6903606253305504768, 6903606254164498432, 6903606255019196416, 6903606255878190080, 6903606256741478400, 6903606257604766720, 6903606258459465728, 6903606259314163712, 6903606260173157376, 6903606261036445696, 6903606261891144704, 6903606262874691584, 6903606263609131008, 6903606264468124672, 6903606265331412992, 6903606266186112000, 6903606267049400320, 6903606267959932928, 6903606268883351552, 6903606269622085632, 6903606270485373952, 6903606271344367616, 6903606272199065600, 6903606273058059264, 6903606273968592896, 6903606274780341248, 6903606275639334912, 6903606276494032896, 6903606277353026560, 6903606278216314880, 6903606279101078528, 6903606279934302208, 6903606280789000192, 6903606281647993856, 6903606282511282176, 6903606283365981184, 6903606284319463424, 6903606285088263168, 6903606285947255808, 6903606286801954816, 6903606287665243136, 6903606288524236800, 6903606289434769408, 6903606290353892352, 6903606291101216768, 6903606291955915776, 6903606292814908416, 6903606293678197760, 6903606294537190400, 6903606295443429376, 6903606296250883072, 6903606297114171392, 6903606297968869376, 6903606298827863040, 6903606299691151360, 6903606300580209664, 6903606301409138688, 6903606302263836672, 6903606303122830336, 6903606303986118656, 6903606304845112320, 6903606305790005248, 6903606306554509312, 6903606307413502976, 6903606308276791296, 6903606309131489280, 6903606309990482944, 6903606310892426240, 6903606311854498816, 6903606312567463936, 6903606313430752256, 6903606314289744896, 6903606315148738560, 6903606316007732224, 6903606316913970176, 6903606317730014208, 6903606318580417536, 6903606319439411200, 6903606320298404864, 6903606321161693184, 6903606322020686848, 6903606322879679488, 6903606323738673152, 6903606324597666816, 6903606325452365824, 6903606326315654144, 6903606327307791360, 6903606328033640448, 6903606328896928768, 6903606329751627776, 6903606330606325760, 6903606331465319424, 6903606332371557376, 6903606333367990272, 6903606334046595072, 6903606334905588736, 6903606335760286720, 6903606336623575040, 6903606337482568704, 6903606338375921664, 6903606339196260352, 6903606340055254016, 6903606340918542336, 6903606341777536000, 6903606342632235008, 6903606343538472960, 6903606344350221312, 6903606345213509632, 6903606346072503296, 6903606346927202304, 6903606347790490624, 6903606348743972864, 6903606349504182272, 6903606350363175936, 6903606351226464256, 6903606352081162240, 6903606352944450560, 6903606353824919552, 6903606354752631808, 6903606355517136896, 6903606356376129536, 6903606357239417856, 6903606358094116864, 6903606358953110528, 6903606359829283840, 6903606360671096832, 6903606361530090496, 6903606362389084160, 6903606363248077824, 6903606364111366144, 6903606365017604096, 6903606365833648128, 6903606366692641792, 6903606367551634432, 6903606368406333440, 6903606369269621760, 6903606370231694336, 6903606370987609088, 6903606371846601728, 6903606372701300736, 6903606373564589056, 6903606374423582720, 6903606375286871040, 6903606376313368576, 6903606377000562688, 6903606377855261696, 6903606378718550016, 6903606379573248000, 6903606380432241664, 6903606381338479616, 6903606382150228992, 6903606383013517312, 6903606383868215296, 6903606384727208960, 6903606385590497280, 6903606386501030912, 6903606387308484608, 6903606388167478272, 6903606389026470912, 6903606389881169920, 6903606390744458240, 6903606391753775104, 6903606392462445568, 6903606393321438208, 6903606394180431872, 6903606395035130880, 6903606395894123520, 6903606396787477504, 6903606397719485440, 6903606398475399168, 6903606399334392832, 6903606400189090816, 6903606401052380160, 6903606401911372800, 6903606402783251456, 6903606403625065472, 6903606404484058112, 6903606405347347456, 6903606406202045440, 6903606407065333760, 6903606407975867392, 6903606408783321088, 6903606409638019072, 6903606410497012736, 6903606411360301056, 6903606412215000064, 6903606413168482304, 6903606413937282048, 6903606414800570368, 6903606415655268352, 6903606416509967360, 6903606417368960000, 6903606418288083968, 6903606419220090880, 6903606419950235648, 6903606420804934656, 6903606421663927296, 6903606422527216640, 6903606423381914624, 6903606424399821824, 6903606425104196608, 6903606425958894592, 6903606426822183936, 6903606427681176576, 6903606428540170240, 6903606429429228544, 6903606430253861888, 6903606431117151232, 6903606431976143872, 6903606432835137536, 6903606433689836544, 6903606434643318784, 6903606435407822848, 6903606436266816512, 6903606437130104832, 6903606437984803840, 6903606438839501824, 6903606439754330112, 6903606440651977728, 6903606441420777472, 6903606442275475456, 6903606443134469120, 6903606443997757440, 6903606444856751104, 6903606445904722944, 6903606446574738432, 6903606447433731072, 6903606448288430080, 6903606449147423744, 6903606450010712064, 6903606450878295040, 6903606451724403712, 6903606452587692032, 6903606453446685696, 6903606454301384704, 6903606455164673024, 6903606456165399552, 6903606456882659328, 6903606457741652992, 6903606458596352000, 6903606459459640320, 6903606460318632960, 6903606461216281600, 6903606462131109888, 6903606462891319296, 6903606463754607616, 6903606464609305600, 6903606465468299264, 6903606466327292928, 6903606467280775168, 6903606468045279232, 6903606468908567552, 6903606469763266560, 6903606470622260224, 6903606471485548544, 6903606472387491840, 6903606473203534848, 6903606474062528512, 6903606474921522176, 6903606475776221184, 6903606476639509504, 6903606477592991744, 6903606478353201152, 6903606479212194816, 6903606480071188480, 6903606480934476800, 6903606481793469440, 6903606482704003072, 6903606483515751424, 6903606484370450432, 6903606485225148416, 6903606486084142080, 6903606486947430400, 6903606487857964032, 6903606488837216256, 6903606489524411392, 6903606490379109376, 6903606491242397696, 6903606492101391360, 6903606492956090368, 6903606493862328320, 6903606494678371328, 6903606495533070336, 6903606496392064000, 6903606497255352320, 6903606498114345984, 6903606499110777856, 6903606499836627968, 6903606500695620608, 6903606501550319616, 6903606502409313280, 6903606503268305920, 6903606504157364224, 6903606505072192512, 6903606505849581568, 6903606506708575232, 6903606507563273216, 6903606508426562560, 6903606509285555200, 6903606510234743808, 6903606511003542528, 6903606511862536192, 6903606512717234176, 6903606513576227840, 6903606514435221504, 6903606515392999424, 6903606516157503488, 6903606517016497152, 6903606517875489792, 6903606518730188800, 6903606519593477120, 6903606520594204672, 6903606521311464448, 6903606522170457088, 6903606523029450752, 6903606523884149760, 6903606524747438080, 6903606525610726400, 6903606526542734336, 6903606527320123392, 6903606528183411712, 6903606529042405376, 6903606529897103360, 6903606530756097024, 6903606531782594560, 6903606532474084352, 6903606533333076992, 6903606534196366336, 6903606535051064320, 6903606535914352640, 6903606536824886272, 6903606537632339968, 6903606538487037952, 6903606539346031616, 6903606540209319936, 6903606541064018944, 6903606542026091520, 6903606542782005248, 6903606543645293568, 6903606544499992576, 6903606545363280896, 6903606546222274560, 6903606547081268224, 6903606547935966208, 6903606548799254528, 6903606549653953536, 6903606550512946176, 6903606551376235520, 6903606552282473472, 6903606553287495680, 6903606553948920832, 6903606554807913472, 6903606555666907136, 6903606556525900800, 6903606557389189120, 6903606558291132416, 6903606559107176448, 6903606559961874432, 6903606560820868096, 6903606561684156416, 6903606562538855424, 6903606563492337664, 6903606564256841728, 6903606565115835392, 6903606565979123712, 6903606566833822720, 6903606567692815360, 6903606568607643648, 6903606569415097344, 6903606570274091008, 6903606571133084672, 6903606571987782656, 6903606572842481664, 6903606573710064640, 6903606574689317888, 6903606575423757312, 6903606576282749952, 6903606577137448960, 6903606577996442624, 6903606578859730944, 6903606579765968896, 6903606580577717248, 6903606581432416256, 6903606582291409920, 6903606583154698240, 6903606584009396224, 6903606585035893760, 6903606585727383552, 6903606586586377216, 6903606587449665536, 6903606588304363520, 6903606589167651840, 6903606590065300480, 6903606590881344512, 6903606591744632832, 6903606592603626496, 6903606593462619136, 6903606594317318144, 6903606595232146432, 6903606596172743680, 6903606596894298112, 6903606597757586432, 6903606598612285440, 6903606599471279104, 6903606600334567424, 6903606601361064960, 6903606602048259072, 6903606602911547392, 6903606603770541056, 6903606604625240064, 6903606605484232704, 6903606606454895616, 6903606607206514688, 6903606608065508352, 6903606608920207360, 6903606609783495680, 6903606610638193664, 6903606611505777664, 6903606612356180992, 6903606613219469312, 6903606614074167296, 6903606614933160960, 6903606615796449280, 6903606616668327936, 6903606617677644800, 6903606618373430272, 6903606619232422912, 6903606620091416576, 6903606620950410240, 6903606621805109248, 6903606622689871872, 6903606623527390208, 6903606624382089216, 6903606625241082880, 6903606626100076544, 6903606626963364864, 6903606627998451712, 6903606628681351168, 6903606629540344832, 6903606630395043840, 6903606631254036480, 6903606632117324800, 6903606633036448768, 6903606633839606784, 6903606634698600448, 6903606635557594112, 6903606636416587776, 6903606637271285760, 6903606638151754752, 6903606639135301632, 6903606639848266752, 6903606640707259392, 6903606641570548736, 6903606642429541376, 6903606643284240384, 6903606644259197952, 6903606645006522368, 6903606645861220352, 6903606646720214016, 6903606647583502336, 6903606648438201344, 6903606649391683584, 6903606650156187648, 6903606651015181312, 6903606651874174976, 6903606652737463296, 6903606653596456960, 6903606654455450624, 6903606655310148608, 6903606656173436928, 6903606657032430592, 6903606657891424256, 6903606658746122240, 6903606659656655872, 6903606660588663808, 6903606661327397888, 6903606662182095872, 6903606663041089536, 6903606663900083200, 6903606664763371520, 6903606665648135168, 6903606666477063168, 6903606667340352512, 6903606668199345152, 6903606669054044160, 6903606669917332480, 6903606670866520064, 6903606671639614464, 6903606672490017792, 6903606673349011456, 6903606674212299776, 6903606675071293440, 6903606675968941056, 6903606676789279744, 6903606677643978752, 6903606678507267072, 6903606679366260736, 6903606680220958720, 6903606681101427712, 6903606682089269248, 6903606682802234368, 6903606683656932352, 6903606684520221696, 6903606685379214336, 6903606686238208000, 6903606687101496320, 6903606687951899648, 6903606688815188992, 6903606689674181632, 6903606690533175296, 6903606691387874304, 6903606692388600832, 6903606693105860608, 6903606693964854272, 6903606694828142592, 6903606695682841600, 6903606696546129920, 6903606697435188224, 6903606698264116224, 6903606699123109888, 6903606699982103552, 6903606700841097216, 6903606701695795200], 'FORT': [19.1989, 19.2146, 19.1989, 19.177, 19.1644, 19.155, 19.1331, 19.1112, 19.13, 19.1237, 19.1174, 19.1488, 19.13, 19.1237, 19.1362, 19.1394, 19.1832, 19.2083, 19.2083, 19.1832, 19.1488, 19.2083, 19.1832, 19.2397, 19.1926, 19.1958, 19.1958, 19.1707, 19.1644, 19.1989, 19.1926, 19.2114, 19.2303, 19.2303, 19.2114, 19.2052, 19.1738, 19.1331, 19.1331, 19.1895, 19.224, 19.2491, 19.2271, 19.2303, 19.3086, 19.3211, 19.2992, 19.2804, 19.2585, 19.224, 19.2459, 19.2553, 19.2616, 19.2114, 19.1989, 19.2052, 19.2271, 19.2083, 19.1958, 19.2208, 19.2741, 19.2961, 19.2459, 19.2867, 19.2773, 19.3023, 19.2647, 19.2585, 19.2208, 19.2271, 19.1989, 19.2114, 19.1895, 19.2428, 19.2397, 19.2052, 19.2365, 19.2585, 19.2491, 19.2428, 19.2365, 19.2835, 19.2428, 19.2334, 19.2522, 19.2616, 19.3055, 19.2804, 19.271, 19.2773, 19.2929, 19.2522, 19.2679, 19.271, 19.2585, 19.2365, 19.2303, 19.224, 19.2522, 19.2585, 19.271, 19.2334, 19.2177, 19.224, 19.2271, 19.2334, 19.2303, 19.2585, 19.2491, 19.224, 19.1707, 19.2208, 19.1519, 19.2052, 19.1425, 19.1989, 19.202, 19.1801, 19.224, 19.1707, 19.1958, 19.2208, 19.2208, 19.2271, 19.2397, 19.2146, 19.2491, 19.2271, 19.2052, 19.1895, 19.1864, 19.2083, 19.224, 19.2114, 19.1989, 19.177, 19.2208, 19.2553, 19.2647, 19.2773, 19.2741, 19.2428, 19.2208, 19.1738, 19.1926, 19.1738, 19.1206, 19.1801, 19.1488, 19.0829, 19.1268, 19.155, 19.224, 19.1989, 19.177, 19.177, 19.1738, 19.1644, 19.1926, 19.2083, 19.2083, 19.2146, 19.1832, 19.1676, 19.1488, 19.2271, 19.2271, 19.224, 19.2428, 19.2303, 19.2397, 19.2459, 19.2271, 19.2647, 19.2679, 19.2741, 19.2741, 19.2491, 19.2585, 19.2459, 19.224, 19.1895, 19.177, 19.1488, 19.1644, 19.2052, 19.1707, 19.1832, 19.1707, 19.1582, 19.1801, 19.1738, 19.202, 19.2052, 19.202, 19.1864, 19.2114, 19.1456, 19.1425, 19.1519, 19.1206, 19.1237, 19.1613, 19.2208, 19.202, 19.1801, 19.1519, 19.1143, 19.108, 19.1206, 19.2052, 19.2146, 19.1676, 19.1832, 19.1864, 19.1832, 19.1644, 19.1801, 19.2522, 19.2397, 19.224, 19.2679, 19.2647, 19.2365, 19.2271, 19.1895, 19.1832, 19.1707, 19.1832, 19.1895, 19.177, 19.0735, 19.0485, 19.014, 19.0641, 19.1112, 19.1049, 19.1676, 19.1958, 19.2177, 19.2146, 19.2177, 19.2083, 19.2052, 19.2303, 19.2052, 19.1958, 19.2052, 19.2114, 19.177, 19.1268, 19.1049, 19.1268, 19.1519, 19.1864, 19.2177, 19.2177, 19.2334, 19.2303, 19.1926, 19.2303, 19.155, 19.1801, 19.1582, 19.177, 19.177, 19.1989, 19.2083, 19.2177, 19.2052, 19.2334, 19.2428, 19.2428, 19.2428, 19.2334, 19.2271, 19.2083, 19.1456, 19.1519, 19.2052, 19.2114, 19.2114, 19.2334, 19.2052, 19.1738, 19.1801, 19.1958, 19.2334, 19.271, 19.2929, 19.3023, 19.318, 19.2992, 19.2616, 19.2114, 19.1958, 19.1582, 19.1676, 19.2177, 19.2114, 19.2083, 19.202, 19.1425, 19.1362, 19.1425, 19.1801, 19.1895, 19.202, 19.2177, 19.2146, 19.2052, 19.2114, 19.271, 19.3086, 19.2585, 19.2365, 19.2553, 19.2146, 19.2804, 19.2585, 19.2177, 19.2177, 19.2177, 19.1801, 19.202, 19.1832, 19.1613, 19.1676, 19.202, 19.2052, 19.2146, 19.2052, 19.1926, 19.1707, 19.1864, 19.2114, 19.2365, 19.2679, 19.2522, 19.2428, 19.2365, 19.2177, 19.2271, 19.2428, 19.2679, 19.2773, 19.2459, 19.2428, 19.2553, 19.2616, 19.2208, 19.2052, 19.1926, 19.2052, 19.224, 19.2522, 19.2585, 19.2334, 19.271, 19.3431, 19.3149, 19.2397, 19.224, 19.2585, 19.2271, 19.1895, 19.2271, 19.2397, 19.224, 19.2303, 19.2773, 19.2271, 19.1926, 19.2208, 19.2365, 19.2616, 19.2553, 19.2146, 19.1801, 19.1958, 19.177, 19.1895, 19.2146, 19.1958, 19.1738, 19.2083, 19.1926, 19.1488, 19.1676, 19.1268, 19.1394, 19.1926, 19.0955, 19.0735, 19.061, 19.0829, 19.1237, 19.1206, 19.1018, 19.108, 19.1613, 19.1488, 19.177, 19.13, 19.0923, 19.0892, 19.1268, 19.1206, 19.0704, 19.1049, 19.1143, 19.0767, 19.0861, 19.1488, 19.1456, 19.0955, 19.0955, 19.155, 19.1707, 19.1958, 19.202, 19.1801, 19.1832, 19.1644, 19.1394, 19.0767, 19.1049, 19.1237, 19.1456, 19.1582, 19.1738, 19.1613, 19.2083, 19.2208, 19.2083, 19.2208, 19.2303, 19.1926, 19.1613, 19.1864, 19.1644, 19.1676, 19.1895, 19.1989, 19.1864, 19.2459, 19.2146, 19.1425, 19.1237, 19.155, 19.1644, 19.177, 19.1676, 19.1801, 19.1582, 19.155, 19.1676, 19.1425, 19.1018, 19.1425, 19.1613, 19.1456, 19.1738, 19.1676, 19.177, 19.1644, 19.1613, 19.1519, 19.1237, 19.2114, 19.2334, 19.2585, 19.2334, 19.2083, 19.1644, 19.2208, 19.2585, 19.2679, 19.2428, 19.202, 19.2303, 19.2146, 19.2271, 19.2491, 19.2334, 19.2208, 19.2428, 19.202, 19.2491, 19.1864, 19.1644, 19.1958, 19.2365, 19.1864, 19.202, 19.1456, 19.1394, 19.1331, 19.1394, 19.1362, 19.1582, 19.1112, 19.1456, 19.177, 19.1519, 19.177, 19.2146, 19.2428, 19.224, 19.2177, 19.2083, 19.1958, 19.1644, 19.1926, 19.1644, 19.2114, 19.2083, 19.2114, 19.202, 19.1801, 19.1895, 19.1676, 19.1801, 19.2083, 19.2052, 19.2365, 19.1832, 19.1801, 19.1832, 19.1864, 19.1926, 19.2052, 19.2303, 19.202, 19.2397, 19.2177, 19.1989, 19.1613, 19.1644, 19.1268, 19.1237, 19.1676, 19.2114, 19.2992, 19.2867, 19.3086, 19.365, 19.2334, 19.2052, 19.2303, 19.2553, 19.1895, 19.1394, 19.1362, 19.1237, 19.155, 19.1488, 19.1488, 19.1331, 19.1425, 19.1488, 19.1738, 19.2114, 19.2146, 19.224, 19.2177, 19.1707, 19.1738, 19.1519, 19.1676, 19.1174, 19.108, 19.1049, 19.0735, 19.0955, 19.108, 19.1049, 19.1582, 19.1112, 19.1174, 19.0861, 19.1456, 19.1456, 19.1362, 19.1237, 19.1331, 19.0735, 19.0892, 19.1018, 19.1707, 19.0923, 19.0767, 19.1206, 19.1174, 19.1488, 19.0798, 19.0359, 19.0328, 19.0767, 19.1331, 19.1394, 19.1488, 19.1425, 19.1456, 19.1926, 19.202, 19.1926, 19.1456, 19.1018, 19.1237, 19.13, 19.155, 19.13, 19.0986, 19.0485, 19.0955, 19.0829, 19.0829, 19.0861, 19.061, 19.0547, 19.061, 19.0767, 19.1425, 19.1394, 19.177, 19.1644, 19.1989, 19.2052, 19.2177, 19.2052, 19.2428, 19.2961, 19.2303, 19.1926, 19.1268, 19.0892, 19.1456, 19.1425, 19.1958, 19.1394, 19.1394, 19.0955, 19.0955, 19.1237, 19.1143, 19.1519, 19.1425, 19.1394, 19.0892, 19.1018, 19.108, 19.0798, 19.0861, 19.0892, 19.0829, 19.0767, 19.0798, 19.1112, 19.1676, 19.1018, 19.0704, 19.0328, 18.9952, 18.9921, 18.9983, 19.0579, 19.1206, 19.1394, 19.1143, 19.1143, 19.108, 19.0986, 19.108, 19.1362, 19.1519, 19.1362, 19.1519, 19.1018, 19.1488, 19.1488, 19.1049, 19.0955, 19.1206, 19.0704, 19.1112, 19.1018, 19.0485, 19.0829, 19.1018, 19.0829, 19.0485, 19.0673, 19.061, 19.0265, 19.0391, 19.0767, 19.1362, 19.1519, 19.1519, 19.1268, 19.1174, 19.1143, 19.1676, 19.1864, 19.1488, 19.1425, 19.13, 19.1237, 19.0955, 19.014, 18.9638, 18.9482, 19.0516, 19.0673, 19.0485, 19.0422, 19.0955, 19.0735, 19.0955, 19.1425, 19.1832, 19.1989, 19.1958, 19.1519, 19.1832, 19.108, 19.177, 19.1237, 19.1237, 19.108, 19.0923, 19.0829, 19.0234, 19.0485, 19.0203, 19.0485, 19.0547, 19.1049, 19.1143, 19.1644, 19.2334, 19.2146, 19.2114, 19.1613, 19.1519, 19.1582, 19.0861, 19.1613, 19.1707, 19.1613, 19.2114, 19.1864, 19.1926, 19.2114, 19.1989, 19.2146, 19.177, 19.1425, 19.1331, 19.1394, 19.1456, 19.1237, 19.1237, 19.13, 19.1331, 19.1456, 19.2146, 19.2334, 19.2083, 19.1895, 19.177, 19.1488, 19.1425, 19.1456, 19.1425, 19.1488, 19.0923, 19.108, 19.1331, 19.1237, 19.1895, 19.2083, 19.1582, 19.1331, 19.1676, 19.108, 19.0735, 19.0579, 19.108, 19.1237, 19.0986, 19.1268, 19.0923, 19.1112, 19.0986, 19.0892, 19.1049, 19.0203, 19.0297, 19.13, 19.1488, 19.0923, 19.1488, 19.155, 19.2177, 19.1519, 19.1143, 19.1112, 19.0923, 19.0673, 19.0986, 19.0986, 19.1206, 19.1676, 19.1237, 19.1488, 19.1676, 19.1832, 19.1331, 19.1206, 19.0955, 19.0015, 18.9544, 18.9827, 19.0328, 19.0767, 19.0704, 19.0077, 18.9983, 19.0516, 19.1049, 19.0547, 19.0516, 19.0641, 19.1018, 19.1018, 19.0422, 19.0579, 19.0328, 19.0015, 19.0297, 19.0391, 19.0265, 19.0328, 19.0547, 19.0923, 19.0798, 19.0829, 19.0422, 19.061, 19.0767, 19.0641, 19.1112, 19.155, 19.1268, 19.061, 19.061, 19.0861, 19.0923, 19.0829, 19.0767, 19.13, 19.108, 19.1112, 19.0673, 19.0767, 19.1018, 19.1018, 19.1268, 19.13, 19.13, 19.155, 19.155, 19.0861, 19.0767, 19.0829, 19.0986, 19.0829, 19.1174, 19.1331, 19.1362, 19.1143, 19.1268, 19.1268, 19.1018, 19.0579, 19.1362, 19.1456, 19.1143, 19.0704, 19.0234, 19.0767, 19.0829, 19.0171, 19.0704, 19.0798, 19.1644, 19.1519, 19.1143, 19.0829, 19.0579, 19.0735, 19.1268, 19.1206, 19.1456, 19.1519, 19.1738, 19.2052, 19.1738, 19.13, 19.1206, 19.1519, 19.1425, 19.1268, 19.0704, 19.0829, 19.0923, 19.0704, 19.0798, 19.0453, 19.0547, 19.0829, 19.0297, 19.0735, 19.1049, 19.0955, 19.0986, 19.1644, 19.1613, 19.1143, 19.1268, 19.1362, 19.0516, 19.0829, 19.0516, 19.0767, 19.0453, 19.0735, 19.1049, 19.1143, 19.0986, 19.0829, 19.061, 19.0955, 19.0923, 19.1362, 19.1958, 19.1644, 19.1895, 19.1362, 19.1362, 19.0767, 19.0579, 19.0297, 18.9952, 19.0015, 19.0453, 19.0359, 19.0203, 19.0015, 19.0422, 19.0829, 18.9827, 19.0391, 19.0798, 19.0704, 19.0798, 19.1268, 19.1738, 19.2052, 19.1613, 19.13, 19.1143, 19.1174, 19.13, 19.1394, 19.0861, 19.0923, 19.0986, 19.0892, 19.0955, 19.1018, 19.108, 19.1644, 19.1926, 19.1676, 19.1582, 19.155, 19.1582, 19.1801, 19.1676, 19.1582, 19.1362, 19.1112, 19.0955, 19.1456, 19.0923, 19.1049, 19.1425, 19.1206, 19.1362, 19.0986, 19.1488, 19.1112, 19.1018, 19.0986, 19.108, 19.0735, 19.0704, 19.13, 19.1206, 19.1613, 19.1644, 19.1425, 19.202, 19.1864, 19.177, 19.1018, 19.1488, 19.1613, 19.1331, 19.13, 19.1613, 19.1394, 19.0923, 19.0892, 19.0955, 19.0986, 19.1456, 19.1613, 19.1456, 19.1832, 19.1895, 19.1864, 19.1801, 19.1456, 19.1049, 19.0829, 19.1801, 19.1707, 19.202, 19.2146, 19.1958, 19.1801, 19.1268, 19.1519, 19.1582, 19.1456, 19.1456, 19.1112, 19.1331, 19.1049, 19.1488, 19.155, 19.1707, 19.1801, 19.1331, 19.1425, 19.1394, 19.1582, 19.1707, 19.1049, 19.1331, 19.1644, 19.1331, 19.1425, 19.1676, 19.1707, 19.1958, 19.1613, 19.1801, 19.1989, 19.1394, 19.1237, 19.1331, 19.0829, 19.13, 19.1394, 19.1895, 19.1801, 19.0923, 19.0704, 19.0297, 19.0735, 19.0673, 19.0704, 19.1519, 19.1895, 19.1864, 19.1707, 19.1519, 19.1895, 19.1362, 19.1331, 19.2052, 19.1926, 19.2083, 19.2334, 19.1989, 19.1143, 19.0892, 19.0986, 19.0453, 19.0422, 19.108, 19.0923, 19.1331, 19.1456, 19.1676, 19.1237, 19.1832, 19.1989, 19.2052, 19.2146, 19.1832, 19.2114, 19.2553, 19.1989, 19.1644, 19.1362, 19.1613, 19.1958, 19.1707, 19.1425, 19.1112, 19.0735, 19.061, 19.1237, 19.1018, 19.1268, 19.1331, 19.1143, 19.0579, 19.0422, 19.0735, 19.0547, 19.0641, 19.0328, 19.0547, 19.0265, 19.0547, 19.0485, 18.9952, 19.0485, 19.0735, 19.0704, 19.061, 19.0798, 19.0422, 19.0265, 19.0297, 19.0359, 19.0265, 19.0015, 19.0265, 18.9983, 19.0109, 19.0234, 19.061, 19.061, 19.1112, 19.0861, 19.0547, 19.0547, 19.108, 19.014, 18.9701, 19.0015, 19.0265, 19.0673, 19.0485, 19.1049, 19.0829, 19.108, 19.1174, 19.1143, 19.13, 19.0673, 19.0171, 19.0046, 18.9764, 19.0265, 19.0359, 19.0955, 19.1049, 19.0955, 19.0735, 19.0485, 19.0485, 19.0203, 19.0171, 19.0203, 19.0109, 19.0422, 19.0673, 19.0453, 19.0453, 19.0516, 19.0767, 19.1174, 19.1425, 19.061, 19.1895, 19.1926, 19.1018, 19.1958, 19.1801, 19.177, 19.1832, 19.1738, 19.1237, 19.0892, 19.1237, 19.1143, 19.0829, 19.108, 19.0955, 19.0923, 19.0171, 19.0234, 19.0547, 19.1394, 19.108, 19.0453, 19.0328, 19.0673, 19.1049, 19.0986, 19.0516, 19.0391, 19.0046, 18.9983, 19.0015, 18.9795, 19.0265, 18.9513, 18.9576, 18.9952, 18.9607, 19.0203, 18.9952, 19.0015, 19.0046, 19.0046, 19.0265, 19.0171, 19.061, 19.1394, 19.1519, 19.1613, 19.0704, 18.9827, 19.0109, 18.9638, 18.9889, 18.9419, 18.967, 18.9827, 19.0485, 19.0892, 19.1049, 19.0673, 19.0203, 19.0359, 19.0955, 19.0297, 18.9921, 19.0015, 19.0109, 19.014, 18.9733, 18.9952, 18.9952, 18.967, 18.9388, 19.061, 19.1143, 19.0453, 18.9858, 18.9733, 18.9921, 18.9795, 18.9638, 18.9764, 18.9795, 18.9889, 19.0203, 19.061, 19.0704, 19.0516, 19.0641, 19.0673, 19.0485, 19.0328, 19.0234, 19.0077, 19.0046, 19.0265, 19.0579, 19.0641, 19.0485, 19.0892, 19.0297, 19.0203, 19.0328, 19.0234, 19.061, 19.1268, 19.1237, 19.0704, 19.0798, 19.1206, 19.1174, 19.0829, 19.0955, 19.0798, 19.0673, 19.0046, 18.9262, 18.9262, 18.9356, 18.945, 18.9356, 18.9827, 19.0015, 19.0422, 19.0453, 19.0485, 19.0641, 19.1143, 19.0422, 19.0579, 19.1112, 19.1112, 19.0955, 19.0798, 19.0547, 19.1049, 19.0923, 19.0829, 19.0328, 18.9419, 18.9638, 19.014, 18.9858, 18.9544, 19.0265, 19.0673, 19.0735, 19.108, 19.1112, 19.1488, 19.1519, 19.0986, 19.1049, 19.061, 19.0391, 18.9795, 18.9983, 18.9638, 19.0077, 18.9795, 18.9638, 18.9889, 19.0485, 19.0735, 19.0892, 19.0673, 19.0735, 19.0955, 19.0829, 19.0735, 19.0986, 19.1174, 19.1456, 19.1488, 19.1707, 19.1707, 19.1644, 19.1362, 19.1582, 19.1362, 19.1143, 19.1864, 19.13, 19.108, 19.0579, 19.1112, 19.0892, 19.0704, 19.0109, 19.0422, 19.1488, 19.1676, 19.1488, 19.108, 19.13, 19.1331, 19.108, 19.1143, 19.1331, 19.1362, 19.1519, 19.1362, 19.1362, 19.1362, 19.1018, 19.1112, 19.1206, 19.108, 19.1676, 19.1425, 19.1362, 19.1268, 19.0955, 19.1018, 19.1331, 19.1456, 19.1112, 19.0955, 19.1049, 19.0829, 19.0391, 19.0547, 19.0892, 19.0829, 19.0923, 19.0923, 19.0923, 19.1268, 19.1268, 19.1268, 19.1456, 19.1864, 19.1519, 19.1268, 19.0955, 19.0704, 19.0767, 19.108, 19.1394, 19.0829, 19.061, 19.0547, 19.0673, 19.0767, 19.0829, 19.0547, 19.0704, 19.0767, 19.1143, 19.0798, 19.0861, 19.0829, 19.0516, 19.0892, 19.0704, 19.0798, 19.0673, 19.0829, 19.1018, 19.0767, 19.0735, 19.108, 19.0485, 18.9952, 19.0015, 19.0203, 19.0516, 19.0547, 19.0516, 19.0955, 19.0579, 19.0234, 18.9889, 18.9983, 19.0234, 19.0391, 19.0798, 19.0547, 19.0453, 19.0735, 19.0641, 19.0485, 19.0516, 19.0641, 19.0735, 19.0641, 19.0359, 19.014, 19.0485, 19.0704, 19.0516, 18.9952, 19.0203, 19.0453, 19.0767, 19.0516, 19.108]}
2020-12-07 14:05:13,563 - callbacks - DEBUG - read from subscriber file
2020-12-07 14:05:37,534 - callbacks - DEBUG - read from subscriber file
2020-12-07 14:05:47,608 - callbacks - DEBUG - read from subscriber file
2020-12-07 14:05:57,624 - callbacks - DEBUG - read from subscriber file
2020-12-07 14:44:03,956 - callbacks - DEBUG - {'Hybrid_Mux':                   measurement_time       FORT
568  2020-12-07 20:40:47.726999998  18.894900
569  2020-12-07 20:40:47.927000046  18.888600
570     2020-12-07 20:40:48.125000  18.891800
571  2020-12-07 20:40:48.325999975  18.885500
572  2020-12-07 20:40:48.525000095  18.851000
..                             ...        ...
563                    1.60737e+09  18.857286
564                    1.60737e+09  18.907433
565                    1.60737e+09  18.819677
566                    1.60737e+09  18.791470
567                    1.60737e+09  18.819677

[1500 rows x 2 columns]}
2020-12-07 14:44:13,972 - callbacks - DEBUG - {'Hybrid_Mux':                  measurement_time       FORT
50  2020-12-07 20:39:04.124000072  18.932500
51  2020-12-07 20:39:04.322999954  18.916800
52  2020-12-07 20:39:04.523999929  18.907400
53  2020-12-07 20:39:04.765000105  18.910600
54  2020-12-07 20:39:04.947000027  18.904300
..                            ...        ...
45                    1.60737e+09  18.857286
46                    1.60737e+09  18.844749
47                    1.60737e+09  18.876091
48                    1.60737e+09  18.851019
49                    1.60737e+09  18.822811

[1500 rows x 2 columns]}
2020-12-07 14:50:11,189 - callbacks - DEBUG -                 measurement_time     FORT
32 2020-12-07 20:40:25.523000001  18.8479
33 2020-12-07 20:40:25.724999905  18.8447
34 2020-12-07 20:40:25.923000097  18.8291
35 2020-12-07 20:40:26.128999949  18.8071
36 2020-12-07 20:40:26.358999968  18.8385
2020-12-07 14:50:11,224 - callbacks - DEBUG -                 measurement_time       FORT
27 2020-12-07 20:45:49.128999949  18.816544
28 2020-12-07 20:45:49.339999914  18.772665
29 2020-12-07 20:45:49.529000044  18.800873
30 2020-12-07 20:45:49.730000019  18.797737
31 2020-12-07 20:45:49.930000067  18.810274
2020-12-07 14:51:35,109 - callbacks - DEBUG -                  measurement_time     FORT
110 2020-12-07 20:46:47.042000055  18.7351
111 2020-12-07 20:46:47.263999939  18.8103
112 2020-12-07 20:46:47.430999994  18.8510
113 2020-12-07 20:46:47.628999949  18.8573
114 2020-12-07 20:46:47.828999996  18.7977
2020-12-07 14:51:35,165 - callbacks - DEBUG -                  measurement_time       FORT
105 2020-12-07 20:51:39.078999996  18.929373
106 2020-12-07 20:51:39.233999968  18.926239
107 2020-12-07 20:51:39.434999943  18.941910
108 2020-12-07 20:51:39.634000063  18.879227
109 2020-12-07 20:51:39.835000038  18.841616
2020-12-07 14:51:45,090 - callbacks - DEBUG -            measurement_time     FORT
160 2020-12-07 20:46:57.033  18.8291
161 2020-12-07 20:46:57.265  18.8416
162 2020-12-07 20:46:57.430  18.8604
163 2020-12-07 20:46:57.630  18.8792
164 2020-12-07 20:46:57.829  18.8479
2020-12-07 14:51:45,122 - callbacks - DEBUG -                 measurement_time       FORT
45 2020-12-07 20:51:49.061000109  18.913702
46 2020-12-07 20:51:49.233999968  18.904299
47 2020-12-07 20:51:49.434000015  18.885494
48 2020-12-07 20:51:49.632999897  18.898031
49 2020-12-07 20:51:49.834000111  18.941910
2020-12-07 14:51:55,061 - callbacks - DEBUG -            measurement_time     FORT
160 2020-12-07 20:46:57.033  18.8291
161 2020-12-07 20:46:57.265  18.8416
162 2020-12-07 20:46:57.430  18.8604
163 2020-12-07 20:46:57.630  18.8792
164 2020-12-07 20:46:57.829  18.8479
2020-12-07 14:51:55,189 - callbacks - DEBUG -                 measurement_time       FORT
45 2020-12-07 20:51:59.059000015  18.891762
46 2020-12-07 20:51:59.233999968  18.901165
47 2020-12-07 20:51:59.433000088  18.923103
48 2020-12-07 20:51:59.634999990  18.926239
49 2020-12-07 20:51:59.832999945  18.882360
2020-12-07 14:52:05,045 - callbacks - DEBUG -            measurement_time     FORT
160 2020-12-07 20:46:57.033  18.8291
161 2020-12-07 20:46:57.265  18.8416
162 2020-12-07 20:46:57.430  18.8604
163 2020-12-07 20:46:57.630  18.8792
164 2020-12-07 20:46:57.829  18.8479
2020-12-07 14:52:05,060 - callbacks - DEBUG -                 measurement_time       FORT
45 2020-12-07 20:52:09.035000086  18.841616
46 2020-12-07 20:52:09.233999968  18.844749
47 2020-12-07 20:52:09.434999943  18.807140
48 2020-12-07 20:52:09.634000063  18.772665
49 2020-12-07 20:52:09.835000038  18.753860
2020-12-07 14:54:58,052 - callbacks - DEBUG -                measurement_time       FORT
0 2020-12-07 20:52:10.042000055  18.794603
1 2020-12-07 20:52:10.273000002  18.797737
2 2020-12-07 20:52:10.434999943  18.791470
3 2020-12-07 20:52:10.634000063  18.807140
4 2020-12-07 20:52:10.834000111  18.807140
2020-12-07 14:54:58,071 - callbacks - DEBUG -                   measurement_time     FORT
1495 2020-12-07 20:54:47.035000086  18.9043
1496 2020-12-07 20:54:47.246999979  18.9043
1497 2020-12-07 20:54:47.434999943  18.8792
1498 2020-12-07 20:54:47.634999990  18.8385
1499 2020-12-07 20:54:47.835000038  18.7977
2020-12-07 14:55:08,002 - callbacks - DEBUG -                measurement_time       FORT
0 2020-12-07 20:55:03.035000086  18.788336
1 2020-12-07 20:55:03.236000061  18.760128
2 2020-12-07 20:55:03.434000015  18.804007
3 2020-12-07 20:55:03.680999994  18.835348
4 2020-12-07 20:55:03.835000038  18.788336
2020-12-07 14:55:08,083 - callbacks - DEBUG -             measurement_time     FORT
1495 2020-12-07 20:54:47.035  18.9043
1496 2020-12-07 20:54:47.246  18.9043
1497 2020-12-07 20:54:47.434  18.8792
1498 2020-12-07 20:54:47.634  18.8385
1499 2020-12-07 20:54:47.835  18.7977
2020-12-07 14:55:18,063 - callbacks - DEBUG -                measurement_time       FORT
0 2020-12-07 20:55:12.835999966  18.794603
1 2020-12-07 20:55:13.036999941  18.810274
2 2020-12-07 20:55:13.236000061  18.819677
3 2020-12-07 20:55:13.436000109  18.819677
4 2020-12-07 20:55:13.667000055  18.816544
2020-12-07 14:55:18,076 - callbacks - DEBUG -             measurement_time     FORT
1495 2020-12-07 20:54:47.035  18.9043
1496 2020-12-07 20:54:47.246  18.9043
1497 2020-12-07 20:54:47.434  18.8792
1498 2020-12-07 20:54:47.634  18.8385
1499 2020-12-07 20:54:47.835  18.7977
2020-12-07 14:55:28,002 - callbacks - DEBUG -                measurement_time       FORT
0 2020-12-07 20:55:23.036000013  18.851019
1 2020-12-07 20:55:23.236999989  18.854153
2 2020-12-07 20:55:23.447999954  18.860420
3 2020-12-07 20:55:23.664000034  18.876091
4 2020-12-07 20:55:23.836999893  18.829079
2020-12-07 14:55:28,033 - callbacks - DEBUG -             measurement_time     FORT
1495 2020-12-07 20:54:47.035  18.9043
1496 2020-12-07 20:54:47.246  18.9043
1497 2020-12-07 20:54:47.434  18.8792
1498 2020-12-07 20:54:47.634  18.8385
1499 2020-12-07 20:54:47.835  18.7977
2020-12-07 15:23:21,269 - callbacks - DEBUG - None
2020-12-07 15:23:22,868 - callbacks - DEBUG - 1607376200.9709282
2020-12-07 15:24:47,808 - callbacks - DEBUG - None
2020-12-07 15:24:49,168 - callbacks - DEBUG - 1607376287.20984
2020-12-07 15:28:57,753 - callbacks - DEBUG - None
2020-12-07 15:28:59,589 - callbacks - DEBUG - 1607376537.7043352
2020-12-07 15:34:11,614 - callbacks - DEBUG - None
2020-12-07 15:34:13,456 - callbacks - DEBUG - 1607376851.4233978
2020-12-07 15:35:18,906 - callbacks - DEBUG - None
2020-12-07 15:35:20,627 - callbacks - DEBUG - 1607376918.321632
2020-12-07 15:36:22,754 - callbacks - DEBUG - None
2020-12-07 15:36:24,517 - callbacks - DEBUG - 1607376982.668967
2020-12-07 15:46:09,338 - callbacks - DEBUG - None
2020-12-07 15:46:11,038 - callbacks - DEBUG - 1607377568.630461
2020-12-07 16:02:03,834 - callbacks - DEBUG - None
2020-12-07 16:02:05,659 - callbacks - DEBUG - 1607378523.385078
2020-12-07 16:02:59,982 - callbacks - DEBUG - 1607378578.1455739
2020-12-07 16:03:53,599 - callbacks - DEBUG - None
2020-12-07 16:03:55,551 - callbacks - DEBUG - 1607378633.526082
2020-12-07 16:06:40,340 - callbacks - DEBUG - 1607378798.333062
2020-12-07 16:08:44,542 - callbacks - DEBUG - 1607378922.567607
2020-12-07 16:09:33,436 - callbacks - DEBUG - 1607378971.6459122
2020-12-07 16:10:35,205 - callbacks - DEBUG - 1607379033.2042391
2020-12-07 16:11:51,025 - callbacks - DEBUG - 1607379109.2102149
2020-12-07 16:13:44,432 - callbacks - DEBUG - 1607379222.484425
2020-12-07 16:13:44,962 - callbacks - ERROR - The server responds to the request with error message: `Stream declared, but no data in range.`
2020-12-07 16:13:44,963 - callbacks - INFO - Updating stream definitions from server.
2020-12-07 16:13:45,107 - callbacks - ERROR - The server responds to the request with error message: `Stream declared, but no data in range.`
2020-12-07 16:13:45,107 - callbacks - INFO - Updating stream definitions from server.
2020-12-07 16:13:46,449 - callbacks - DEBUG - 1607379222.484425
2020-12-07 16:13:46,996 - callbacks - ERROR - The server responds to the request with error message: `Stream declared, but no data in range.`
2020-12-07 16:13:46,997 - callbacks - INFO - Updating stream definitions from server.
2020-12-07 16:13:47,138 - callbacks - ERROR - The server responds to the request with error message: `Stream declared, but no data in range.`
2020-12-07 16:13:47,138 - callbacks - INFO - Updating stream definitions from server.
2020-12-07 16:13:48,456 - callbacks - DEBUG - 1607379222.484425
2020-12-07 16:13:48,973 - callbacks - ERROR - The server responds to the request with error message: `Stream declared, but no data in range.`
2020-12-07 16:13:48,974 - callbacks - INFO - Updating stream definitions from server.
2020-12-07 16:13:49,157 - callbacks - ERROR - The server responds to the request with error message: `Stream declared, but no data in range.`
2020-12-07 16:13:49,157 - callbacks - INFO - Updating stream definitions from server.
2020-12-07 16:13:50,488 - callbacks - DEBUG - 1607379222.484425
2020-12-07 16:13:51,005 - callbacks - ERROR - The server responds to the request with error message: `Stream declared, but no data in range.`
2020-12-07 16:13:51,005 - callbacks - INFO - Updating stream definitions from server.
2020-12-07 16:13:51,196 - callbacks - ERROR - The server responds to the request with error message: `Stream declared, but no data in range.`
2020-12-07 16:13:51,196 - callbacks - INFO - Updating stream definitions from server.
2020-12-07 16:13:52,442 - callbacks - DEBUG - 1607379222.484425
2020-12-07 16:13:52,990 - callbacks - ERROR - The server responds to the request with error message: `Stream declared, but no data in range.`
2020-12-07 16:13:52,990 - callbacks - INFO - Updating stream definitions from server.
2020-12-07 16:13:53,175 - callbacks - ERROR - The server responds to the request with error message: `Stream declared, but no data in range.`
2020-12-07 16:13:53,175 - callbacks - INFO - Updating stream definitions from server.
2020-12-07 16:13:54,441 - callbacks - DEBUG - 1607379222.484425
2020-12-07 16:13:54,990 - callbacks - ERROR - The server responds to the request with error message: `Stream declared, but no data in range.`
2020-12-07 16:13:54,990 - callbacks - INFO - Updating stream definitions from server.
2020-12-07 16:13:55,125 - callbacks - ERROR - The server responds to the request with error message: `Stream declared, but no data in range.`
2020-12-07 16:13:55,125 - callbacks - INFO - Updating stream definitions from server.
2020-12-07 16:13:56,446 - callbacks - DEBUG - 1607379222.484425
2020-12-07 16:13:57,005 - callbacks - ERROR - The server responds to the request with error message: `Stream declared, but no data in range.`
2020-12-07 16:13:57,005 - callbacks - INFO - Updating stream definitions from server.
2020-12-07 16:13:57,152 - callbacks - ERROR - The server responds to the request with error message: `Stream declared, but no data in range.`
2020-12-07 16:13:57,152 - callbacks - INFO - Updating stream definitions from server.
2020-12-07 16:14:21,064 - callbacks - DEBUG - 1607379222.484425
2020-12-07 16:14:21,903 - callbacks - ERROR - The server responds to the request with error message: `Stream declared, but no data in range.`
2020-12-07 16:14:21,903 - callbacks - INFO - Updating stream definitions from server.
2020-12-07 16:14:22,085 - callbacks - ERROR - The server responds to the request with error message: `Stream declared, but no data in range.`
2020-12-07 16:14:22,085 - callbacks - INFO - Updating stream definitions from server.
2020-12-07 16:14:26,251 - callbacks - DEBUG - 1607379264.332601
2020-12-07 16:14:26,432 - callbacks - ERROR - The server responds to the request with error message: `Stream declared, but no data in range.`
2020-12-07 16:14:26,433 - callbacks - INFO - Updating stream definitions from server.
2020-12-07 16:14:28,348 - callbacks - DEBUG - 1607379264.332601
2020-12-07 16:14:28,535 - callbacks - ERROR - The server responds to the request with error message: `Stream declared, but no data in range.`
2020-12-07 16:14:28,535 - callbacks - INFO - Updating stream definitions from server.
2020-12-07 16:14:30,293 - callbacks - DEBUG - 1607379264.332601
2020-12-07 16:14:30,478 - callbacks - ERROR - The server responds to the request with error message: `Stream declared, but no data in range.`
2020-12-07 16:14:30,478 - callbacks - INFO - Updating stream definitions from server.
2020-12-07 16:14:32,284 - callbacks - DEBUG - 1607379264.332601
2020-12-07 16:14:32,472 - callbacks - ERROR - The server responds to the request with error message: `Stream declared, but no data in range.`
2020-12-07 16:14:32,472 - callbacks - INFO - Updating stream definitions from server.
2020-12-07 16:14:34,312 - callbacks - DEBUG - 1607379264.332601
2020-12-07 16:14:34,495 - callbacks - ERROR - The server responds to the request with error message: `Stream declared, but no data in range.`
2020-12-07 16:14:34,496 - callbacks - INFO - Updating stream definitions from server.
2020-12-07 16:14:36,278 - callbacks - DEBUG - 1607379264.332601
2020-12-07 16:14:36,469 - callbacks - ERROR - The server responds to the request with error message: `Stream declared, but no data in range.`
2020-12-07 16:14:36,469 - callbacks - INFO - Updating stream definitions from server.
2020-12-07 16:19:54,255 - callbacks - DEBUG - 1607379592.3186822
2020-12-07 16:19:54,439 - callbacks - ERROR - The server responds to the request with error message: `Stream declared, but no data in range.`
2020-12-07 16:19:54,439 - callbacks - INFO - Updating stream definitions from server.
2020-12-07 16:19:56,262 - callbacks - DEBUG - 1607379592.3186822
2020-12-07 16:19:56,421 - callbacks - ERROR - The server responds to the request with error message: `Stream declared, but no data in range.`
2020-12-07 16:19:56,421 - callbacks - INFO - Updating stream definitions from server.
2020-12-07 16:19:58,265 - callbacks - DEBUG - 1607379592.3186822
2020-12-07 16:19:58,446 - callbacks - ERROR - The server responds to the request with error message: `Stream declared, but no data in range.`
2020-12-07 16:19:58,446 - callbacks - INFO - Updating stream definitions from server.
2020-12-07 16:20:00,260 - callbacks - DEBUG - 1607379592.3186822
2020-12-07 16:20:00,446 - callbacks - ERROR - The server responds to the request with error message: `Stream declared, but no data in range.`
2020-12-07 16:20:00,446 - callbacks - INFO - Updating stream definitions from server.
2020-12-07 16:20:02,281 - callbacks - DEBUG - 1607379592.3186822
2020-12-07 16:20:02,500 - callbacks - ERROR - The server responds to the request with error message: `Stream declared, but no data in range.`
2020-12-07 16:20:02,500 - callbacks - INFO - Updating stream definitions from server.
2020-12-07 16:20:04,307 - callbacks - DEBUG - 1607379592.3186822
2020-12-07 16:20:04,497 - callbacks - ERROR - The server responds to the request with error message: `Stream declared, but no data in range.`
2020-12-07 16:20:04,498 - callbacks - INFO - Updating stream definitions from server.
2020-12-07 16:23:10,839 - callbacks - DEBUG - 1607379592.3186822
2020-12-07 16:23:11,052 - callbacks - ERROR - The server responds to the request with error message: `Stream declared, but no data in range.`
2020-12-07 16:23:11,052 - callbacks - INFO - Updating stream definitions from server.
2020-12-07 16:24:05,770 - callbacks - DEBUG - 1607379843.403379
2020-12-07 16:25:41,328 - callbacks - DEBUG - 1607379939.423929
2020-12-07 17:02:43,274 - callbacks - DEBUG - 1607382161.1938848
2020-12-07 17:04:10,551 - callbacks - DEBUG - 1607382248.40146
2020-12-07 17:16:32,155 - callbacks - ERROR - [Errno 2] No such file or directory: 'data0038.csv'
Traceback (most recent call last):
  File "/Users/bradleynordin/Documents/GraphingData/callbacks.py", line 90, in updateData
    df = pd.read_csv(file)
  File "/Users/bradleynordin/.local/share/virtualenvs/GraphingData-5SWGkA_0/lib/python3.8/site-packages/pandas/io/parsers.py", line 688, in read_csv
    return _read(filepath_or_buffer, kwds)
  File "/Users/bradleynordin/.local/share/virtualenvs/GraphingData-5SWGkA_0/lib/python3.8/site-packages/pandas/io/parsers.py", line 454, in _read
    parser = TextFileReader(fp_or_buf, **kwds)
  File "/Users/bradleynordin/.local/share/virtualenvs/GraphingData-5SWGkA_0/lib/python3.8/site-packages/pandas/io/parsers.py", line 948, in __init__
    self._make_engine(self.engine)
  File "/Users/bradleynordin/.local/share/virtualenvs/GraphingData-5SWGkA_0/lib/python3.8/site-packages/pandas/io/parsers.py", line 1180, in _make_engine
    self._engine = CParserWrapper(self.f, **self.options)
  File "/Users/bradleynordin/.local/share/virtualenvs/GraphingData-5SWGkA_0/lib/python3.8/site-packages/pandas/io/parsers.py", line 2010, in __init__
    self._reader = parsers.TextReader(src, **kwds)
  File "pandas/_libs/parsers.pyx", line 382, in pandas._libs.parsers.TextReader.__cinit__
  File "pandas/_libs/parsers.pyx", line 674, in pandas._libs.parsers.TextReader._setup_parser_source
FileNotFoundError: [Errno 2] No such file or directory: 'data0038.csv'
2020-12-07 17:16:33,346 - callbacks - ERROR - [Errno 2] No such file or directory: 'data0038.csv'
Traceback (most recent call last):
  File "/Users/bradleynordin/Documents/GraphingData/callbacks.py", line 90, in updateData
    df = pd.read_csv(file)
  File "/Users/bradleynordin/.local/share/virtualenvs/GraphingData-5SWGkA_0/lib/python3.8/site-packages/pandas/io/parsers.py", line 688, in read_csv
    return _read(filepath_or_buffer, kwds)
  File "/Users/bradleynordin/.local/share/virtualenvs/GraphingData-5SWGkA_0/lib/python3.8/site-packages/pandas/io/parsers.py", line 454, in _read
    parser = TextFileReader(fp_or_buf, **kwds)
  File "/Users/bradleynordin/.local/share/virtualenvs/GraphingData-5SWGkA_0/lib/python3.8/site-packages/pandas/io/parsers.py", line 948, in __init__
    self._make_engine(self.engine)
  File "/Users/bradleynordin/.local/share/virtualenvs/GraphingData-5SWGkA_0/lib/python3.8/site-packages/pandas/io/parsers.py", line 1180, in _make_engine
    self._engine = CParserWrapper(self.f, **self.options)
  File "/Users/bradleynordin/.local/share/virtualenvs/GraphingData-5SWGkA_0/lib/python3.8/site-packages/pandas/io/parsers.py", line 2010, in __init__
    self._reader = parsers.TextReader(src, **kwds)
  File "pandas/_libs/parsers.pyx", line 382, in pandas._libs.parsers.TextReader.__cinit__
  File "pandas/_libs/parsers.pyx", line 674, in pandas._libs.parsers.TextReader._setup_parser_source
FileNotFoundError: [Errno 2] No such file or directory: 'data0038.csv'
2020-12-07 17:16:43,536 - callbacks - DEBUG - 1607383002.5793018
2020-12-07 17:24:54,178 - callbacks - ERROR - 'measurement_time'
Traceback (most recent call last):
  File "/Users/bradleynordin/.local/share/virtualenvs/GraphingData-5SWGkA_0/lib/python3.8/site-packages/pandas/core/indexes/base.py", line 2895, in get_loc
    return self._engine.get_loc(casted_key)
  File "pandas/_libs/index.pyx", line 70, in pandas._libs.index.IndexEngine.get_loc
  File "pandas/_libs/index.pyx", line 101, in pandas._libs.index.IndexEngine.get_loc
  File "pandas/_libs/hashtable_class_helper.pxi", line 1675, in pandas._libs.hashtable.PyObjectHashTable.get_item
  File "pandas/_libs/hashtable_class_helper.pxi", line 1683, in pandas._libs.hashtable.PyObjectHashTable.get_item
KeyError: 'measurement_time'

The above exception was the direct cause of the following exception:

Traceback (most recent call last):
  File "/Users/bradleynordin/Documents/GraphingData/callbacks.py", line 94, in updateData
    data[stream] = df
  File "/Users/bradleynordin/.local/share/virtualenvs/GraphingData-5SWGkA_0/lib/python3.8/site-packages/pandas/core/frame.py", line 2906, in __getitem__
    indexer = self.columns.get_loc(key)
  File "/Users/bradleynordin/.local/share/virtualenvs/GraphingData-5SWGkA_0/lib/python3.8/site-packages/pandas/core/indexes/base.py", line 2897, in get_loc
    raise KeyError(key) from err
KeyError: 'measurement_time'
2020-12-07 17:24:56,183 - callbacks - ERROR - 'measurement_time'
Traceback (most recent call last):
  File "/Users/bradleynordin/.local/share/virtualenvs/GraphingData-5SWGkA_0/lib/python3.8/site-packages/pandas/core/indexes/base.py", line 2895, in get_loc
    return self._engine.get_loc(casted_key)
  File "pandas/_libs/index.pyx", line 70, in pandas._libs.index.IndexEngine.get_loc
  File "pandas/_libs/index.pyx", line 101, in pandas._libs.index.IndexEngine.get_loc
  File "pandas/_libs/hashtable_class_helper.pxi", line 1675, in pandas._libs.hashtable.PyObjectHashTable.get_item
  File "pandas/_libs/hashtable_class_helper.pxi", line 1683, in pandas._libs.hashtable.PyObjectHashTable.get_item
KeyError: 'measurement_time'

The above exception was the direct cause of the following exception:

Traceback (most recent call last):
  File "/Users/bradleynordin/Documents/GraphingData/callbacks.py", line 94, in updateData
    data[stream] = df
  File "/Users/bradleynordin/.local/share/virtualenvs/GraphingData-5SWGkA_0/lib/python3.8/site-packages/pandas/core/frame.py", line 2906, in __getitem__
    indexer = self.columns.get_loc(key)
  File "/Users/bradleynordin/.local/share/virtualenvs/GraphingData-5SWGkA_0/lib/python3.8/site-packages/pandas/core/indexes/base.py", line 2897, in get_loc
    raise KeyError(key) from err
KeyError: 'measurement_time'
2020-12-07 17:24:58,178 - callbacks - ERROR - 'measurement_time'
Traceback (most recent call last):
  File "/Users/bradleynordin/.local/share/virtualenvs/GraphingData-5SWGkA_0/lib/python3.8/site-packages/pandas/core/indexes/base.py", line 2895, in get_loc
    return self._engine.get_loc(casted_key)
  File "pandas/_libs/index.pyx", line 70, in pandas._libs.index.IndexEngine.get_loc
  File "pandas/_libs/index.pyx", line 101, in pandas._libs.index.IndexEngine.get_loc
  File "pandas/_libs/hashtable_class_helper.pxi", line 1675, in pandas._libs.hashtable.PyObjectHashTable.get_item
  File "pandas/_libs/hashtable_class_helper.pxi", line 1683, in pandas._libs.hashtable.PyObjectHashTable.get_item
KeyError: 'measurement_time'

The above exception was the direct cause of the following exception:

Traceback (most recent call last):
  File "/Users/bradleynordin/Documents/GraphingData/callbacks.py", line 94, in updateData
    data[stream] = df
  File "/Users/bradleynordin/.local/share/virtualenvs/GraphingData-5SWGkA_0/lib/python3.8/site-packages/pandas/core/frame.py", line 2906, in __getitem__
    indexer = self.columns.get_loc(key)
  File "/Users/bradleynordin/.local/share/virtualenvs/GraphingData-5SWGkA_0/lib/python3.8/site-packages/pandas/core/indexes/base.py", line 2897, in get_loc
    raise KeyError(key) from err
KeyError: 'measurement_time'
2020-12-07 17:25:00,193 - callbacks - ERROR - 'measurement_time'
Traceback (most recent call last):
  File "/Users/bradleynordin/.local/share/virtualenvs/GraphingData-5SWGkA_0/lib/python3.8/site-packages/pandas/core/indexes/base.py", line 2895, in get_loc
    return self._engine.get_loc(casted_key)
  File "pandas/_libs/index.pyx", line 70, in pandas._libs.index.IndexEngine.get_loc
  File "pandas/_libs/index.pyx", line 101, in pandas._libs.index.IndexEngine.get_loc
  File "pandas/_libs/hashtable_class_helper.pxi", line 1675, in pandas._libs.hashtable.PyObjectHashTable.get_item
  File "pandas/_libs/hashtable_class_helper.pxi", line 1683, in pandas._libs.hashtable.PyObjectHashTable.get_item
KeyError: 'measurement_time'

The above exception was the direct cause of the following exception:

Traceback (most recent call last):
  File "/Users/bradleynordin/Documents/GraphingData/callbacks.py", line 94, in updateData
    data[stream] = df
  File "/Users/bradleynordin/.local/share/virtualenvs/GraphingData-5SWGkA_0/lib/python3.8/site-packages/pandas/core/frame.py", line 2906, in __getitem__
    indexer = self.columns.get_loc(key)
  File "/Users/bradleynordin/.local/share/virtualenvs/GraphingData-5SWGkA_0/lib/python3.8/site-packages/pandas/core/indexes/base.py", line 2897, in get_loc
    raise KeyError(key) from err
KeyError: 'measurement_time'
2020-12-07 17:25:02,203 - callbacks - ERROR - 'measurement_time'
Traceback (most recent call last):
  File "/Users/bradleynordin/.local/share/virtualenvs/GraphingData-5SWGkA_0/lib/python3.8/site-packages/pandas/core/indexes/base.py", line 2895, in get_loc
    return self._engine.get_loc(casted_key)
  File "pandas/_libs/index.pyx", line 70, in pandas._libs.index.IndexEngine.get_loc
  File "pandas/_libs/index.pyx", line 101, in pandas._libs.index.IndexEngine.get_loc
  File "pandas/_libs/hashtable_class_helper.pxi", line 1675, in pandas._libs.hashtable.PyObjectHashTable.get_item
  File "pandas/_libs/hashtable_class_helper.pxi", line 1683, in pandas._libs.hashtable.PyObjectHashTable.get_item
KeyError: 'measurement_time'

The above exception was the direct cause of the following exception:

Traceback (most recent call last):
  File "/Users/bradleynordin/Documents/GraphingData/callbacks.py", line 94, in updateData
    data[stream] = df
  File "/Users/bradleynordin/.local/share/virtualenvs/GraphingData-5SWGkA_0/lib/python3.8/site-packages/pandas/core/frame.py", line 2906, in __getitem__
    indexer = self.columns.get_loc(key)
  File "/Users/bradleynordin/.local/share/virtualenvs/GraphingData-5SWGkA_0/lib/python3.8/site-packages/pandas/core/indexes/base.py", line 2897, in get_loc
    raise KeyError(key) from err
KeyError: 'measurement_time'
2020-12-07 17:25:04,206 - callbacks - ERROR - 'measurement_time'
Traceback (most recent call last):
  File "/Users/bradleynordin/.local/share/virtualenvs/GraphingData-5SWGkA_0/lib/python3.8/site-packages/pandas/core/indexes/base.py", line 2895, in get_loc
    return self._engine.get_loc(casted_key)
  File "pandas/_libs/index.pyx", line 70, in pandas._libs.index.IndexEngine.get_loc
  File "pandas/_libs/index.pyx", line 101, in pandas._libs.index.IndexEngine.get_loc
  File "pandas/_libs/hashtable_class_helper.pxi", line 1675, in pandas._libs.hashtable.PyObjectHashTable.get_item
  File "pandas/_libs/hashtable_class_helper.pxi", line 1683, in pandas._libs.hashtable.PyObjectHashTable.get_item
KeyError: 'measurement_time'

The above exception was the direct cause of the following exception:

Traceback (most recent call last):
  File "/Users/bradleynordin/Documents/GraphingData/callbacks.py", line 94, in updateData
    data[stream] = df
  File "/Users/bradleynordin/.local/share/virtualenvs/GraphingData-5SWGkA_0/lib/python3.8/site-packages/pandas/core/frame.py", line 2906, in __getitem__
    indexer = self.columns.get_loc(key)
  File "/Users/bradleynordin/.local/share/virtualenvs/GraphingData-5SWGkA_0/lib/python3.8/site-packages/pandas/core/indexes/base.py", line 2897, in get_loc
    raise KeyError(key) from err
KeyError: 'measurement_time'
2020-12-07 17:25:06,220 - callbacks - ERROR - 'measurement_time'
Traceback (most recent call last):
  File "/Users/bradleynordin/.local/share/virtualenvs/GraphingData-5SWGkA_0/lib/python3.8/site-packages/pandas/core/indexes/base.py", line 2895, in get_loc
    return self._engine.get_loc(casted_key)
  File "pandas/_libs/index.pyx", line 70, in pandas._libs.index.IndexEngine.get_loc
  File "pandas/_libs/index.pyx", line 101, in pandas._libs.index.IndexEngine.get_loc
  File "pandas/_libs/hashtable_class_helper.pxi", line 1675, in pandas._libs.hashtable.PyObjectHashTable.get_item
  File "pandas/_libs/hashtable_class_helper.pxi", line 1683, in pandas._libs.hashtable.PyObjectHashTable.get_item
KeyError: 'measurement_time'

The above exception was the direct cause of the following exception:

Traceback (most recent call last):
  File "/Users/bradleynordin/Documents/GraphingData/callbacks.py", line 94, in updateData
    data[stream] = df
  File "/Users/bradleynordin/.local/share/virtualenvs/GraphingData-5SWGkA_0/lib/python3.8/site-packages/pandas/core/frame.py", line 2906, in __getitem__
    indexer = self.columns.get_loc(key)
  File "/Users/bradleynordin/.local/share/virtualenvs/GraphingData-5SWGkA_0/lib/python3.8/site-packages/pandas/core/indexes/base.py", line 2897, in get_loc
    raise KeyError(key) from err
KeyError: 'measurement_time'
2020-12-07 17:25:08,216 - callbacks - ERROR - 'measurement_time'
Traceback (most recent call last):
  File "/Users/bradleynordin/.local/share/virtualenvs/GraphingData-5SWGkA_0/lib/python3.8/site-packages/pandas/core/indexes/base.py", line 2895, in get_loc
    return self._engine.get_loc(casted_key)
  File "pandas/_libs/index.pyx", line 70, in pandas._libs.index.IndexEngine.get_loc
  File "pandas/_libs/index.pyx", line 101, in pandas._libs.index.IndexEngine.get_loc
  File "pandas/_libs/hashtable_class_helper.pxi", line 1675, in pandas._libs.hashtable.PyObjectHashTable.get_item
  File "pandas/_libs/hashtable_class_helper.pxi", line 1683, in pandas._libs.hashtable.PyObjectHashTable.get_item
KeyError: 'measurement_time'

The above exception was the direct cause of the following exception:

Traceback (most recent call last):
  File "/Users/bradleynordin/Documents/GraphingData/callbacks.py", line 94, in updateData
    data[stream] = df
  File "/Users/bradleynordin/.local/share/virtualenvs/GraphingData-5SWGkA_0/lib/python3.8/site-packages/pandas/core/frame.py", line 2906, in __getitem__
    indexer = self.columns.get_loc(key)
  File "/Users/bradleynordin/.local/share/virtualenvs/GraphingData-5SWGkA_0/lib/python3.8/site-packages/pandas/core/indexes/base.py", line 2897, in get_loc
    raise KeyError(key) from err
KeyError: 'measurement_time'
2020-12-07 17:25:10,269 - callbacks - ERROR - 'measurement_time'
Traceback (most recent call last):
  File "/Users/bradleynordin/.local/share/virtualenvs/GraphingData-5SWGkA_0/lib/python3.8/site-packages/pandas/core/indexes/base.py", line 2895, in get_loc
    return self._engine.get_loc(casted_key)
  File "pandas/_libs/index.pyx", line 70, in pandas._libs.index.IndexEngine.get_loc
  File "pandas/_libs/index.pyx", line 101, in pandas._libs.index.IndexEngine.get_loc
  File "pandas/_libs/hashtable_class_helper.pxi", line 1675, in pandas._libs.hashtable.PyObjectHashTable.get_item
  File "pandas/_libs/hashtable_class_helper.pxi", line 1683, in pandas._libs.hashtable.PyObjectHashTable.get_item
KeyError: 'measurement_time'

The above exception was the direct cause of the following exception:

Traceback (most recent call last):
  File "/Users/bradleynordin/Documents/GraphingData/callbacks.py", line 94, in updateData
    data[stream] = df
  File "/Users/bradleynordin/.local/share/virtualenvs/GraphingData-5SWGkA_0/lib/python3.8/site-packages/pandas/core/frame.py", line 2906, in __getitem__
    indexer = self.columns.get_loc(key)
  File "/Users/bradleynordin/.local/share/virtualenvs/GraphingData-5SWGkA_0/lib/python3.8/site-packages/pandas/core/indexes/base.py", line 2897, in get_loc
    raise KeyError(key) from err
KeyError: 'measurement_time'
2020-12-07 17:25:12,219 - callbacks - ERROR - 'measurement_time'
Traceback (most recent call last):
  File "/Users/bradleynordin/.local/share/virtualenvs/GraphingData-5SWGkA_0/lib/python3.8/site-packages/pandas/core/indexes/base.py", line 2895, in get_loc
    return self._engine.get_loc(casted_key)
  File "pandas/_libs/index.pyx", line 70, in pandas._libs.index.IndexEngine.get_loc
  File "pandas/_libs/index.pyx", line 101, in pandas._libs.index.IndexEngine.get_loc
  File "pandas/_libs/hashtable_class_helper.pxi", line 1675, in pandas._libs.hashtable.PyObjectHashTable.get_item
  File "pandas/_libs/hashtable_class_helper.pxi", line 1683, in pandas._libs.hashtable.PyObjectHashTable.get_item
KeyError: 'measurement_time'

The above exception was the direct cause of the following exception:

Traceback (most recent call last):
  File "/Users/bradleynordin/Documents/GraphingData/callbacks.py", line 94, in updateData
    data[stream] = df
  File "/Users/bradleynordin/.local/share/virtualenvs/GraphingData-5SWGkA_0/lib/python3.8/site-packages/pandas/core/frame.py", line 2906, in __getitem__
    indexer = self.columns.get_loc(key)
  File "/Users/bradleynordin/.local/share/virtualenvs/GraphingData-5SWGkA_0/lib/python3.8/site-packages/pandas/core/indexes/base.py", line 2897, in get_loc
    raise KeyError(key) from err
KeyError: 'measurement_time'
2020-12-07 17:25:14,230 - callbacks - ERROR - 'measurement_time'
Traceback (most recent call last):
  File "/Users/bradleynordin/.local/share/virtualenvs/GraphingData-5SWGkA_0/lib/python3.8/site-packages/pandas/core/indexes/base.py", line 2895, in get_loc
    return self._engine.get_loc(casted_key)
  File "pandas/_libs/index.pyx", line 70, in pandas._libs.index.IndexEngine.get_loc
  File "pandas/_libs/index.pyx", line 101, in pandas._libs.index.IndexEngine.get_loc
  File "pandas/_libs/hashtable_class_helper.pxi", line 1675, in pandas._libs.hashtable.PyObjectHashTable.get_item
  File "pandas/_libs/hashtable_class_helper.pxi", line 1683, in pandas._libs.hashtable.PyObjectHashTable.get_item
KeyError: 'measurement_time'

The above exception was the direct cause of the following exception:

Traceback (most recent call last):
  File "/Users/bradleynordin/Documents/GraphingData/callbacks.py", line 94, in updateData
    data[stream] = df
  File "/Users/bradleynordin/.local/share/virtualenvs/GraphingData-5SWGkA_0/lib/python3.8/site-packages/pandas/core/frame.py", line 2906, in __getitem__
    indexer = self.columns.get_loc(key)
  File "/Users/bradleynordin/.local/share/virtualenvs/GraphingData-5SWGkA_0/lib/python3.8/site-packages/pandas/core/indexes/base.py", line 2897, in get_loc
    raise KeyError(key) from err
KeyError: 'measurement_time'
2020-12-07 17:25:16,209 - callbacks - ERROR - 'measurement_time'
Traceback (most recent call last):
  File "/Users/bradleynordin/.local/share/virtualenvs/GraphingData-5SWGkA_0/lib/python3.8/site-packages/pandas/core/indexes/base.py", line 2895, in get_loc
    return self._engine.get_loc(casted_key)
  File "pandas/_libs/index.pyx", line 70, in pandas._libs.index.IndexEngine.get_loc
  File "pandas/_libs/index.pyx", line 101, in pandas._libs.index.IndexEngine.get_loc
  File "pandas/_libs/hashtable_class_helper.pxi", line 1675, in pandas._libs.hashtable.PyObjectHashTable.get_item
  File "pandas/_libs/hashtable_class_helper.pxi", line 1683, in pandas._libs.hashtable.PyObjectHashTable.get_item
KeyError: 'measurement_time'

The above exception was the direct cause of the following exception:

Traceback (most recent call last):
  File "/Users/bradleynordin/Documents/GraphingData/callbacks.py", line 94, in updateData
    data[stream] = df
  File "/Users/bradleynordin/.local/share/virtualenvs/GraphingData-5SWGkA_0/lib/python3.8/site-packages/pandas/core/frame.py", line 2906, in __getitem__
    indexer = self.columns.get_loc(key)
  File "/Users/bradleynordin/.local/share/virtualenvs/GraphingData-5SWGkA_0/lib/python3.8/site-packages/pandas/core/indexes/base.py", line 2897, in get_loc
    raise KeyError(key) from err
KeyError: 'measurement_time'
2020-12-07 17:25:18,216 - callbacks - ERROR - 'measurement_time'
Traceback (most recent call last):
  File "/Users/bradleynordin/.local/share/virtualenvs/GraphingData-5SWGkA_0/lib/python3.8/site-packages/pandas/core/indexes/base.py", line 2895, in get_loc
    return self._engine.get_loc(casted_key)
  File "pandas/_libs/index.pyx", line 70, in pandas._libs.index.IndexEngine.get_loc
  File "pandas/_libs/index.pyx", line 101, in pandas._libs.index.IndexEngine.get_loc
  File "pandas/_libs/hashtable_class_helper.pxi", line 1675, in pandas._libs.hashtable.PyObjectHashTable.get_item
  File "pandas/_libs/hashtable_class_helper.pxi", line 1683, in pandas._libs.hashtable.PyObjectHashTable.get_item
KeyError: 'measurement_time'

The above exception was the direct cause of the following exception:

Traceback (most recent call last):
  File "/Users/bradleynordin/Documents/GraphingData/callbacks.py", line 94, in updateData
    data[stream] = df
  File "/Users/bradleynordin/.local/share/virtualenvs/GraphingData-5SWGkA_0/lib/python3.8/site-packages/pandas/core/frame.py", line 2906, in __getitem__
    indexer = self.columns.get_loc(key)
  File "/Users/bradleynordin/.local/share/virtualenvs/GraphingData-5SWGkA_0/lib/python3.8/site-packages/pandas/core/indexes/base.py", line 2897, in get_loc
    raise KeyError(key) from err
KeyError: 'measurement_time'
2020-12-07 17:25:20,213 - callbacks - ERROR - 'measurement_time'
Traceback (most recent call last):
  File "/Users/bradleynordin/.local/share/virtualenvs/GraphingData-5SWGkA_0/lib/python3.8/site-packages/pandas/core/indexes/base.py", line 2895, in get_loc
    return self._engine.get_loc(casted_key)
  File "pandas/_libs/index.pyx", line 70, in pandas._libs.index.IndexEngine.get_loc
  File "pandas/_libs/index.pyx", line 101, in pandas._libs.index.IndexEngine.get_loc
  File "pandas/_libs/hashtable_class_helper.pxi", line 1675, in pandas._libs.hashtable.PyObjectHashTable.get_item
  File "pandas/_libs/hashtable_class_helper.pxi", line 1683, in pandas._libs.hashtable.PyObjectHashTable.get_item
KeyError: 'measurement_time'

The above exception was the direct cause of the following exception:

Traceback (most recent call last):
  File "/Users/bradleynordin/Documents/GraphingData/callbacks.py", line 94, in updateData
    data[stream] = df
  File "/Users/bradleynordin/.local/share/virtualenvs/GraphingData-5SWGkA_0/lib/python3.8/site-packages/pandas/core/frame.py", line 2906, in __getitem__
    indexer = self.columns.get_loc(key)
  File "/Users/bradleynordin/.local/share/virtualenvs/GraphingData-5SWGkA_0/lib/python3.8/site-packages/pandas/core/indexes/base.py", line 2897, in get_loc
    raise KeyError(key) from err
KeyError: 'measurement_time'
2020-12-07 17:25:22,224 - callbacks - ERROR - 'measurement_time'
Traceback (most recent call last):
  File "/Users/bradleynordin/.local/share/virtualenvs/GraphingData-5SWGkA_0/lib/python3.8/site-packages/pandas/core/indexes/base.py", line 2895, in get_loc
    return self._engine.get_loc(casted_key)
  File "pandas/_libs/index.pyx", line 70, in pandas._libs.index.IndexEngine.get_loc
  File "pandas/_libs/index.pyx", line 101, in pandas._libs.index.IndexEngine.get_loc
  File "pandas/_libs/hashtable_class_helper.pxi", line 1675, in pandas._libs.hashtable.PyObjectHashTable.get_item
  File "pandas/_libs/hashtable_class_helper.pxi", line 1683, in pandas._libs.hashtable.PyObjectHashTable.get_item
KeyError: 'measurement_time'

The above exception was the direct cause of the following exception:

Traceback (most recent call last):
  File "/Users/bradleynordin/Documents/GraphingData/callbacks.py", line 94, in updateData
    data[stream] = df
  File "/Users/bradleynordin/.local/share/virtualenvs/GraphingData-5SWGkA_0/lib/python3.8/site-packages/pandas/core/frame.py", line 2906, in __getitem__
    indexer = self.columns.get_loc(key)
  File "/Users/bradleynordin/.local/share/virtualenvs/GraphingData-5SWGkA_0/lib/python3.8/site-packages/pandas/core/indexes/base.py", line 2897, in get_loc
    raise KeyError(key) from err
KeyError: 'measurement_time'
2020-12-07 17:25:24,231 - callbacks - ERROR - 'measurement_time'
Traceback (most recent call last):
  File "/Users/bradleynordin/.local/share/virtualenvs/GraphingData-5SWGkA_0/lib/python3.8/site-packages/pandas/core/indexes/base.py", line 2895, in get_loc
    return self._engine.get_loc(casted_key)
  File "pandas/_libs/index.pyx", line 70, in pandas._libs.index.IndexEngine.get_loc
  File "pandas/_libs/index.pyx", line 101, in pandas._libs.index.IndexEngine.get_loc
  File "pandas/_libs/hashtable_class_helper.pxi", line 1675, in pandas._libs.hashtable.PyObjectHashTable.get_item
  File "pandas/_libs/hashtable_class_helper.pxi", line 1683, in pandas._libs.hashtable.PyObjectHashTable.get_item
KeyError: 'measurement_time'

The above exception was the direct cause of the following exception:

Traceback (most recent call last):
  File "/Users/bradleynordin/Documents/GraphingData/callbacks.py", line 94, in updateData
    data[stream] = df
  File "/Users/bradleynordin/.local/share/virtualenvs/GraphingData-5SWGkA_0/lib/python3.8/site-packages/pandas/core/frame.py", line 2906, in __getitem__
    indexer = self.columns.get_loc(key)
  File "/Users/bradleynordin/.local/share/virtualenvs/GraphingData-5SWGkA_0/lib/python3.8/site-packages/pandas/core/indexes/base.py", line 2897, in get_loc
    raise KeyError(key) from err
KeyError: 'measurement_time'
2020-12-07 17:25:26,265 - callbacks - ERROR - 'measurement_time'
Traceback (most recent call last):
  File "/Users/bradleynordin/.local/share/virtualenvs/GraphingData-5SWGkA_0/lib/python3.8/site-packages/pandas/core/indexes/base.py", line 2895, in get_loc
    return self._engine.get_loc(casted_key)
  File "pandas/_libs/index.pyx", line 70, in pandas._libs.index.IndexEngine.get_loc
  File "pandas/_libs/index.pyx", line 101, in pandas._libs.index.IndexEngine.get_loc
  File "pandas/_libs/hashtable_class_helper.pxi", line 1675, in pandas._libs.hashtable.PyObjectHashTable.get_item
  File "pandas/_libs/hashtable_class_helper.pxi", line 1683, in pandas._libs.hashtable.PyObjectHashTable.get_item
KeyError: 'measurement_time'

The above exception was the direct cause of the following exception:

Traceback (most recent call last):
  File "/Users/bradleynordin/Documents/GraphingData/callbacks.py", line 94, in updateData
    data[stream] = df
  File "/Users/bradleynordin/.local/share/virtualenvs/GraphingData-5SWGkA_0/lib/python3.8/site-packages/pandas/core/frame.py", line 2906, in __getitem__
    indexer = self.columns.get_loc(key)
  File "/Users/bradleynordin/.local/share/virtualenvs/GraphingData-5SWGkA_0/lib/python3.8/site-packages/pandas/core/indexes/base.py", line 2897, in get_loc
    raise KeyError(key) from err
KeyError: 'measurement_time'
2020-12-07 17:25:28,216 - callbacks - ERROR - 'measurement_time'
Traceback (most recent call last):
  File "/Users/bradleynordin/.local/share/virtualenvs/GraphingData-5SWGkA_0/lib/python3.8/site-packages/pandas/core/indexes/base.py", line 2895, in get_loc
    return self._engine.get_loc(casted_key)
  File "pandas/_libs/index.pyx", line 70, in pandas._libs.index.IndexEngine.get_loc
  File "pandas/_libs/index.pyx", line 101, in pandas._libs.index.IndexEngine.get_loc
  File "pandas/_libs/hashtable_class_helper.pxi", line 1675, in pandas._libs.hashtable.PyObjectHashTable.get_item
  File "pandas/_libs/hashtable_class_helper.pxi", line 1683, in pandas._libs.hashtable.PyObjectHashTable.get_item
KeyError: 'measurement_time'

The above exception was the direct cause of the following exception:

Traceback (most recent call last):
  File "/Users/bradleynordin/Documents/GraphingData/callbacks.py", line 94, in updateData
    data[stream] = df
  File "/Users/bradleynordin/.local/share/virtualenvs/GraphingData-5SWGkA_0/lib/python3.8/site-packages/pandas/core/frame.py", line 2906, in __getitem__
    indexer = self.columns.get_loc(key)
  File "/Users/bradleynordin/.local/share/virtualenvs/GraphingData-5SWGkA_0/lib/python3.8/site-packages/pandas/core/indexes/base.py", line 2897, in get_loc
    raise KeyError(key) from err
KeyError: 'measurement_time'
2020-12-07 17:25:30,241 - callbacks - ERROR - 'measurement_time'
Traceback (most recent call last):
  File "/Users/bradleynordin/.local/share/virtualenvs/GraphingData-5SWGkA_0/lib/python3.8/site-packages/pandas/core/indexes/base.py", line 2895, in get_loc
    return self._engine.get_loc(casted_key)
  File "pandas/_libs/index.pyx", line 70, in pandas._libs.index.IndexEngine.get_loc
  File "pandas/_libs/index.pyx", line 101, in pandas._libs.index.IndexEngine.get_loc
  File "pandas/_libs/hashtable_class_helper.pxi", line 1675, in pandas._libs.hashtable.PyObjectHashTable.get_item
  File "pandas/_libs/hashtable_class_helper.pxi", line 1683, in pandas._libs.hashtable.PyObjectHashTable.get_item
KeyError: 'measurement_time'

The above exception was the direct cause of the following exception:

Traceback (most recent call last):
  File "/Users/bradleynordin/Documents/GraphingData/callbacks.py", line 94, in updateData
    data[stream] = df
  File "/Users/bradleynordin/.local/share/virtualenvs/GraphingData-5SWGkA_0/lib/python3.8/site-packages/pandas/core/frame.py", line 2906, in __getitem__
    indexer = self.columns.get_loc(key)
  File "/Users/bradleynordin/.local/share/virtualenvs/GraphingData-5SWGkA_0/lib/python3.8/site-packages/pandas/core/indexes/base.py", line 2897, in get_loc
    raise KeyError(key) from err
KeyError: 'measurement_time'
2020-12-07 17:25:32,227 - callbacks - ERROR - 'measurement_time'
Traceback (most recent call last):
  File "/Users/bradleynordin/.local/share/virtualenvs/GraphingData-5SWGkA_0/lib/python3.8/site-packages/pandas/core/indexes/base.py", line 2895, in get_loc
    return self._engine.get_loc(casted_key)
  File "pandas/_libs/index.pyx", line 70, in pandas._libs.index.IndexEngine.get_loc
  File "pandas/_libs/index.pyx", line 101, in pandas._libs.index.IndexEngine.get_loc
  File "pandas/_libs/hashtable_class_helper.pxi", line 1675, in pandas._libs.hashtable.PyObjectHashTable.get_item
  File "pandas/_libs/hashtable_class_helper.pxi", line 1683, in pandas._libs.hashtable.PyObjectHashTable.get_item
KeyError: 'measurement_time'

The above exception was the direct cause of the following exception:

Traceback (most recent call last):
  File "/Users/bradleynordin/Documents/GraphingData/callbacks.py", line 94, in updateData
    data[stream] = df
  File "/Users/bradleynordin/.local/share/virtualenvs/GraphingData-5SWGkA_0/lib/python3.8/site-packages/pandas/core/frame.py", line 2906, in __getitem__
    indexer = self.columns.get_loc(key)
  File "/Users/bradleynordin/.local/share/virtualenvs/GraphingData-5SWGkA_0/lib/python3.8/site-packages/pandas/core/indexes/base.py", line 2897, in get_loc
    raise KeyError(key) from err
KeyError: 'measurement_time'
2020-12-07 17:25:34,232 - callbacks - ERROR - 'measurement_time'
Traceback (most recent call last):
  File "/Users/bradleynordin/.local/share/virtualenvs/GraphingData-5SWGkA_0/lib/python3.8/site-packages/pandas/core/indexes/base.py", line 2895, in get_loc
    return self._engine.get_loc(casted_key)
  File "pandas/_libs/index.pyx", line 70, in pandas._libs.index.IndexEngine.get_loc
  File "pandas/_libs/index.pyx", line 101, in pandas._libs.index.IndexEngine.get_loc
  File "pandas/_libs/hashtable_class_helper.pxi", line 1675, in pandas._libs.hashtable.PyObjectHashTable.get_item
  File "pandas/_libs/hashtable_class_helper.pxi", line 1683, in pandas._libs.hashtable.PyObjectHashTable.get_item
KeyError: 'measurement_time'

The above exception was the direct cause of the following exception:

Traceback (most recent call last):
  File "/Users/bradleynordin/Documents/GraphingData/callbacks.py", line 94, in updateData
    data[stream] = df
  File "/Users/bradleynordin/.local/share/virtualenvs/GraphingData-5SWGkA_0/lib/python3.8/site-packages/pandas/core/frame.py", line 2906, in __getitem__
    indexer = self.columns.get_loc(key)
  File "/Users/bradleynordin/.local/share/virtualenvs/GraphingData-5SWGkA_0/lib/python3.8/site-packages/pandas/core/indexes/base.py", line 2897, in get_loc
    raise KeyError(key) from err
KeyError: 'measurement_time'
2020-12-07 17:25:36,230 - callbacks - ERROR - 'measurement_time'
Traceback (most recent call last):
  File "/Users/bradleynordin/.local/share/virtualenvs/GraphingData-5SWGkA_0/lib/python3.8/site-packages/pandas/core/indexes/base.py", line 2895, in get_loc
    return self._engine.get_loc(casted_key)
  File "pandas/_libs/index.pyx", line 70, in pandas._libs.index.IndexEngine.get_loc
  File "pandas/_libs/index.pyx", line 101, in pandas._libs.index.IndexEngine.get_loc
  File "pandas/_libs/hashtable_class_helper.pxi", line 1675, in pandas._libs.hashtable.PyObjectHashTable.get_item
  File "pandas/_libs/hashtable_class_helper.pxi", line 1683, in pandas._libs.hashtable.PyObjectHashTable.get_item
KeyError: 'measurement_time'

The above exception was the direct cause of the following exception:

Traceback (most recent call last):
  File "/Users/bradleynordin/Documents/GraphingData/callbacks.py", line 94, in updateData
    data[stream] = df
  File "/Users/bradleynordin/.local/share/virtualenvs/GraphingData-5SWGkA_0/lib/python3.8/site-packages/pandas/core/frame.py", line 2906, in __getitem__
    indexer = self.columns.get_loc(key)
  File "/Users/bradleynordin/.local/share/virtualenvs/GraphingData-5SWGkA_0/lib/python3.8/site-packages/pandas/core/indexes/base.py", line 2897, in get_loc
    raise KeyError(key) from err
KeyError: 'measurement_time'
2020-12-07 17:25:38,236 - callbacks - ERROR - 'measurement_time'
Traceback (most recent call last):
  File "/Users/bradleynordin/.local/share/virtualenvs/GraphingData-5SWGkA_0/lib/python3.8/site-packages/pandas/core/indexes/base.py", line 2895, in get_loc
    return self._engine.get_loc(casted_key)
  File "pandas/_libs/index.pyx", line 70, in pandas._libs.index.IndexEngine.get_loc
  File "pandas/_libs/index.pyx", line 101, in pandas._libs.index.IndexEngine.get_loc
  File "pandas/_libs/hashtable_class_helper.pxi", line 1675, in pandas._libs.hashtable.PyObjectHashTable.get_item
  File "pandas/_libs/hashtable_class_helper.pxi", line 1683, in pandas._libs.hashtable.PyObjectHashTable.get_item
KeyError: 'measurement_time'

The above exception was the direct cause of the following exception:

Traceback (most recent call last):
  File "/Users/bradleynordin/Documents/GraphingData/callbacks.py", line 94, in updateData
    data[stream] = df
  File "/Users/bradleynordin/.local/share/virtualenvs/GraphingData-5SWGkA_0/lib/python3.8/site-packages/pandas/core/frame.py", line 2906, in __getitem__
    indexer = self.columns.get_loc(key)
  File "/Users/bradleynordin/.local/share/virtualenvs/GraphingData-5SWGkA_0/lib/python3.8/site-packages/pandas/core/indexes/base.py", line 2897, in get_loc
    raise KeyError(key) from err
KeyError: 'measurement_time'
2020-12-07 17:25:40,234 - callbacks - ERROR - 'measurement_time'
Traceback (most recent call last):
  File "/Users/bradleynordin/.local/share/virtualenvs/GraphingData-5SWGkA_0/lib/python3.8/site-packages/pandas/core/indexes/base.py", line 2895, in get_loc
    return self._engine.get_loc(casted_key)
  File "pandas/_libs/index.pyx", line 70, in pandas._libs.index.IndexEngine.get_loc
  File "pandas/_libs/index.pyx", line 101, in pandas._libs.index.IndexEngine.get_loc
  File "pandas/_libs/hashtable_class_helper.pxi", line 1675, in pandas._libs.hashtable.PyObjectHashTable.get_item
  File "pandas/_libs/hashtable_class_helper.pxi", line 1683, in pandas._libs.hashtable.PyObjectHashTable.get_item
KeyError: 'measurement_time'

The above exception was the direct cause of the following exception:

Traceback (most recent call last):
  File "/Users/bradleynordin/Documents/GraphingData/callbacks.py", line 94, in updateData
    data[stream] = df
  File "/Users/bradleynordin/.local/share/virtualenvs/GraphingData-5SWGkA_0/lib/python3.8/site-packages/pandas/core/frame.py", line 2906, in __getitem__
    indexer = self.columns.get_loc(key)
  File "/Users/bradleynordin/.local/share/virtualenvs/GraphingData-5SWGkA_0/lib/python3.8/site-packages/pandas/core/indexes/base.py", line 2897, in get_loc
    raise KeyError(key) from err
KeyError: 'measurement_time'
2020-12-07 17:25:42,266 - callbacks - ERROR - 'measurement_time'
Traceback (most recent call last):
  File "/Users/bradleynordin/.local/share/virtualenvs/GraphingData-5SWGkA_0/lib/python3.8/site-packages/pandas/core/indexes/base.py", line 2895, in get_loc
    return self._engine.get_loc(casted_key)
  File "pandas/_libs/index.pyx", line 70, in pandas._libs.index.IndexEngine.get_loc
  File "pandas/_libs/index.pyx", line 101, in pandas._libs.index.IndexEngine.get_loc
  File "pandas/_libs/hashtable_class_helper.pxi", line 1675, in pandas._libs.hashtable.PyObjectHashTable.get_item
  File "pandas/_libs/hashtable_class_helper.pxi", line 1683, in pandas._libs.hashtable.PyObjectHashTable.get_item
KeyError: 'measurement_time'

The above exception was the direct cause of the following exception:

Traceback (most recent call last):
  File "/Users/bradleynordin/Documents/GraphingData/callbacks.py", line 94, in updateData
    data[stream] = df
  File "/Users/bradleynordin/.local/share/virtualenvs/GraphingData-5SWGkA_0/lib/python3.8/site-packages/pandas/core/frame.py", line 2906, in __getitem__
    indexer = self.columns.get_loc(key)
  File "/Users/bradleynordin/.local/share/virtualenvs/GraphingData-5SWGkA_0/lib/python3.8/site-packages/pandas/core/indexes/base.py", line 2897, in get_loc
    raise KeyError(key) from err
KeyError: 'measurement_time'
2020-12-07 17:25:44,241 - callbacks - ERROR - 'measurement_time'
Traceback (most recent call last):
  File "/Users/bradleynordin/.local/share/virtualenvs/GraphingData-5SWGkA_0/lib/python3.8/site-packages/pandas/core/indexes/base.py", line 2895, in get_loc
    return self._engine.get_loc(casted_key)
  File "pandas/_libs/index.pyx", line 70, in pandas._libs.index.IndexEngine.get_loc
  File "pandas/_libs/index.pyx", line 101, in pandas._libs.index.IndexEngine.get_loc
  File "pandas/_libs/hashtable_class_helper.pxi", line 1675, in pandas._libs.hashtable.PyObjectHashTable.get_item
  File "pandas/_libs/hashtable_class_helper.pxi", line 1683, in pandas._libs.hashtable.PyObjectHashTable.get_item
KeyError: 'measurement_time'

The above exception was the direct cause of the following exception:

Traceback (most recent call last):
  File "/Users/bradleynordin/Documents/GraphingData/callbacks.py", line 94, in updateData
    data[stream] = df
  File "/Users/bradleynordin/.local/share/virtualenvs/GraphingData-5SWGkA_0/lib/python3.8/site-packages/pandas/core/frame.py", line 2906, in __getitem__
    indexer = self.columns.get_loc(key)
  File "/Users/bradleynordin/.local/share/virtualenvs/GraphingData-5SWGkA_0/lib/python3.8/site-packages/pandas/core/indexes/base.py", line 2897, in get_loc
    raise KeyError(key) from err
KeyError: 'measurement_time'
2020-12-07 17:25:46,244 - callbacks - ERROR - 'measurement_time'
Traceback (most recent call last):
  File "/Users/bradleynordin/.local/share/virtualenvs/GraphingData-5SWGkA_0/lib/python3.8/site-packages/pandas/core/indexes/base.py", line 2895, in get_loc
    return self._engine.get_loc(casted_key)
  File "pandas/_libs/index.pyx", line 70, in pandas._libs.index.IndexEngine.get_loc
  File "pandas/_libs/index.pyx", line 101, in pandas._libs.index.IndexEngine.get_loc
  File "pandas/_libs/hashtable_class_helper.pxi", line 1675, in pandas._libs.hashtable.PyObjectHashTable.get_item
  File "pandas/_libs/hashtable_class_helper.pxi", line 1683, in pandas._libs.hashtable.PyObjectHashTable.get_item
KeyError: 'measurement_time'

The above exception was the direct cause of the following exception:

Traceback (most recent call last):
  File "/Users/bradleynordin/Documents/GraphingData/callbacks.py", line 94, in updateData
    data[stream] = df
  File "/Users/bradleynordin/.local/share/virtualenvs/GraphingData-5SWGkA_0/lib/python3.8/site-packages/pandas/core/frame.py", line 2906, in __getitem__
    indexer = self.columns.get_loc(key)
  File "/Users/bradleynordin/.local/share/virtualenvs/GraphingData-5SWGkA_0/lib/python3.8/site-packages/pandas/core/indexes/base.py", line 2897, in get_loc
    raise KeyError(key) from err
KeyError: 'measurement_time'
2020-12-07 17:25:48,248 - callbacks - ERROR - 'measurement_time'
Traceback (most recent call last):
  File "/Users/bradleynordin/.local/share/virtualenvs/GraphingData-5SWGkA_0/lib/python3.8/site-packages/pandas/core/indexes/base.py", line 2895, in get_loc
    return self._engine.get_loc(casted_key)
  File "pandas/_libs/index.pyx", line 70, in pandas._libs.index.IndexEngine.get_loc
  File "pandas/_libs/index.pyx", line 101, in pandas._libs.index.IndexEngine.get_loc
  File "pandas/_libs/hashtable_class_helper.pxi", line 1675, in pandas._libs.hashtable.PyObjectHashTable.get_item
  File "pandas/_libs/hashtable_class_helper.pxi", line 1683, in pandas._libs.hashtable.PyObjectHashTable.get_item
KeyError: 'measurement_time'

The above exception was the direct cause of the following exception:

Traceback (most recent call last):
  File "/Users/bradleynordin/Documents/GraphingData/callbacks.py", line 94, in updateData
    data[stream] = df
  File "/Users/bradleynordin/.local/share/virtualenvs/GraphingData-5SWGkA_0/lib/python3.8/site-packages/pandas/core/frame.py", line 2906, in __getitem__
    indexer = self.columns.get_loc(key)
  File "/Users/bradleynordin/.local/share/virtualenvs/GraphingData-5SWGkA_0/lib/python3.8/site-packages/pandas/core/indexes/base.py", line 2897, in get_loc
    raise KeyError(key) from err
KeyError: 'measurement_time'
2020-12-07 17:25:50,246 - callbacks - ERROR - 'measurement_time'
Traceback (most recent call last):
  File "/Users/bradleynordin/.local/share/virtualenvs/GraphingData-5SWGkA_0/lib/python3.8/site-packages/pandas/core/indexes/base.py", line 2895, in get_loc
    return self._engine.get_loc(casted_key)
  File "pandas/_libs/index.pyx", line 70, in pandas._libs.index.IndexEngine.get_loc
  File "pandas/_libs/index.pyx", line 101, in pandas._libs.index.IndexEngine.get_loc
  File "pandas/_libs/hashtable_class_helper.pxi", line 1675, in pandas._libs.hashtable.PyObjectHashTable.get_item
  File "pandas/_libs/hashtable_class_helper.pxi", line 1683, in pandas._libs.hashtable.PyObjectHashTable.get_item
KeyError: 'measurement_time'

The above exception was the direct cause of the following exception:

Traceback (most recent call last):
  File "/Users/bradleynordin/Documents/GraphingData/callbacks.py", line 94, in updateData
    data[stream] = df
  File "/Users/bradleynordin/.local/share/virtualenvs/GraphingData-5SWGkA_0/lib/python3.8/site-packages/pandas/core/frame.py", line 2906, in __getitem__
    indexer = self.columns.get_loc(key)
  File "/Users/bradleynordin/.local/share/virtualenvs/GraphingData-5SWGkA_0/lib/python3.8/site-packages/pandas/core/indexes/base.py", line 2897, in get_loc
    raise KeyError(key) from err
KeyError: 'measurement_time'
2020-12-07 17:25:52,247 - callbacks - ERROR - 'measurement_time'
Traceback (most recent call last):
  File "/Users/bradleynordin/.local/share/virtualenvs/GraphingData-5SWGkA_0/lib/python3.8/site-packages/pandas/core/indexes/base.py", line 2895, in get_loc
    return self._engine.get_loc(casted_key)
  File "pandas/_libs/index.pyx", line 70, in pandas._libs.index.IndexEngine.get_loc
  File "pandas/_libs/index.pyx", line 101, in pandas._libs.index.IndexEngine.get_loc
  File "pandas/_libs/hashtable_class_helper.pxi", line 1675, in pandas._libs.hashtable.PyObjectHashTable.get_item
  File "pandas/_libs/hashtable_class_helper.pxi", line 1683, in pandas._libs.hashtable.PyObjectHashTable.get_item
KeyError: 'measurement_time'

The above exception was the direct cause of the following exception:

Traceback (most recent call last):
  File "/Users/bradleynordin/Documents/GraphingData/callbacks.py", line 94, in updateData
    df['measurement_time'] = pd.to_datetime(df['measurement_time']/(2**32),unit='s')
  File "/Users/bradleynordin/.local/share/virtualenvs/GraphingData-5SWGkA_0/lib/python3.8/site-packages/pandas/core/frame.py", line 2906, in __getitem__
    indexer = self.columns.get_loc(key)
  File "/Users/bradleynordin/.local/share/virtualenvs/GraphingData-5SWGkA_0/lib/python3.8/site-packages/pandas/core/indexes/base.py", line 2897, in get_loc
    raise KeyError(key) from err
KeyError: 'measurement_time'
2020-12-07 17:25:54,284 - callbacks - ERROR - 'measurement_time'
Traceback (most recent call last):
  File "/Users/bradleynordin/.local/share/virtualenvs/GraphingData-5SWGkA_0/lib/python3.8/site-packages/pandas/core/indexes/base.py", line 2895, in get_loc
    return self._engine.get_loc(casted_key)
  File "pandas/_libs/index.pyx", line 70, in pandas._libs.index.IndexEngine.get_loc
  File "pandas/_libs/index.pyx", line 101, in pandas._libs.index.IndexEngine.get_loc
  File "pandas/_libs/hashtable_class_helper.pxi", line 1675, in pandas._libs.hashtable.PyObjectHashTable.get_item
  File "pandas/_libs/hashtable_class_helper.pxi", line 1683, in pandas._libs.hashtable.PyObjectHashTable.get_item
KeyError: 'measurement_time'

The above exception was the direct cause of the following exception:

Traceback (most recent call last):
  File "/Users/bradleynordin/Documents/GraphingData/callbacks.py", line 94, in updateData
    df['measurement_time'] = pd.to_datetime(df['measurement_time']/(2**32),unit='s')
  File "/Users/bradleynordin/.local/share/virtualenvs/GraphingData-5SWGkA_0/lib/python3.8/site-packages/pandas/core/frame.py", line 2906, in __getitem__
    indexer = self.columns.get_loc(key)
  File "/Users/bradleynordin/.local/share/virtualenvs/GraphingData-5SWGkA_0/lib/python3.8/site-packages/pandas/core/indexes/base.py", line 2897, in get_loc
    raise KeyError(key) from err
KeyError: 'measurement_time'
2020-12-07 17:26:24,379 - callbacks - ERROR - 'measurement_time'
Traceback (most recent call last):
  File "/Users/bradleynordin/.local/share/virtualenvs/GraphingData-5SWGkA_0/lib/python3.8/site-packages/pandas/core/indexes/base.py", line 2895, in get_loc
    return self._engine.get_loc(casted_key)
  File "pandas/_libs/index.pyx", line 70, in pandas._libs.index.IndexEngine.get_loc
  File "pandas/_libs/index.pyx", line 101, in pandas._libs.index.IndexEngine.get_loc
  File "pandas/_libs/hashtable_class_helper.pxi", line 1675, in pandas._libs.hashtable.PyObjectHashTable.get_item
  File "pandas/_libs/hashtable_class_helper.pxi", line 1683, in pandas._libs.hashtable.PyObjectHashTable.get_item
KeyError: 'measurement_time'

The above exception was the direct cause of the following exception:

Traceback (most recent call last):
  File "/Users/bradleynordin/Documents/GraphingData/callbacks.py", line 94, in updateData
    df['measurement_time'] = pd.to_datetime(df['measurement_time']/(2**32),unit='s')
  File "/Users/bradleynordin/.local/share/virtualenvs/GraphingData-5SWGkA_0/lib/python3.8/site-packages/pandas/core/frame.py", line 2906, in __getitem__
    indexer = self.columns.get_loc(key)
  File "/Users/bradleynordin/.local/share/virtualenvs/GraphingData-5SWGkA_0/lib/python3.8/site-packages/pandas/core/indexes/base.py", line 2897, in get_loc
    raise KeyError(key) from err
KeyError: 'measurement_time'
2020-12-07 17:26:24,401 - callbacks - ERROR - The data csv got messed up
Traceback (most recent call last):
  File "/Users/bradleynordin/Documents/GraphingData/callbacks.py", line 101, in updateData
    length = len(data[stream].index)
KeyError: 'Hybrid_Mux'
2020-12-07 17:26:32,496 - callbacks - ERROR - 'measurement_time'
Traceback (most recent call last):
  File "/Users/bradleynordin/.local/share/virtualenvs/GraphingData-5SWGkA_0/lib/python3.8/site-packages/pandas/core/indexes/base.py", line 2895, in get_loc
    return self._engine.get_loc(casted_key)
  File "pandas/_libs/index.pyx", line 70, in pandas._libs.index.IndexEngine.get_loc
  File "pandas/_libs/index.pyx", line 101, in pandas._libs.index.IndexEngine.get_loc
  File "pandas/_libs/hashtable_class_helper.pxi", line 1675, in pandas._libs.hashtable.PyObjectHashTable.get_item
  File "pandas/_libs/hashtable_class_helper.pxi", line 1683, in pandas._libs.hashtable.PyObjectHashTable.get_item
KeyError: 'measurement_time'

The above exception was the direct cause of the following exception:

Traceback (most recent call last):
  File "/Users/bradleynordin/Documents/GraphingData/callbacks.py", line 94, in updateData
    df['measurement_time'] = pd.to_datetime(df['measurement_time']/(2**32),unit='s')
  File "/Users/bradleynordin/.local/share/virtualenvs/GraphingData-5SWGkA_0/lib/python3.8/site-packages/pandas/core/frame.py", line 2906, in __getitem__
    indexer = self.columns.get_loc(key)
  File "/Users/bradleynordin/.local/share/virtualenvs/GraphingData-5SWGkA_0/lib/python3.8/site-packages/pandas/core/indexes/base.py", line 2897, in get_loc
    raise KeyError(key) from err
KeyError: 'measurement_time'
2020-12-07 17:26:32,498 - callbacks - ERROR - The data csv got messed up
Traceback (most recent call last):
  File "/Users/bradleynordin/Documents/GraphingData/callbacks.py", line 101, in updateData
    length = len(data[stream].index)
KeyError: 'Hybrid_Mux'
2020-12-07 17:26:34,497 - callbacks - ERROR - 'measurement_time'
Traceback (most recent call last):
  File "/Users/bradleynordin/.local/share/virtualenvs/GraphingData-5SWGkA_0/lib/python3.8/site-packages/pandas/core/indexes/base.py", line 2895, in get_loc
    return self._engine.get_loc(casted_key)
  File "pandas/_libs/index.pyx", line 70, in pandas._libs.index.IndexEngine.get_loc
  File "pandas/_libs/index.pyx", line 101, in pandas._libs.index.IndexEngine.get_loc
  File "pandas/_libs/hashtable_class_helper.pxi", line 1675, in pandas._libs.hashtable.PyObjectHashTable.get_item
  File "pandas/_libs/hashtable_class_helper.pxi", line 1683, in pandas._libs.hashtable.PyObjectHashTable.get_item
KeyError: 'measurement_time'

The above exception was the direct cause of the following exception:

Traceback (most recent call last):
  File "/Users/bradleynordin/Documents/GraphingData/callbacks.py", line 94, in updateData
    df['measurement_time'] = pd.to_datetime(df['measurement_time']/(2**32),unit='s')
  File "/Users/bradleynordin/.local/share/virtualenvs/GraphingData-5SWGkA_0/lib/python3.8/site-packages/pandas/core/frame.py", line 2906, in __getitem__
    indexer = self.columns.get_loc(key)
  File "/Users/bradleynordin/.local/share/virtualenvs/GraphingData-5SWGkA_0/lib/python3.8/site-packages/pandas/core/indexes/base.py", line 2897, in get_loc
    raise KeyError(key) from err
KeyError: 'measurement_time'
2020-12-07 17:26:34,498 - callbacks - ERROR - The data csv got messed up
Traceback (most recent call last):
  File "/Users/bradleynordin/Documents/GraphingData/callbacks.py", line 101, in updateData
    length = len(data[stream].index)
KeyError: 'Hybrid_Mux'
2020-12-07 17:26:36,519 - callbacks - ERROR - 'measurement_time'
Traceback (most recent call last):
  File "/Users/bradleynordin/.local/share/virtualenvs/GraphingData-5SWGkA_0/lib/python3.8/site-packages/pandas/core/indexes/base.py", line 2895, in get_loc
    return self._engine.get_loc(casted_key)
  File "pandas/_libs/index.pyx", line 70, in pandas._libs.index.IndexEngine.get_loc
  File "pandas/_libs/index.pyx", line 101, in pandas._libs.index.IndexEngine.get_loc
  File "pandas/_libs/hashtable_class_helper.pxi", line 1675, in pandas._libs.hashtable.PyObjectHashTable.get_item
  File "pandas/_libs/hashtable_class_helper.pxi", line 1683, in pandas._libs.hashtable.PyObjectHashTable.get_item
KeyError: 'measurement_time'

The above exception was the direct cause of the following exception:

Traceback (most recent call last):
  File "/Users/bradleynordin/Documents/GraphingData/callbacks.py", line 94, in updateData
    df['measurement_time'] = pd.to_datetime(df['measurement_time']/(2**32),unit='s')
  File "/Users/bradleynordin/.local/share/virtualenvs/GraphingData-5SWGkA_0/lib/python3.8/site-packages/pandas/core/frame.py", line 2906, in __getitem__
    indexer = self.columns.get_loc(key)
  File "/Users/bradleynordin/.local/share/virtualenvs/GraphingData-5SWGkA_0/lib/python3.8/site-packages/pandas/core/indexes/base.py", line 2897, in get_loc
    raise KeyError(key) from err
KeyError: 'measurement_time'
2020-12-07 17:26:36,520 - callbacks - ERROR - The data csv got messed up
Traceback (most recent call last):
  File "/Users/bradleynordin/Documents/GraphingData/callbacks.py", line 101, in updateData
    length = len(data[stream].index)
KeyError: 'Hybrid_Mux'
2020-12-07 17:26:38,512 - callbacks - ERROR - 'measurement_time'
Traceback (most recent call last):
  File "/Users/bradleynordin/.local/share/virtualenvs/GraphingData-5SWGkA_0/lib/python3.8/site-packages/pandas/core/indexes/base.py", line 2895, in get_loc
    return self._engine.get_loc(casted_key)
  File "pandas/_libs/index.pyx", line 70, in pandas._libs.index.IndexEngine.get_loc
  File "pandas/_libs/index.pyx", line 101, in pandas._libs.index.IndexEngine.get_loc
  File "pandas/_libs/hashtable_class_helper.pxi", line 1675, in pandas._libs.hashtable.PyObjectHashTable.get_item
  File "pandas/_libs/hashtable_class_helper.pxi", line 1683, in pandas._libs.hashtable.PyObjectHashTable.get_item
KeyError: 'measurement_time'

The above exception was the direct cause of the following exception:

Traceback (most recent call last):
  File "/Users/bradleynordin/Documents/GraphingData/callbacks.py", line 94, in updateData
    df['measurement_time'] = pd.to_datetime(df['measurement_time']/(2**32),unit='s')
  File "/Users/bradleynordin/.local/share/virtualenvs/GraphingData-5SWGkA_0/lib/python3.8/site-packages/pandas/core/frame.py", line 2906, in __getitem__
    indexer = self.columns.get_loc(key)
  File "/Users/bradleynordin/.local/share/virtualenvs/GraphingData-5SWGkA_0/lib/python3.8/site-packages/pandas/core/indexes/base.py", line 2897, in get_loc
    raise KeyError(key) from err
KeyError: 'measurement_time'
2020-12-07 17:26:38,514 - callbacks - ERROR - The data csv got messed up
Traceback (most recent call last):
  File "/Users/bradleynordin/Documents/GraphingData/callbacks.py", line 101, in updateData
    length = len(data[stream].index)
KeyError: 'Hybrid_Mux'
2020-12-07 17:26:40,549 - callbacks - ERROR - 'measurement_time'
Traceback (most recent call last):
  File "/Users/bradleynordin/.local/share/virtualenvs/GraphingData-5SWGkA_0/lib/python3.8/site-packages/pandas/core/indexes/base.py", line 2895, in get_loc
    return self._engine.get_loc(casted_key)
  File "pandas/_libs/index.pyx", line 70, in pandas._libs.index.IndexEngine.get_loc
  File "pandas/_libs/index.pyx", line 101, in pandas._libs.index.IndexEngine.get_loc
  File "pandas/_libs/hashtable_class_helper.pxi", line 1675, in pandas._libs.hashtable.PyObjectHashTable.get_item
  File "pandas/_libs/hashtable_class_helper.pxi", line 1683, in pandas._libs.hashtable.PyObjectHashTable.get_item
KeyError: 'measurement_time'

The above exception was the direct cause of the following exception:

Traceback (most recent call last):
  File "/Users/bradleynordin/Documents/GraphingData/callbacks.py", line 94, in updateData
    df['measurement_time'] = pd.to_datetime(df['measurement_time']/(2**32),unit='s')
  File "/Users/bradleynordin/.local/share/virtualenvs/GraphingData-5SWGkA_0/lib/python3.8/site-packages/pandas/core/frame.py", line 2906, in __getitem__
    indexer = self.columns.get_loc(key)
  File "/Users/bradleynordin/.local/share/virtualenvs/GraphingData-5SWGkA_0/lib/python3.8/site-packages/pandas/core/indexes/base.py", line 2897, in get_loc
    raise KeyError(key) from err
KeyError: 'measurement_time'
2020-12-07 17:26:40,550 - callbacks - ERROR - The data csv got messed up
Traceback (most recent call last):
  File "/Users/bradleynordin/Documents/GraphingData/callbacks.py", line 101, in updateData
    length = len(data[stream].index)
KeyError: 'Hybrid_Mux'
2020-12-07 17:26:42,536 - callbacks - ERROR - 'measurement_time'
Traceback (most recent call last):
  File "/Users/bradleynordin/.local/share/virtualenvs/GraphingData-5SWGkA_0/lib/python3.8/site-packages/pandas/core/indexes/base.py", line 2895, in get_loc
    return self._engine.get_loc(casted_key)
  File "pandas/_libs/index.pyx", line 70, in pandas._libs.index.IndexEngine.get_loc
  File "pandas/_libs/index.pyx", line 101, in pandas._libs.index.IndexEngine.get_loc
  File "pandas/_libs/hashtable_class_helper.pxi", line 1675, in pandas._libs.hashtable.PyObjectHashTable.get_item
  File "pandas/_libs/hashtable_class_helper.pxi", line 1683, in pandas._libs.hashtable.PyObjectHashTable.get_item
KeyError: 'measurement_time'

The above exception was the direct cause of the following exception:

Traceback (most recent call last):
  File "/Users/bradleynordin/Documents/GraphingData/callbacks.py", line 94, in updateData
    df['measurement_time'] = pd.to_datetime(df['measurement_time']/(2**32),unit='s')
  File "/Users/bradleynordin/.local/share/virtualenvs/GraphingData-5SWGkA_0/lib/python3.8/site-packages/pandas/core/frame.py", line 2906, in __getitem__
    indexer = self.columns.get_loc(key)
  File "/Users/bradleynordin/.local/share/virtualenvs/GraphingData-5SWGkA_0/lib/python3.8/site-packages/pandas/core/indexes/base.py", line 2897, in get_loc
    raise KeyError(key) from err
KeyError: 'measurement_time'
2020-12-07 17:26:42,539 - callbacks - ERROR - The data csv got messed up
Traceback (most recent call last):
  File "/Users/bradleynordin/Documents/GraphingData/callbacks.py", line 101, in updateData
    length = len(data[stream].index)
KeyError: 'Hybrid_Mux'
2020-12-07 17:26:44,519 - callbacks - ERROR - 'measurement_time'
Traceback (most recent call last):
  File "/Users/bradleynordin/.local/share/virtualenvs/GraphingData-5SWGkA_0/lib/python3.8/site-packages/pandas/core/indexes/base.py", line 2895, in get_loc
    return self._engine.get_loc(casted_key)
  File "pandas/_libs/index.pyx", line 70, in pandas._libs.index.IndexEngine.get_loc
  File "pandas/_libs/index.pyx", line 101, in pandas._libs.index.IndexEngine.get_loc
  File "pandas/_libs/hashtable_class_helper.pxi", line 1675, in pandas._libs.hashtable.PyObjectHashTable.get_item
  File "pandas/_libs/hashtable_class_helper.pxi", line 1683, in pandas._libs.hashtable.PyObjectHashTable.get_item
KeyError: 'measurement_time'

The above exception was the direct cause of the following exception:

Traceback (most recent call last):
  File "/Users/bradleynordin/Documents/GraphingData/callbacks.py", line 94, in updateData
    df['measurement_time'] = pd.to_datetime(df['measurement_time']/(2**32),unit='s')
  File "/Users/bradleynordin/.local/share/virtualenvs/GraphingData-5SWGkA_0/lib/python3.8/site-packages/pandas/core/frame.py", line 2906, in __getitem__
    indexer = self.columns.get_loc(key)
  File "/Users/bradleynordin/.local/share/virtualenvs/GraphingData-5SWGkA_0/lib/python3.8/site-packages/pandas/core/indexes/base.py", line 2897, in get_loc
    raise KeyError(key) from err
KeyError: 'measurement_time'
2020-12-07 17:26:44,520 - callbacks - ERROR - The data csv got messed up
Traceback (most recent call last):
  File "/Users/bradleynordin/Documents/GraphingData/callbacks.py", line 101, in updateData
    length = len(data[stream].index)
KeyError: 'Hybrid_Mux'
2020-12-07 17:26:46,532 - callbacks - ERROR - 'measurement_time'
Traceback (most recent call last):
  File "/Users/bradleynordin/.local/share/virtualenvs/GraphingData-5SWGkA_0/lib/python3.8/site-packages/pandas/core/indexes/base.py", line 2895, in get_loc
    return self._engine.get_loc(casted_key)
  File "pandas/_libs/index.pyx", line 70, in pandas._libs.index.IndexEngine.get_loc
  File "pandas/_libs/index.pyx", line 101, in pandas._libs.index.IndexEngine.get_loc
  File "pandas/_libs/hashtable_class_helper.pxi", line 1675, in pandas._libs.hashtable.PyObjectHashTable.get_item
  File "pandas/_libs/hashtable_class_helper.pxi", line 1683, in pandas._libs.hashtable.PyObjectHashTable.get_item
KeyError: 'measurement_time'

The above exception was the direct cause of the following exception:

Traceback (most recent call last):
  File "/Users/bradleynordin/Documents/GraphingData/callbacks.py", line 94, in updateData
    df['measurement_time'] = pd.to_datetime(df['measurement_time']/(2**32),unit='s')
  File "/Users/bradleynordin/.local/share/virtualenvs/GraphingData-5SWGkA_0/lib/python3.8/site-packages/pandas/core/frame.py", line 2906, in __getitem__
    indexer = self.columns.get_loc(key)
  File "/Users/bradleynordin/.local/share/virtualenvs/GraphingData-5SWGkA_0/lib/python3.8/site-packages/pandas/core/indexes/base.py", line 2897, in get_loc
    raise KeyError(key) from err
KeyError: 'measurement_time'
2020-12-07 17:26:46,533 - callbacks - ERROR - The data csv got messed up
Traceback (most recent call last):
  File "/Users/bradleynordin/Documents/GraphingData/callbacks.py", line 101, in updateData
    length = len(data[stream].index)
KeyError: 'Hybrid_Mux'
2020-12-07 17:26:55,773 - callbacks - ERROR - 'measurement_time'
Traceback (most recent call last):
  File "/Users/bradleynordin/.local/share/virtualenvs/GraphingData-5SWGkA_0/lib/python3.8/site-packages/pandas/core/indexes/base.py", line 2895, in get_loc
    return self._engine.get_loc(casted_key)
  File "pandas/_libs/index.pyx", line 70, in pandas._libs.index.IndexEngine.get_loc
  File "pandas/_libs/index.pyx", line 101, in pandas._libs.index.IndexEngine.get_loc
  File "pandas/_libs/hashtable_class_helper.pxi", line 1675, in pandas._libs.hashtable.PyObjectHashTable.get_item
  File "pandas/_libs/hashtable_class_helper.pxi", line 1683, in pandas._libs.hashtable.PyObjectHashTable.get_item
KeyError: 'measurement_time'

The above exception was the direct cause of the following exception:

Traceback (most recent call last):
  File "/Users/bradleynordin/Documents/GraphingData/callbacks.py", line 94, in updateData
    df['measurement_time'] = pd.to_datetime(df['measurement_time']/(2**32),unit='s')
  File "/Users/bradleynordin/.local/share/virtualenvs/GraphingData-5SWGkA_0/lib/python3.8/site-packages/pandas/core/frame.py", line 2906, in __getitem__
    indexer = self.columns.get_loc(key)
  File "/Users/bradleynordin/.local/share/virtualenvs/GraphingData-5SWGkA_0/lib/python3.8/site-packages/pandas/core/indexes/base.py", line 2897, in get_loc
    raise KeyError(key) from err
KeyError: 'measurement_time'
2020-12-07 17:26:55,774 - callbacks - ERROR - The data csv got messed up
Traceback (most recent call last):
  File "/Users/bradleynordin/Documents/GraphingData/callbacks.py", line 101, in updateData
    length = len(data[stream].index)
KeyError: 'Hybrid_Mux'
2020-12-07 17:26:57,787 - callbacks - ERROR - 'measurement_time'
Traceback (most recent call last):
  File "/Users/bradleynordin/.local/share/virtualenvs/GraphingData-5SWGkA_0/lib/python3.8/site-packages/pandas/core/indexes/base.py", line 2895, in get_loc
    return self._engine.get_loc(casted_key)
  File "pandas/_libs/index.pyx", line 70, in pandas._libs.index.IndexEngine.get_loc
  File "pandas/_libs/index.pyx", line 101, in pandas._libs.index.IndexEngine.get_loc
  File "pandas/_libs/hashtable_class_helper.pxi", line 1675, in pandas._libs.hashtable.PyObjectHashTable.get_item
  File "pandas/_libs/hashtable_class_helper.pxi", line 1683, in pandas._libs.hashtable.PyObjectHashTable.get_item
KeyError: 'measurement_time'

The above exception was the direct cause of the following exception:

Traceback (most recent call last):
  File "/Users/bradleynordin/Documents/GraphingData/callbacks.py", line 94, in updateData
    df['measurement_time'] = pd.to_datetime(df['measurement_time']/(2**32),unit='s')
  File "/Users/bradleynordin/.local/share/virtualenvs/GraphingData-5SWGkA_0/lib/python3.8/site-packages/pandas/core/frame.py", line 2906, in __getitem__
    indexer = self.columns.get_loc(key)
  File "/Users/bradleynordin/.local/share/virtualenvs/GraphingData-5SWGkA_0/lib/python3.8/site-packages/pandas/core/indexes/base.py", line 2897, in get_loc
    raise KeyError(key) from err
KeyError: 'measurement_time'
2020-12-07 17:26:57,790 - callbacks - ERROR - The data csv got messed up
Traceback (most recent call last):
  File "/Users/bradleynordin/Documents/GraphingData/callbacks.py", line 101, in updateData
    length = len(data[stream].index)
KeyError: 'Hybrid_Mux'
2020-12-07 17:26:59,774 - callbacks - ERROR - 'measurement_time'
Traceback (most recent call last):
  File "/Users/bradleynordin/.local/share/virtualenvs/GraphingData-5SWGkA_0/lib/python3.8/site-packages/pandas/core/indexes/base.py", line 2895, in get_loc
    return self._engine.get_loc(casted_key)
  File "pandas/_libs/index.pyx", line 70, in pandas._libs.index.IndexEngine.get_loc
  File "pandas/_libs/index.pyx", line 101, in pandas._libs.index.IndexEngine.get_loc
  File "pandas/_libs/hashtable_class_helper.pxi", line 1675, in pandas._libs.hashtable.PyObjectHashTable.get_item
  File "pandas/_libs/hashtable_class_helper.pxi", line 1683, in pandas._libs.hashtable.PyObjectHashTable.get_item
KeyError: 'measurement_time'

The above exception was the direct cause of the following exception:

Traceback (most recent call last):
  File "/Users/bradleynordin/Documents/GraphingData/callbacks.py", line 94, in updateData
    df['measurement_time'] = pd.to_datetime(df['measurement_time']/(2**32),unit='s')
  File "/Users/bradleynordin/.local/share/virtualenvs/GraphingData-5SWGkA_0/lib/python3.8/site-packages/pandas/core/frame.py", line 2906, in __getitem__
    indexer = self.columns.get_loc(key)
  File "/Users/bradleynordin/.local/share/virtualenvs/GraphingData-5SWGkA_0/lib/python3.8/site-packages/pandas/core/indexes/base.py", line 2897, in get_loc
    raise KeyError(key) from err
KeyError: 'measurement_time'
2020-12-07 17:26:59,775 - callbacks - ERROR - The data csv got messed up
Traceback (most recent call last):
  File "/Users/bradleynordin/Documents/GraphingData/callbacks.py", line 101, in updateData
    length = len(data[stream].index)
KeyError: 'Hybrid_Mux'
2020-12-07 17:27:01,806 - callbacks - ERROR - 'measurement_time'
Traceback (most recent call last):
  File "/Users/bradleynordin/.local/share/virtualenvs/GraphingData-5SWGkA_0/lib/python3.8/site-packages/pandas/core/indexes/base.py", line 2895, in get_loc
    return self._engine.get_loc(casted_key)
  File "pandas/_libs/index.pyx", line 70, in pandas._libs.index.IndexEngine.get_loc
  File "pandas/_libs/index.pyx", line 101, in pandas._libs.index.IndexEngine.get_loc
  File "pandas/_libs/hashtable_class_helper.pxi", line 1675, in pandas._libs.hashtable.PyObjectHashTable.get_item
  File "pandas/_libs/hashtable_class_helper.pxi", line 1683, in pandas._libs.hashtable.PyObjectHashTable.get_item
KeyError: 'measurement_time'

The above exception was the direct cause of the following exception:

Traceback (most recent call last):
  File "/Users/bradleynordin/Documents/GraphingData/callbacks.py", line 94, in updateData
    df['measurement_time'] = pd.to_datetime(df['measurement_time']/(2**32),unit='s')
  File "/Users/bradleynordin/.local/share/virtualenvs/GraphingData-5SWGkA_0/lib/python3.8/site-packages/pandas/core/frame.py", line 2906, in __getitem__
    indexer = self.columns.get_loc(key)
  File "/Users/bradleynordin/.local/share/virtualenvs/GraphingData-5SWGkA_0/lib/python3.8/site-packages/pandas/core/indexes/base.py", line 2897, in get_loc
    raise KeyError(key) from err
KeyError: 'measurement_time'
2020-12-07 17:27:01,807 - callbacks - ERROR - The data csv got messed up
Traceback (most recent call last):
  File "/Users/bradleynordin/Documents/GraphingData/callbacks.py", line 101, in updateData
    length = len(data[stream].index)
KeyError: 'Hybrid_Mux'
2020-12-07 17:27:03,782 - callbacks - ERROR - 'measurement_time'
Traceback (most recent call last):
  File "/Users/bradleynordin/.local/share/virtualenvs/GraphingData-5SWGkA_0/lib/python3.8/site-packages/pandas/core/indexes/base.py", line 2895, in get_loc
    return self._engine.get_loc(casted_key)
  File "pandas/_libs/index.pyx", line 70, in pandas._libs.index.IndexEngine.get_loc
  File "pandas/_libs/index.pyx", line 101, in pandas._libs.index.IndexEngine.get_loc
  File "pandas/_libs/hashtable_class_helper.pxi", line 1675, in pandas._libs.hashtable.PyObjectHashTable.get_item
  File "pandas/_libs/hashtable_class_helper.pxi", line 1683, in pandas._libs.hashtable.PyObjectHashTable.get_item
KeyError: 'measurement_time'

The above exception was the direct cause of the following exception:

Traceback (most recent call last):
  File "/Users/bradleynordin/Documents/GraphingData/callbacks.py", line 94, in updateData
    df['measurement_time'] = pd.to_datetime(df['measurement_time']/(2**32),unit='s')
  File "/Users/bradleynordin/.local/share/virtualenvs/GraphingData-5SWGkA_0/lib/python3.8/site-packages/pandas/core/frame.py", line 2906, in __getitem__
    indexer = self.columns.get_loc(key)
  File "/Users/bradleynordin/.local/share/virtualenvs/GraphingData-5SWGkA_0/lib/python3.8/site-packages/pandas/core/indexes/base.py", line 2897, in get_loc
    raise KeyError(key) from err
KeyError: 'measurement_time'
2020-12-07 17:27:03,783 - callbacks - ERROR - The data csv got messed up
Traceback (most recent call last):
  File "/Users/bradleynordin/Documents/GraphingData/callbacks.py", line 101, in updateData
    length = len(data[stream].index)
KeyError: 'Hybrid_Mux'
2020-12-07 17:27:05,843 - callbacks - ERROR - 'measurement_time'
Traceback (most recent call last):
  File "/Users/bradleynordin/.local/share/virtualenvs/GraphingData-5SWGkA_0/lib/python3.8/site-packages/pandas/core/indexes/base.py", line 2895, in get_loc
    return self._engine.get_loc(casted_key)
  File "pandas/_libs/index.pyx", line 70, in pandas._libs.index.IndexEngine.get_loc
  File "pandas/_libs/index.pyx", line 101, in pandas._libs.index.IndexEngine.get_loc
  File "pandas/_libs/hashtable_class_helper.pxi", line 1675, in pandas._libs.hashtable.PyObjectHashTable.get_item
  File "pandas/_libs/hashtable_class_helper.pxi", line 1683, in pandas._libs.hashtable.PyObjectHashTable.get_item
KeyError: 'measurement_time'

The above exception was the direct cause of the following exception:

Traceback (most recent call last):
  File "/Users/bradleynordin/Documents/GraphingData/callbacks.py", line 94, in updateData
    df['measurement_time'] = pd.to_datetime(df['measurement_time']/(2**32),unit='s')
  File "/Users/bradleynordin/.local/share/virtualenvs/GraphingData-5SWGkA_0/lib/python3.8/site-packages/pandas/core/frame.py", line 2906, in __getitem__
    indexer = self.columns.get_loc(key)
  File "/Users/bradleynordin/.local/share/virtualenvs/GraphingData-5SWGkA_0/lib/python3.8/site-packages/pandas/core/indexes/base.py", line 2897, in get_loc
    raise KeyError(key) from err
KeyError: 'measurement_time'
2020-12-07 17:27:05,844 - callbacks - ERROR - The data csv got messed up
Traceback (most recent call last):
  File "/Users/bradleynordin/Documents/GraphingData/callbacks.py", line 101, in updateData
    length = len(data[stream].index)
KeyError: 'Hybrid_Mux'
2020-12-07 17:28:29,774 - callbacks - ERROR - 'measurement_time'
Traceback (most recent call last):
  File "/Users/bradleynordin/.local/share/virtualenvs/GraphingData-5SWGkA_0/lib/python3.8/site-packages/pandas/core/indexes/base.py", line 2895, in get_loc
    return self._engine.get_loc(casted_key)
  File "pandas/_libs/index.pyx", line 70, in pandas._libs.index.IndexEngine.get_loc
  File "pandas/_libs/index.pyx", line 101, in pandas._libs.index.IndexEngine.get_loc
  File "pandas/_libs/hashtable_class_helper.pxi", line 1675, in pandas._libs.hashtable.PyObjectHashTable.get_item
  File "pandas/_libs/hashtable_class_helper.pxi", line 1683, in pandas._libs.hashtable.PyObjectHashTable.get_item
KeyError: 'measurement_time'

The above exception was the direct cause of the following exception:

Traceback (most recent call last):
  File "/Users/bradleynordin/Documents/GraphingData/callbacks.py", line 94, in updateData
    df['measurement_time'] = pd.to_datetime(df['measurement_time']/(2**32),unit='s')
  File "/Users/bradleynordin/.local/share/virtualenvs/GraphingData-5SWGkA_0/lib/python3.8/site-packages/pandas/core/frame.py", line 2906, in __getitem__
    indexer = self.columns.get_loc(key)
  File "/Users/bradleynordin/.local/share/virtualenvs/GraphingData-5SWGkA_0/lib/python3.8/site-packages/pandas/core/indexes/base.py", line 2897, in get_loc
    raise KeyError(key) from err
KeyError: 'measurement_time'
2020-12-07 17:28:29,778 - callbacks - ERROR - The data csv got messed up
Traceback (most recent call last):
  File "/Users/bradleynordin/Documents/GraphingData/callbacks.py", line 101, in updateData
    length = len(data[stream].index)
KeyError: 'Hybrid_Mux'
2020-12-07 17:28:31,784 - callbacks - ERROR - 'measurement_time'
Traceback (most recent call last):
  File "/Users/bradleynordin/.local/share/virtualenvs/GraphingData-5SWGkA_0/lib/python3.8/site-packages/pandas/core/indexes/base.py", line 2895, in get_loc
    return self._engine.get_loc(casted_key)
  File "pandas/_libs/index.pyx", line 70, in pandas._libs.index.IndexEngine.get_loc
  File "pandas/_libs/index.pyx", line 101, in pandas._libs.index.IndexEngine.get_loc
  File "pandas/_libs/hashtable_class_helper.pxi", line 1675, in pandas._libs.hashtable.PyObjectHashTable.get_item
  File "pandas/_libs/hashtable_class_helper.pxi", line 1683, in pandas._libs.hashtable.PyObjectHashTable.get_item
KeyError: 'measurement_time'

The above exception was the direct cause of the following exception:

Traceback (most recent call last):
  File "/Users/bradleynordin/Documents/GraphingData/callbacks.py", line 94, in updateData
    df['measurement_time'] = pd.to_datetime(df['measurement_time']/(2**32),unit='s')
  File "/Users/bradleynordin/.local/share/virtualenvs/GraphingData-5SWGkA_0/lib/python3.8/site-packages/pandas/core/frame.py", line 2906, in __getitem__
    indexer = self.columns.get_loc(key)
  File "/Users/bradleynordin/.local/share/virtualenvs/GraphingData-5SWGkA_0/lib/python3.8/site-packages/pandas/core/indexes/base.py", line 2897, in get_loc
    raise KeyError(key) from err
KeyError: 'measurement_time'
2020-12-07 17:28:31,789 - callbacks - ERROR - The data csv got messed up
Traceback (most recent call last):
  File "/Users/bradleynordin/Documents/GraphingData/callbacks.py", line 101, in updateData
    length = len(data[stream].index)
KeyError: 'Hybrid_Mux'
2020-12-07 17:28:33,792 - callbacks - ERROR - 'measurement_time'
Traceback (most recent call last):
  File "/Users/bradleynordin/.local/share/virtualenvs/GraphingData-5SWGkA_0/lib/python3.8/site-packages/pandas/core/indexes/base.py", line 2895, in get_loc
    return self._engine.get_loc(casted_key)
  File "pandas/_libs/index.pyx", line 70, in pandas._libs.index.IndexEngine.get_loc
  File "pandas/_libs/index.pyx", line 101, in pandas._libs.index.IndexEngine.get_loc
  File "pandas/_libs/hashtable_class_helper.pxi", line 1675, in pandas._libs.hashtable.PyObjectHashTable.get_item
  File "pandas/_libs/hashtable_class_helper.pxi", line 1683, in pandas._libs.hashtable.PyObjectHashTable.get_item
KeyError: 'measurement_time'

The above exception was the direct cause of the following exception:

Traceback (most recent call last):
  File "/Users/bradleynordin/Documents/GraphingData/callbacks.py", line 94, in updateData
    df['measurement_time'] = pd.to_datetime(df['measurement_time']/(2**32),unit='s')
  File "/Users/bradleynordin/.local/share/virtualenvs/GraphingData-5SWGkA_0/lib/python3.8/site-packages/pandas/core/frame.py", line 2906, in __getitem__
    indexer = self.columns.get_loc(key)
  File "/Users/bradleynordin/.local/share/virtualenvs/GraphingData-5SWGkA_0/lib/python3.8/site-packages/pandas/core/indexes/base.py", line 2897, in get_loc
    raise KeyError(key) from err
KeyError: 'measurement_time'
2020-12-07 17:28:33,793 - callbacks - ERROR - The data csv got messed up
Traceback (most recent call last):
  File "/Users/bradleynordin/Documents/GraphingData/callbacks.py", line 101, in updateData
    length = len(data[stream].index)
KeyError: 'Hybrid_Mux'
2020-12-07 17:28:35,790 - callbacks - ERROR - 'measurement_time'
Traceback (most recent call last):
  File "/Users/bradleynordin/.local/share/virtualenvs/GraphingData-5SWGkA_0/lib/python3.8/site-packages/pandas/core/indexes/base.py", line 2895, in get_loc
    return self._engine.get_loc(casted_key)
  File "pandas/_libs/index.pyx", line 70, in pandas._libs.index.IndexEngine.get_loc
  File "pandas/_libs/index.pyx", line 101, in pandas._libs.index.IndexEngine.get_loc
  File "pandas/_libs/hashtable_class_helper.pxi", line 1675, in pandas._libs.hashtable.PyObjectHashTable.get_item
  File "pandas/_libs/hashtable_class_helper.pxi", line 1683, in pandas._libs.hashtable.PyObjectHashTable.get_item
KeyError: 'measurement_time'

The above exception was the direct cause of the following exception:

Traceback (most recent call last):
  File "/Users/bradleynordin/Documents/GraphingData/callbacks.py", line 94, in updateData
    df['measurement_time'] = pd.to_datetime(df['measurement_time']/(2**32),unit='s')
  File "/Users/bradleynordin/.local/share/virtualenvs/GraphingData-5SWGkA_0/lib/python3.8/site-packages/pandas/core/frame.py", line 2906, in __getitem__
    indexer = self.columns.get_loc(key)
  File "/Users/bradleynordin/.local/share/virtualenvs/GraphingData-5SWGkA_0/lib/python3.8/site-packages/pandas/core/indexes/base.py", line 2897, in get_loc
    raise KeyError(key) from err
KeyError: 'measurement_time'
2020-12-07 17:28:35,791 - callbacks - ERROR - The data csv got messed up
Traceback (most recent call last):
  File "/Users/bradleynordin/Documents/GraphingData/callbacks.py", line 101, in updateData
    length = len(data[stream].index)
KeyError: 'Hybrid_Mux'
2020-12-07 17:28:37,794 - callbacks - ERROR - 'measurement_time'
Traceback (most recent call last):
  File "/Users/bradleynordin/.local/share/virtualenvs/GraphingData-5SWGkA_0/lib/python3.8/site-packages/pandas/core/indexes/base.py", line 2895, in get_loc
    return self._engine.get_loc(casted_key)
  File "pandas/_libs/index.pyx", line 70, in pandas._libs.index.IndexEngine.get_loc
  File "pandas/_libs/index.pyx", line 101, in pandas._libs.index.IndexEngine.get_loc
  File "pandas/_libs/hashtable_class_helper.pxi", line 1675, in pandas._libs.hashtable.PyObjectHashTable.get_item
  File "pandas/_libs/hashtable_class_helper.pxi", line 1683, in pandas._libs.hashtable.PyObjectHashTable.get_item
KeyError: 'measurement_time'

The above exception was the direct cause of the following exception:

Traceback (most recent call last):
  File "/Users/bradleynordin/Documents/GraphingData/callbacks.py", line 94, in updateData
    df['measurement_time'] = pd.to_datetime(df['measurement_time']/(2**32),unit='s')
  File "/Users/bradleynordin/.local/share/virtualenvs/GraphingData-5SWGkA_0/lib/python3.8/site-packages/pandas/core/frame.py", line 2906, in __getitem__
    indexer = self.columns.get_loc(key)
  File "/Users/bradleynordin/.local/share/virtualenvs/GraphingData-5SWGkA_0/lib/python3.8/site-packages/pandas/core/indexes/base.py", line 2897, in get_loc
    raise KeyError(key) from err
KeyError: 'measurement_time'
2020-12-07 17:28:37,794 - callbacks - ERROR - The data csv got messed up
Traceback (most recent call last):
  File "/Users/bradleynordin/Documents/GraphingData/callbacks.py", line 101, in updateData
    length = len(data[stream].index)
KeyError: 'Hybrid_Mux'
2020-12-07 17:28:39,787 - callbacks - ERROR - 'measurement_time'
Traceback (most recent call last):
  File "/Users/bradleynordin/.local/share/virtualenvs/GraphingData-5SWGkA_0/lib/python3.8/site-packages/pandas/core/indexes/base.py", line 2895, in get_loc
    return self._engine.get_loc(casted_key)
  File "pandas/_libs/index.pyx", line 70, in pandas._libs.index.IndexEngine.get_loc
  File "pandas/_libs/index.pyx", line 101, in pandas._libs.index.IndexEngine.get_loc
  File "pandas/_libs/hashtable_class_helper.pxi", line 1675, in pandas._libs.hashtable.PyObjectHashTable.get_item
  File "pandas/_libs/hashtable_class_helper.pxi", line 1683, in pandas._libs.hashtable.PyObjectHashTable.get_item
KeyError: 'measurement_time'

The above exception was the direct cause of the following exception:

Traceback (most recent call last):
  File "/Users/bradleynordin/Documents/GraphingData/callbacks.py", line 94, in updateData
    df['measurement_time'] = pd.to_datetime(df['measurement_time']/(2**32),unit='s')
  File "/Users/bradleynordin/.local/share/virtualenvs/GraphingData-5SWGkA_0/lib/python3.8/site-packages/pandas/core/frame.py", line 2906, in __getitem__
    indexer = self.columns.get_loc(key)
  File "/Users/bradleynordin/.local/share/virtualenvs/GraphingData-5SWGkA_0/lib/python3.8/site-packages/pandas/core/indexes/base.py", line 2897, in get_loc
    raise KeyError(key) from err
KeyError: 'measurement_time'
2020-12-07 17:28:39,788 - callbacks - ERROR - The data csv got messed up
Traceback (most recent call last):
  File "/Users/bradleynordin/Documents/GraphingData/callbacks.py", line 101, in updateData
    length = len(data[stream].index)
KeyError: 'Hybrid_Mux'
2020-12-07 17:28:41,800 - callbacks - ERROR - 'measurement_time'
Traceback (most recent call last):
  File "/Users/bradleynordin/.local/share/virtualenvs/GraphingData-5SWGkA_0/lib/python3.8/site-packages/pandas/core/indexes/base.py", line 2895, in get_loc
    return self._engine.get_loc(casted_key)
  File "pandas/_libs/index.pyx", line 70, in pandas._libs.index.IndexEngine.get_loc
  File "pandas/_libs/index.pyx", line 101, in pandas._libs.index.IndexEngine.get_loc
  File "pandas/_libs/hashtable_class_helper.pxi", line 1675, in pandas._libs.hashtable.PyObjectHashTable.get_item
  File "pandas/_libs/hashtable_class_helper.pxi", line 1683, in pandas._libs.hashtable.PyObjectHashTable.get_item
KeyError: 'measurement_time'

The above exception was the direct cause of the following exception:

Traceback (most recent call last):
  File "/Users/bradleynordin/Documents/GraphingData/callbacks.py", line 94, in updateData
    df['measurement_time'] = pd.to_datetime(df['measurement_time']/(2**32),unit='s')
  File "/Users/bradleynordin/.local/share/virtualenvs/GraphingData-5SWGkA_0/lib/python3.8/site-packages/pandas/core/frame.py", line 2906, in __getitem__
    indexer = self.columns.get_loc(key)
  File "/Users/bradleynordin/.local/share/virtualenvs/GraphingData-5SWGkA_0/lib/python3.8/site-packages/pandas/core/indexes/base.py", line 2897, in get_loc
    raise KeyError(key) from err
KeyError: 'measurement_time'
2020-12-07 17:28:41,801 - callbacks - ERROR - The data csv got messed up
Traceback (most recent call last):
  File "/Users/bradleynordin/Documents/GraphingData/callbacks.py", line 101, in updateData
    length = len(data[stream].index)
KeyError: 'Hybrid_Mux'
2020-12-07 17:28:43,806 - callbacks - ERROR - 'measurement_time'
Traceback (most recent call last):
  File "/Users/bradleynordin/.local/share/virtualenvs/GraphingData-5SWGkA_0/lib/python3.8/site-packages/pandas/core/indexes/base.py", line 2895, in get_loc
    return self._engine.get_loc(casted_key)
  File "pandas/_libs/index.pyx", line 70, in pandas._libs.index.IndexEngine.get_loc
  File "pandas/_libs/index.pyx", line 101, in pandas._libs.index.IndexEngine.get_loc
  File "pandas/_libs/hashtable_class_helper.pxi", line 1675, in pandas._libs.hashtable.PyObjectHashTable.get_item
  File "pandas/_libs/hashtable_class_helper.pxi", line 1683, in pandas._libs.hashtable.PyObjectHashTable.get_item
KeyError: 'measurement_time'

The above exception was the direct cause of the following exception:

Traceback (most recent call last):
  File "/Users/bradleynordin/Documents/GraphingData/callbacks.py", line 94, in updateData
    df['measurement_time'] = pd.to_datetime(df['measurement_time']/(2**32),unit='s')
  File "/Users/bradleynordin/.local/share/virtualenvs/GraphingData-5SWGkA_0/lib/python3.8/site-packages/pandas/core/frame.py", line 2906, in __getitem__
    indexer = self.columns.get_loc(key)
  File "/Users/bradleynordin/.local/share/virtualenvs/GraphingData-5SWGkA_0/lib/python3.8/site-packages/pandas/core/indexes/base.py", line 2897, in get_loc
    raise KeyError(key) from err
KeyError: 'measurement_time'
2020-12-07 17:28:43,807 - callbacks - ERROR - The data csv got messed up
Traceback (most recent call last):
  File "/Users/bradleynordin/Documents/GraphingData/callbacks.py", line 101, in updateData
    length = len(data[stream].index)
KeyError: 'Hybrid_Mux'
2020-12-07 17:32:21,781 - callbacks - ERROR - 'measurement_time'
Traceback (most recent call last):
  File "/Users/bradleynordin/.local/share/virtualenvs/GraphingData-5SWGkA_0/lib/python3.8/site-packages/pandas/core/indexes/base.py", line 2895, in get_loc
    return self._engine.get_loc(casted_key)
  File "pandas/_libs/index.pyx", line 70, in pandas._libs.index.IndexEngine.get_loc
  File "pandas/_libs/index.pyx", line 101, in pandas._libs.index.IndexEngine.get_loc
  File "pandas/_libs/hashtable_class_helper.pxi", line 1675, in pandas._libs.hashtable.PyObjectHashTable.get_item
  File "pandas/_libs/hashtable_class_helper.pxi", line 1683, in pandas._libs.hashtable.PyObjectHashTable.get_item
KeyError: 'measurement_time'

The above exception was the direct cause of the following exception:

Traceback (most recent call last):
  File "/Users/bradleynordin/Documents/GraphingData/callbacks.py", line 95, in updateData
    df['measurement_time'] = pd.to_datetime(df['measurement_time']/(2**32),unit='s')
  File "/Users/bradleynordin/.local/share/virtualenvs/GraphingData-5SWGkA_0/lib/python3.8/site-packages/pandas/core/frame.py", line 2906, in __getitem__
    indexer = self.columns.get_loc(key)
  File "/Users/bradleynordin/.local/share/virtualenvs/GraphingData-5SWGkA_0/lib/python3.8/site-packages/pandas/core/indexes/base.py", line 2897, in get_loc
    raise KeyError(key) from err
KeyError: 'measurement_time'
