2020-12-07 19:08:15,917 - callbacks - DEBUG - graphing 24hr
2020-12-07 19:09:08,128 - callbacks - DEBUG - graphing 24hr
2020-12-07 19:10:48,918 - callbacks - DEBUG - graphing 24hr
2020-12-07 19:11:40,494 - callbacks - DEBUG - graphing 24hr
2020-12-07 19:11:40,768 - callbacks - DEBUG - starting reads
2020-12-07 19:13:44,202 - callbacks - DEBUG - graphing 24hr
2020-12-07 19:13:44,507 - callbacks - DEBUG - starting reads
2020-12-07 19:14:37,470 - callbacks - ERROR - [Errno 2] No such file or directory: 'data0038.csv'
Traceback (most recent call last):
  File "/home/bradleynordin/Documents/GraphingData/callbacks.py", line 89, in updateData
    df = pd.read_csv(file)
  File "/home/bradleynordin/.local/share/virtualenvs/GraphingData-0ufmG3h2/lib/python3.8/site-packages/pandas/io/parsers.py", line 688, in read_csv
    return _read(filepath_or_buffer, kwds)
  File "/home/bradleynordin/.local/share/virtualenvs/GraphingData-0ufmG3h2/lib/python3.8/site-packages/pandas/io/parsers.py", line 454, in _read
    parser = TextFileReader(fp_or_buf, **kwds)
  File "/home/bradleynordin/.local/share/virtualenvs/GraphingData-0ufmG3h2/lib/python3.8/site-packages/pandas/io/parsers.py", line 948, in __init__
    self._make_engine(self.engine)
  File "/home/bradleynordin/.local/share/virtualenvs/GraphingData-0ufmG3h2/lib/python3.8/site-packages/pandas/io/parsers.py", line 1180, in _make_engine
    self._engine = CParserWrapper(self.f, **self.options)
  File "/home/bradleynordin/.local/share/virtualenvs/GraphingData-0ufmG3h2/lib/python3.8/site-packages/pandas/io/parsers.py", line 2010, in __init__
    self._reader = parsers.TextReader(src, **kwds)
  File "pandas/_libs/parsers.pyx", line 382, in pandas._libs.parsers.TextReader.__cinit__
  File "pandas/_libs/parsers.pyx", line 674, in pandas._libs.parsers.TextReader._setup_parser_source
FileNotFoundError: [Errno 2] No such file or directory: 'data0038.csv'
2020-12-07 19:14:48,604 - callbacks - DEBUG - done with read {'measurement_time': {'start': 6903656661983742976, 'stop': 6903656662847031296}, 'FORT': {'standard_deviation': 5.461094997579687, 'average': 4.040932141744548, 'min': -0.295536, 'max': 11.0877}}
2020-12-07 19:19:25,496 - callbacks - ERROR - write() argument must be str, not Index
Traceback (most recent call last):
  File "/home/bradleynordin/Documents/GraphingData/callbacks.py", line 92, in updateData
    f.write(df.columns)
TypeError: write() argument must be str, not Index
2020-12-07 19:19:33,822 - callbacks - ERROR - write() argument must be str, not Index
Traceback (most recent call last):
  File "/home/bradleynordin/Documents/GraphingData/callbacks.py", line 92, in updateData
    f.write(df.columns)
TypeError: write() argument must be str, not Index
2020-12-07 19:19:35,837 - callbacks - ERROR - write() argument must be str, not Index
Traceback (most recent call last):
  File "/home/bradleynordin/Documents/GraphingData/callbacks.py", line 92, in updateData
    f.write(df.columns)
TypeError: write() argument must be str, not Index
2020-12-07 19:19:37,824 - callbacks - ERROR - write() argument must be str, not Index
Traceback (most recent call last):
  File "/home/bradleynordin/Documents/GraphingData/callbacks.py", line 92, in updateData
    f.write(df.columns)
TypeError: write() argument must be str, not Index
2020-12-07 19:19:39,825 - callbacks - ERROR - write() argument must be str, not Index
Traceback (most recent call last):
  File "/home/bradleynordin/Documents/GraphingData/callbacks.py", line 92, in updateData
    f.write(df.columns)
TypeError: write() argument must be str, not Index
2020-12-07 19:19:41,822 - callbacks - ERROR - write() argument must be str, not Index
Traceback (most recent call last):
  File "/home/bradleynordin/Documents/GraphingData/callbacks.py", line 92, in updateData
    f.write(df.columns)
TypeError: write() argument must be str, not Index
2020-12-07 19:19:43,823 - callbacks - ERROR - write() argument must be str, not Index
Traceback (most recent call last):
  File "/home/bradleynordin/Documents/GraphingData/callbacks.py", line 92, in updateData
    f.write(df.columns)
TypeError: write() argument must be str, not Index
2020-12-07 19:19:45,823 - callbacks - ERROR - write() argument must be str, not Index
Traceback (most recent call last):
  File "/home/bradleynordin/Documents/GraphingData/callbacks.py", line 92, in updateData
    f.write(df.columns)
TypeError: write() argument must be str, not Index
2020-12-07 19:19:47,823 - callbacks - ERROR - write() argument must be str, not Index
Traceback (most recent call last):
  File "/home/bradleynordin/Documents/GraphingData/callbacks.py", line 92, in updateData
    f.write(df.columns)
TypeError: write() argument must be str, not Index
2020-12-07 19:25:49,930 - callbacks - ERROR - 'measurement_time'
Traceback (most recent call last):
  File "/home/bradleynordin/.local/share/virtualenvs/GraphingData-0ufmG3h2/lib/python3.8/site-packages/pandas/core/indexes/base.py", line 2898, in get_loc
    return self._engine.get_loc(casted_key)
  File "pandas/_libs/index.pyx", line 70, in pandas._libs.index.IndexEngine.get_loc
  File "pandas/_libs/index.pyx", line 101, in pandas._libs.index.IndexEngine.get_loc
  File "pandas/_libs/hashtable_class_helper.pxi", line 1675, in pandas._libs.hashtable.PyObjectHashTable.get_item
  File "pandas/_libs/hashtable_class_helper.pxi", line 1683, in pandas._libs.hashtable.PyObjectHashTable.get_item
KeyError: 'measurement_time'

The above exception was the direct cause of the following exception:

Traceback (most recent call last):
  File "/home/bradleynordin/Documents/GraphingData/callbacks.py", line 97, in updateData
    df['measurement_time'] = pd.to_datetime(df['measurement_time']/(2**32),unit='s')
  File "/home/bradleynordin/.local/share/virtualenvs/GraphingData-0ufmG3h2/lib/python3.8/site-packages/pandas/core/frame.py", line 2906, in __getitem__
    indexer = self.columns.get_loc(key)
  File "/home/bradleynordin/.local/share/virtualenvs/GraphingData-0ufmG3h2/lib/python3.8/site-packages/pandas/core/indexes/base.py", line 2900, in get_loc
    raise KeyError(key) from err
KeyError: 'measurement_time'
2020-12-07 19:26:04,423 - callbacks - ERROR - 'measurement_time'
Traceback (most recent call last):
  File "/home/bradleynordin/.local/share/virtualenvs/GraphingData-0ufmG3h2/lib/python3.8/site-packages/pandas/core/indexes/base.py", line 2898, in get_loc
    return self._engine.get_loc(casted_key)
  File "pandas/_libs/index.pyx", line 70, in pandas._libs.index.IndexEngine.get_loc
  File "pandas/_libs/index.pyx", line 101, in pandas._libs.index.IndexEngine.get_loc
  File "pandas/_libs/hashtable_class_helper.pxi", line 1675, in pandas._libs.hashtable.PyObjectHashTable.get_item
  File "pandas/_libs/hashtable_class_helper.pxi", line 1683, in pandas._libs.hashtable.PyObjectHashTable.get_item
KeyError: 'measurement_time'

The above exception was the direct cause of the following exception:

Traceback (most recent call last):
  File "/home/bradleynordin/Documents/GraphingData/callbacks.py", line 97, in updateData
    df['measurement_time'] = pd.to_datetime(df['measurement_time']/(2**32),unit='s')
  File "/home/bradleynordin/.local/share/virtualenvs/GraphingData-0ufmG3h2/lib/python3.8/site-packages/pandas/core/frame.py", line 2906, in __getitem__
    indexer = self.columns.get_loc(key)
  File "/home/bradleynordin/.local/share/virtualenvs/GraphingData-0ufmG3h2/lib/python3.8/site-packages/pandas/core/indexes/base.py", line 2900, in get_loc
    raise KeyError(key) from err
KeyError: 'measurement_time'
2020-12-07 19:26:06,424 - callbacks - ERROR - 'measurement_time'
Traceback (most recent call last):
  File "/home/bradleynordin/.local/share/virtualenvs/GraphingData-0ufmG3h2/lib/python3.8/site-packages/pandas/core/indexes/base.py", line 2898, in get_loc
    return self._engine.get_loc(casted_key)
  File "pandas/_libs/index.pyx", line 70, in pandas._libs.index.IndexEngine.get_loc
  File "pandas/_libs/index.pyx", line 101, in pandas._libs.index.IndexEngine.get_loc
  File "pandas/_libs/hashtable_class_helper.pxi", line 1675, in pandas._libs.hashtable.PyObjectHashTable.get_item
  File "pandas/_libs/hashtable_class_helper.pxi", line 1683, in pandas._libs.hashtable.PyObjectHashTable.get_item
KeyError: 'measurement_time'

The above exception was the direct cause of the following exception:

Traceback (most recent call last):
  File "/home/bradleynordin/Documents/GraphingData/callbacks.py", line 97, in updateData
    df['measurement_time'] = pd.to_datetime(df['measurement_time']/(2**32),unit='s')
  File "/home/bradleynordin/.local/share/virtualenvs/GraphingData-0ufmG3h2/lib/python3.8/site-packages/pandas/core/frame.py", line 2906, in __getitem__
    indexer = self.columns.get_loc(key)
  File "/home/bradleynordin/.local/share/virtualenvs/GraphingData-0ufmG3h2/lib/python3.8/site-packages/pandas/core/indexes/base.py", line 2900, in get_loc
    raise KeyError(key) from err
KeyError: 'measurement_time'
2020-12-07 19:26:08,443 - callbacks - ERROR - 'measurement_time'
Traceback (most recent call last):
  File "/home/bradleynordin/.local/share/virtualenvs/GraphingData-0ufmG3h2/lib/python3.8/site-packages/pandas/core/indexes/base.py", line 2898, in get_loc
    return self._engine.get_loc(casted_key)
  File "pandas/_libs/index.pyx", line 70, in pandas._libs.index.IndexEngine.get_loc
  File "pandas/_libs/index.pyx", line 101, in pandas._libs.index.IndexEngine.get_loc
  File "pandas/_libs/hashtable_class_helper.pxi", line 1675, in pandas._libs.hashtable.PyObjectHashTable.get_item
  File "pandas/_libs/hashtable_class_helper.pxi", line 1683, in pandas._libs.hashtable.PyObjectHashTable.get_item
KeyError: 'measurement_time'

The above exception was the direct cause of the following exception:

Traceback (most recent call last):
  File "/home/bradleynordin/Documents/GraphingData/callbacks.py", line 97, in updateData
    df['measurement_time'] = pd.to_datetime(df['measurement_time']/(2**32),unit='s')
  File "/home/bradleynordin/.local/share/virtualenvs/GraphingData-0ufmG3h2/lib/python3.8/site-packages/pandas/core/frame.py", line 2906, in __getitem__
    indexer = self.columns.get_loc(key)
  File "/home/bradleynordin/.local/share/virtualenvs/GraphingData-0ufmG3h2/lib/python3.8/site-packages/pandas/core/indexes/base.py", line 2900, in get_loc
    raise KeyError(key) from err
KeyError: 'measurement_time'
2020-12-07 19:26:10,423 - callbacks - ERROR - 'measurement_time'
Traceback (most recent call last):
  File "/home/bradleynordin/.local/share/virtualenvs/GraphingData-0ufmG3h2/lib/python3.8/site-packages/pandas/core/indexes/base.py", line 2898, in get_loc
    return self._engine.get_loc(casted_key)
  File "pandas/_libs/index.pyx", line 70, in pandas._libs.index.IndexEngine.get_loc
  File "pandas/_libs/index.pyx", line 101, in pandas._libs.index.IndexEngine.get_loc
  File "pandas/_libs/hashtable_class_helper.pxi", line 1675, in pandas._libs.hashtable.PyObjectHashTable.get_item
  File "pandas/_libs/hashtable_class_helper.pxi", line 1683, in pandas._libs.hashtable.PyObjectHashTable.get_item
KeyError: 'measurement_time'

The above exception was the direct cause of the following exception:

Traceback (most recent call last):
  File "/home/bradleynordin/Documents/GraphingData/callbacks.py", line 97, in updateData
    df['measurement_time'] = pd.to_datetime(df['measurement_time']/(2**32),unit='s')
  File "/home/bradleynordin/.local/share/virtualenvs/GraphingData-0ufmG3h2/lib/python3.8/site-packages/pandas/core/frame.py", line 2906, in __getitem__
    indexer = self.columns.get_loc(key)
  File "/home/bradleynordin/.local/share/virtualenvs/GraphingData-0ufmG3h2/lib/python3.8/site-packages/pandas/core/indexes/base.py", line 2900, in get_loc
    raise KeyError(key) from err
KeyError: 'measurement_time'
2020-12-07 19:26:12,429 - callbacks - ERROR - 'measurement_time'
Traceback (most recent call last):
  File "/home/bradleynordin/.local/share/virtualenvs/GraphingData-0ufmG3h2/lib/python3.8/site-packages/pandas/core/indexes/base.py", line 2898, in get_loc
    return self._engine.get_loc(casted_key)
  File "pandas/_libs/index.pyx", line 70, in pandas._libs.index.IndexEngine.get_loc
  File "pandas/_libs/index.pyx", line 101, in pandas._libs.index.IndexEngine.get_loc
  File "pandas/_libs/hashtable_class_helper.pxi", line 1675, in pandas._libs.hashtable.PyObjectHashTable.get_item
  File "pandas/_libs/hashtable_class_helper.pxi", line 1683, in pandas._libs.hashtable.PyObjectHashTable.get_item
KeyError: 'measurement_time'

The above exception was the direct cause of the following exception:

Traceback (most recent call last):
  File "/home/bradleynordin/Documents/GraphingData/callbacks.py", line 97, in updateData
    df['measurement_time'] = pd.to_datetime(df['measurement_time']/(2**32),unit='s')
  File "/home/bradleynordin/.local/share/virtualenvs/GraphingData-0ufmG3h2/lib/python3.8/site-packages/pandas/core/frame.py", line 2906, in __getitem__
    indexer = self.columns.get_loc(key)
  File "/home/bradleynordin/.local/share/virtualenvs/GraphingData-0ufmG3h2/lib/python3.8/site-packages/pandas/core/indexes/base.py", line 2900, in get_loc
    raise KeyError(key) from err
KeyError: 'measurement_time'
2020-12-07 19:26:14,445 - callbacks - ERROR - 'measurement_time'
Traceback (most recent call last):
  File "/home/bradleynordin/.local/share/virtualenvs/GraphingData-0ufmG3h2/lib/python3.8/site-packages/pandas/core/indexes/base.py", line 2898, in get_loc
    return self._engine.get_loc(casted_key)
  File "pandas/_libs/index.pyx", line 70, in pandas._libs.index.IndexEngine.get_loc
  File "pandas/_libs/index.pyx", line 101, in pandas._libs.index.IndexEngine.get_loc
  File "pandas/_libs/hashtable_class_helper.pxi", line 1675, in pandas._libs.hashtable.PyObjectHashTable.get_item
  File "pandas/_libs/hashtable_class_helper.pxi", line 1683, in pandas._libs.hashtable.PyObjectHashTable.get_item
KeyError: 'measurement_time'

The above exception was the direct cause of the following exception:

Traceback (most recent call last):
  File "/home/bradleynordin/Documents/GraphingData/callbacks.py", line 97, in updateData
    df['measurement_time'] = pd.to_datetime(df['measurement_time']/(2**32),unit='s')
  File "/home/bradleynordin/.local/share/virtualenvs/GraphingData-0ufmG3h2/lib/python3.8/site-packages/pandas/core/frame.py", line 2906, in __getitem__
    indexer = self.columns.get_loc(key)
  File "/home/bradleynordin/.local/share/virtualenvs/GraphingData-0ufmG3h2/lib/python3.8/site-packages/pandas/core/indexes/base.py", line 2900, in get_loc
    raise KeyError(key) from err
KeyError: 'measurement_time'
2020-12-07 19:26:16,431 - callbacks - ERROR - 'measurement_time'
Traceback (most recent call last):
  File "/home/bradleynordin/.local/share/virtualenvs/GraphingData-0ufmG3h2/lib/python3.8/site-packages/pandas/core/indexes/base.py", line 2898, in get_loc
    return self._engine.get_loc(casted_key)
  File "pandas/_libs/index.pyx", line 70, in pandas._libs.index.IndexEngine.get_loc
  File "pandas/_libs/index.pyx", line 101, in pandas._libs.index.IndexEngine.get_loc
  File "pandas/_libs/hashtable_class_helper.pxi", line 1675, in pandas._libs.hashtable.PyObjectHashTable.get_item
  File "pandas/_libs/hashtable_class_helper.pxi", line 1683, in pandas._libs.hashtable.PyObjectHashTable.get_item
KeyError: 'measurement_time'

The above exception was the direct cause of the following exception:

Traceback (most recent call last):
  File "/home/bradleynordin/Documents/GraphingData/callbacks.py", line 97, in updateData
    df['measurement_time'] = pd.to_datetime(df['measurement_time']/(2**32),unit='s')
  File "/home/bradleynordin/.local/share/virtualenvs/GraphingData-0ufmG3h2/lib/python3.8/site-packages/pandas/core/frame.py", line 2906, in __getitem__
    indexer = self.columns.get_loc(key)
  File "/home/bradleynordin/.local/share/virtualenvs/GraphingData-0ufmG3h2/lib/python3.8/site-packages/pandas/core/indexes/base.py", line 2900, in get_loc
    raise KeyError(key) from err
KeyError: 'measurement_time'
2020-12-07 19:26:18,442 - callbacks - ERROR - 'measurement_time'
Traceback (most recent call last):
  File "/home/bradleynordin/.local/share/virtualenvs/GraphingData-0ufmG3h2/lib/python3.8/site-packages/pandas/core/indexes/base.py", line 2898, in get_loc
    return self._engine.get_loc(casted_key)
  File "pandas/_libs/index.pyx", line 70, in pandas._libs.index.IndexEngine.get_loc
  File "pandas/_libs/index.pyx", line 101, in pandas._libs.index.IndexEngine.get_loc
  File "pandas/_libs/hashtable_class_helper.pxi", line 1675, in pandas._libs.hashtable.PyObjectHashTable.get_item
  File "pandas/_libs/hashtable_class_helper.pxi", line 1683, in pandas._libs.hashtable.PyObjectHashTable.get_item
KeyError: 'measurement_time'

The above exception was the direct cause of the following exception:

Traceback (most recent call last):
  File "/home/bradleynordin/Documents/GraphingData/callbacks.py", line 97, in updateData
    df['measurement_time'] = pd.to_datetime(df['measurement_time']/(2**32),unit='s')
  File "/home/bradleynordin/.local/share/virtualenvs/GraphingData-0ufmG3h2/lib/python3.8/site-packages/pandas/core/frame.py", line 2906, in __getitem__
    indexer = self.columns.get_loc(key)
  File "/home/bradleynordin/.local/share/virtualenvs/GraphingData-0ufmG3h2/lib/python3.8/site-packages/pandas/core/indexes/base.py", line 2900, in get_loc
    raise KeyError(key) from err
KeyError: 'measurement_time'
2020-12-07 19:26:20,432 - callbacks - ERROR - 'measurement_time'
Traceback (most recent call last):
  File "/home/bradleynordin/.local/share/virtualenvs/GraphingData-0ufmG3h2/lib/python3.8/site-packages/pandas/core/indexes/base.py", line 2898, in get_loc
    return self._engine.get_loc(casted_key)
  File "pandas/_libs/index.pyx", line 70, in pandas._libs.index.IndexEngine.get_loc
  File "pandas/_libs/index.pyx", line 101, in pandas._libs.index.IndexEngine.get_loc
  File "pandas/_libs/hashtable_class_helper.pxi", line 1675, in pandas._libs.hashtable.PyObjectHashTable.get_item
  File "pandas/_libs/hashtable_class_helper.pxi", line 1683, in pandas._libs.hashtable.PyObjectHashTable.get_item
KeyError: 'measurement_time'

The above exception was the direct cause of the following exception:

Traceback (most recent call last):
  File "/home/bradleynordin/Documents/GraphingData/callbacks.py", line 97, in updateData
    df['measurement_time'] = pd.to_datetime(df['measurement_time']/(2**32),unit='s')
  File "/home/bradleynordin/.local/share/virtualenvs/GraphingData-0ufmG3h2/lib/python3.8/site-packages/pandas/core/frame.py", line 2906, in __getitem__
    indexer = self.columns.get_loc(key)
  File "/home/bradleynordin/.local/share/virtualenvs/GraphingData-0ufmG3h2/lib/python3.8/site-packages/pandas/core/indexes/base.py", line 2900, in get_loc
    raise KeyError(key) from err
KeyError: 'measurement_time'
2020-12-07 19:26:22,454 - callbacks - ERROR - 'measurement_time'
Traceback (most recent call last):
  File "/home/bradleynordin/.local/share/virtualenvs/GraphingData-0ufmG3h2/lib/python3.8/site-packages/pandas/core/indexes/base.py", line 2898, in get_loc
    return self._engine.get_loc(casted_key)
  File "pandas/_libs/index.pyx", line 70, in pandas._libs.index.IndexEngine.get_loc
  File "pandas/_libs/index.pyx", line 101, in pandas._libs.index.IndexEngine.get_loc
  File "pandas/_libs/hashtable_class_helper.pxi", line 1675, in pandas._libs.hashtable.PyObjectHashTable.get_item
  File "pandas/_libs/hashtable_class_helper.pxi", line 1683, in pandas._libs.hashtable.PyObjectHashTable.get_item
KeyError: 'measurement_time'

The above exception was the direct cause of the following exception:

Traceback (most recent call last):
  File "/home/bradleynordin/Documents/GraphingData/callbacks.py", line 97, in updateData
    df['measurement_time'] = pd.to_datetime(df['measurement_time']/(2**32),unit='s')
  File "/home/bradleynordin/.local/share/virtualenvs/GraphingData-0ufmG3h2/lib/python3.8/site-packages/pandas/core/frame.py", line 2906, in __getitem__
    indexer = self.columns.get_loc(key)
  File "/home/bradleynordin/.local/share/virtualenvs/GraphingData-0ufmG3h2/lib/python3.8/site-packages/pandas/core/indexes/base.py", line 2900, in get_loc
    raise KeyError(key) from err
KeyError: 'measurement_time'
2020-12-07 19:26:24,429 - callbacks - ERROR - 'measurement_time'
Traceback (most recent call last):
  File "/home/bradleynordin/.local/share/virtualenvs/GraphingData-0ufmG3h2/lib/python3.8/site-packages/pandas/core/indexes/base.py", line 2898, in get_loc
    return self._engine.get_loc(casted_key)
  File "pandas/_libs/index.pyx", line 70, in pandas._libs.index.IndexEngine.get_loc
  File "pandas/_libs/index.pyx", line 101, in pandas._libs.index.IndexEngine.get_loc
  File "pandas/_libs/hashtable_class_helper.pxi", line 1675, in pandas._libs.hashtable.PyObjectHashTable.get_item
  File "pandas/_libs/hashtable_class_helper.pxi", line 1683, in pandas._libs.hashtable.PyObjectHashTable.get_item
KeyError: 'measurement_time'

The above exception was the direct cause of the following exception:

Traceback (most recent call last):
  File "/home/bradleynordin/Documents/GraphingData/callbacks.py", line 97, in updateData
    df['measurement_time'] = pd.to_datetime(df['measurement_time']/(2**32),unit='s')
  File "/home/bradleynordin/.local/share/virtualenvs/GraphingData-0ufmG3h2/lib/python3.8/site-packages/pandas/core/frame.py", line 2906, in __getitem__
    indexer = self.columns.get_loc(key)
  File "/home/bradleynordin/.local/share/virtualenvs/GraphingData-0ufmG3h2/lib/python3.8/site-packages/pandas/core/indexes/base.py", line 2900, in get_loc
    raise KeyError(key) from err
KeyError: 'measurement_time'
2020-12-07 19:27:32,453 - callbacks - DEBUG - 6903689170217544704,-0.26419433951377876903690771415711744,-0.273596793413162236903690787801012224,-0.267328500747680666903690796326522880,-0.270462632179260256903690804916457472,-0.27673095464706426903690813506392064,-0.267328500747680666903690822096326656,-0.27986511588096626903690830931074048,-0.273596793413162236903690839276195840,-0.27986511588096626903690847861834752,-0.27673095464706426903690856464654336,-0.270462632179260256903690864191300608,-0.267328500747680666903690873790553088,-0.2641943395137787
2020-12-07 19:27:32,454 - callbacks - ERROR - 'measurement_time'
Traceback (most recent call last):
  File "/home/bradleynordin/.local/share/virtualenvs/GraphingData-0ufmG3h2/lib/python3.8/site-packages/pandas/core/indexes/base.py", line 2898, in get_loc
    return self._engine.get_loc(casted_key)
  File "pandas/_libs/index.pyx", line 70, in pandas._libs.index.IndexEngine.get_loc
  File "pandas/_libs/index.pyx", line 101, in pandas._libs.index.IndexEngine.get_loc
  File "pandas/_libs/hashtable_class_helper.pxi", line 1675, in pandas._libs.hashtable.PyObjectHashTable.get_item
  File "pandas/_libs/hashtable_class_helper.pxi", line 1683, in pandas._libs.hashtable.PyObjectHashTable.get_item
KeyError: 'measurement_time'

The above exception was the direct cause of the following exception:

Traceback (most recent call last):
  File "/home/bradleynordin/Documents/GraphingData/callbacks.py", line 99, in updateData
    df['measurement_time'] = pd.to_datetime(df['measurement_time']/(2**32),unit='s')
  File "/home/bradleynordin/.local/share/virtualenvs/GraphingData-0ufmG3h2/lib/python3.8/site-packages/pandas/core/frame.py", line 2906, in __getitem__
    indexer = self.columns.get_loc(key)
  File "/home/bradleynordin/.local/share/virtualenvs/GraphingData-0ufmG3h2/lib/python3.8/site-packages/pandas/core/indexes/base.py", line 2900, in get_loc
    raise KeyError(key) from err
KeyError: 'measurement_time'
2020-12-07 19:27:39,603 - callbacks - DEBUG - 6903689170217544704,-0.26419433951377876903690771415711744,-0.273596793413162236903690787801012224,-0.267328500747680666903690796326522880,-0.270462632179260256903690804916457472,-0.27673095464706426903690813506392064,-0.267328500747680666903690822096326656,-0.27986511588096626903690830931074048,-0.273596793413162236903690839276195840,-0.27986511588096626903690847861834752,-0.27673095464706426903690856464654336,-0.270462632179260256903690864191300608,-0.267328500747680666903690873790553088,-0.26419433951377876903691182882168832,-0.26732850074768066
2020-12-07 19:27:39,604 - callbacks - ERROR - 'measurement_time'
Traceback (most recent call last):
  File "/home/bradleynordin/.local/share/virtualenvs/GraphingData-0ufmG3h2/lib/python3.8/site-packages/pandas/core/indexes/base.py", line 2898, in get_loc
    return self._engine.get_loc(casted_key)
  File "pandas/_libs/index.pyx", line 70, in pandas._libs.index.IndexEngine.get_loc
  File "pandas/_libs/index.pyx", line 101, in pandas._libs.index.IndexEngine.get_loc
  File "pandas/_libs/hashtable_class_helper.pxi", line 1675, in pandas._libs.hashtable.PyObjectHashTable.get_item
  File "pandas/_libs/hashtable_class_helper.pxi", line 1683, in pandas._libs.hashtable.PyObjectHashTable.get_item
KeyError: 'measurement_time'

The above exception was the direct cause of the following exception:

Traceback (most recent call last):
  File "/home/bradleynordin/Documents/GraphingData/callbacks.py", line 99, in updateData
    df['measurement_time'] = pd.to_datetime(df['measurement_time']/(2**32),unit='s')
  File "/home/bradleynordin/.local/share/virtualenvs/GraphingData-0ufmG3h2/lib/python3.8/site-packages/pandas/core/frame.py", line 2906, in __getitem__
    indexer = self.columns.get_loc(key)
  File "/home/bradleynordin/.local/share/virtualenvs/GraphingData-0ufmG3h2/lib/python3.8/site-packages/pandas/core/indexes/base.py", line 2900, in get_loc
    raise KeyError(key) from err
KeyError: 'measurement_time'
2020-12-07 19:27:41,605 - callbacks - DEBUG - 6903689170217544704,-0.26419433951377876903690771415711744,-0.273596793413162236903690787801012224,-0.267328500747680666903690796326522880,-0.270462632179260256903690804916457472,-0.27673095464706426903690813506392064,-0.267328500747680666903690822096326656,-0.27986511588096626903690830931074048,-0.273596793413162236903690839276195840,-0.27986511588096626903690847861834752,-0.27673095464706426903690856464654336,-0.270462632179260256903690864191300608,-0.267328500747680666903690873790553088,-0.26419433951377876903691182882168832,-0.267328500747680666903691195908804608,-0.27046263217926025
2020-12-07 19:27:41,605 - callbacks - ERROR - 'measurement_time'
Traceback (most recent call last):
  File "/home/bradleynordin/.local/share/virtualenvs/GraphingData-0ufmG3h2/lib/python3.8/site-packages/pandas/core/indexes/base.py", line 2898, in get_loc
    return self._engine.get_loc(casted_key)
  File "pandas/_libs/index.pyx", line 70, in pandas._libs.index.IndexEngine.get_loc
  File "pandas/_libs/index.pyx", line 101, in pandas._libs.index.IndexEngine.get_loc
  File "pandas/_libs/hashtable_class_helper.pxi", line 1675, in pandas._libs.hashtable.PyObjectHashTable.get_item
  File "pandas/_libs/hashtable_class_helper.pxi", line 1683, in pandas._libs.hashtable.PyObjectHashTable.get_item
KeyError: 'measurement_time'

The above exception was the direct cause of the following exception:

Traceback (most recent call last):
  File "/home/bradleynordin/Documents/GraphingData/callbacks.py", line 99, in updateData
    df['measurement_time'] = pd.to_datetime(df['measurement_time']/(2**32),unit='s')
  File "/home/bradleynordin/.local/share/virtualenvs/GraphingData-0ufmG3h2/lib/python3.8/site-packages/pandas/core/frame.py", line 2906, in __getitem__
    indexer = self.columns.get_loc(key)
  File "/home/bradleynordin/.local/share/virtualenvs/GraphingData-0ufmG3h2/lib/python3.8/site-packages/pandas/core/indexes/base.py", line 2900, in get_loc
    raise KeyError(key) from err
KeyError: 'measurement_time'
2020-12-07 19:27:43,606 - callbacks - DEBUG - 6903689170217544704,-0.26419433951377876903690771415711744,-0.273596793413162236903690787801012224,-0.267328500747680666903690796326522880,-0.270462632179260256903690804916457472,-0.27673095464706426903690813506392064,-0.267328500747680666903690822096326656,-0.27986511588096626903690830931074048,-0.273596793413162236903690839276195840,-0.27986511588096626903690847861834752,-0.27673095464706426903690856464654336,-0.270462632179260256903690864191300608,-0.267328500747680666903690873790553088,-0.26419433951377876903691182882168832,-0.267328500747680666903691195908804608,-0.270462632179260256903691205211704320,-0.2641943395137787
2020-12-07 19:27:43,606 - callbacks - ERROR - 'measurement_time'
Traceback (most recent call last):
  File "/home/bradleynordin/.local/share/virtualenvs/GraphingData-0ufmG3h2/lib/python3.8/site-packages/pandas/core/indexes/base.py", line 2898, in get_loc
    return self._engine.get_loc(casted_key)
  File "pandas/_libs/index.pyx", line 70, in pandas._libs.index.IndexEngine.get_loc
  File "pandas/_libs/index.pyx", line 101, in pandas._libs.index.IndexEngine.get_loc
  File "pandas/_libs/hashtable_class_helper.pxi", line 1675, in pandas._libs.hashtable.PyObjectHashTable.get_item
  File "pandas/_libs/hashtable_class_helper.pxi", line 1683, in pandas._libs.hashtable.PyObjectHashTable.get_item
KeyError: 'measurement_time'

The above exception was the direct cause of the following exception:

Traceback (most recent call last):
  File "/home/bradleynordin/Documents/GraphingData/callbacks.py", line 99, in updateData
    df['measurement_time'] = pd.to_datetime(df['measurement_time']/(2**32),unit='s')
  File "/home/bradleynordin/.local/share/virtualenvs/GraphingData-0ufmG3h2/lib/python3.8/site-packages/pandas/core/frame.py", line 2906, in __getitem__
    indexer = self.columns.get_loc(key)
  File "/home/bradleynordin/.local/share/virtualenvs/GraphingData-0ufmG3h2/lib/python3.8/site-packages/pandas/core/indexes/base.py", line 2900, in get_loc
    raise KeyError(key) from err
KeyError: 'measurement_time'
2020-12-07 19:28:10,188 - callbacks - ERROR - [Errno 2] No such file or directory: 'data0038.csv'
Traceback (most recent call last):
  File "/home/bradleynordin/Documents/GraphingData/callbacks.py", line 89, in updateData
    df = pd.read_csv(fileName)
  File "/home/bradleynordin/.local/share/virtualenvs/GraphingData-0ufmG3h2/lib/python3.8/site-packages/pandas/io/parsers.py", line 688, in read_csv
    return _read(filepath_or_buffer, kwds)
  File "/home/bradleynordin/.local/share/virtualenvs/GraphingData-0ufmG3h2/lib/python3.8/site-packages/pandas/io/parsers.py", line 454, in _read
    parser = TextFileReader(fp_or_buf, **kwds)
  File "/home/bradleynordin/.local/share/virtualenvs/GraphingData-0ufmG3h2/lib/python3.8/site-packages/pandas/io/parsers.py", line 948, in __init__
    self._make_engine(self.engine)
  File "/home/bradleynordin/.local/share/virtualenvs/GraphingData-0ufmG3h2/lib/python3.8/site-packages/pandas/io/parsers.py", line 1180, in _make_engine
    self._engine = CParserWrapper(self.f, **self.options)
  File "/home/bradleynordin/.local/share/virtualenvs/GraphingData-0ufmG3h2/lib/python3.8/site-packages/pandas/io/parsers.py", line 2010, in __init__
    self._reader = parsers.TextReader(src, **kwds)
  File "pandas/_libs/parsers.pyx", line 382, in pandas._libs.parsers.TextReader.__cinit__
  File "pandas/_libs/parsers.pyx", line 674, in pandas._libs.parsers.TextReader._setup_parser_source
FileNotFoundError: [Errno 2] No such file or directory: 'data0038.csv'
2020-12-07 19:28:11,634 - callbacks - ERROR - [Errno 2] No such file or directory: 'data0038.csv'
Traceback (most recent call last):
  File "/home/bradleynordin/Documents/GraphingData/callbacks.py", line 89, in updateData
    df = pd.read_csv(fileName)
  File "/home/bradleynordin/.local/share/virtualenvs/GraphingData-0ufmG3h2/lib/python3.8/site-packages/pandas/io/parsers.py", line 688, in read_csv
    return _read(filepath_or_buffer, kwds)
  File "/home/bradleynordin/.local/share/virtualenvs/GraphingData-0ufmG3h2/lib/python3.8/site-packages/pandas/io/parsers.py", line 454, in _read
    parser = TextFileReader(fp_or_buf, **kwds)
  File "/home/bradleynordin/.local/share/virtualenvs/GraphingData-0ufmG3h2/lib/python3.8/site-packages/pandas/io/parsers.py", line 948, in __init__
    self._make_engine(self.engine)
  File "/home/bradleynordin/.local/share/virtualenvs/GraphingData-0ufmG3h2/lib/python3.8/site-packages/pandas/io/parsers.py", line 1180, in _make_engine
    self._engine = CParserWrapper(self.f, **self.options)
  File "/home/bradleynordin/.local/share/virtualenvs/GraphingData-0ufmG3h2/lib/python3.8/site-packages/pandas/io/parsers.py", line 2010, in __init__
    self._reader = parsers.TextReader(src, **kwds)
  File "pandas/_libs/parsers.pyx", line 382, in pandas._libs.parsers.TextReader.__cinit__
  File "pandas/_libs/parsers.pyx", line 674, in pandas._libs.parsers.TextReader._setup_parser_source
FileNotFoundError: [Errno 2] No such file or directory: 'data0038.csv'
2020-12-07 19:28:20,134 - callbacks - DEBUG - measurement_time,FORT
2020-12-07 19:28:22,137 - callbacks - DEBUG - measurement_time,FORT6903691371001736192,-0.26732850074768066
2020-12-07 19:28:24,135 - callbacks - DEBUG - measurement_time,FORT6903691371001736192,-0.267328500747680666903691378745563136,-0.27359679341316223
2020-12-07 19:29:00,144 - callbacks - DEBUG - measurement_time,FORT6903691371001736192,-0.267328500747680666903691378745563136,-0.273596793413162236903691387318317056,-0.25479185581207275

2020-12-07 19:29:18,219 - callbacks - DEBUG - measurement_time,FORT6903691371001736192,-0.267328500747680666903691378745563136,-0.273596793413162236903691387318317056,-0.254791855812072756903691557403317248,-0.27359679341316223

2020-12-07 19:29:20,220 - callbacks - DEBUG - measurement_time,FORT6903691371001736192,-0.267328500747680666903691378745563136,-0.273596793413162236903691387318317056,-0.254791855812072756903691557403317248,-0.273596793413162236903691620165673984,-0.25792601704597473

2020-12-07 19:29:22,222 - callbacks - DEBUG - measurement_time,FORT6903691371001736192,-0.267328500747680666903691378745563136,-0.273596793413162236903691387318317056,-0.254791855812072756903691557403317248,-0.273596793413162236903691620165673984,-0.257926017045974736903691628695479296,-0.27359679341316223

2020-12-07 19:29:43,164 - callbacks - DEBUG - measurement_time,FORT

2020-12-07 19:29:45,164 - callbacks - DEBUG - measurement_time,FORT6903691727505497088,-0.2641943395137787

2020-12-07 19:29:47,173 - callbacks - DEBUG - measurement_time,FORT6903691727505497088,-0.26419433951377876903691735210668032,-0.27046263217926025

2020-12-07 19:29:49,254 - callbacks - DEBUG - measurement_time,FORT6903691727505497088,-0.26419433951377876903691735210668032,-0.270462632179260256903691744659596288,-0.26732850074768066

2020-12-07 19:29:51,166 - callbacks - DEBUG - measurement_time,FORT6903691727505497088,-0.26419433951377876903691735210668032,-0.270462632179260256903691744659596288,-0.267328500747680666903691753249530880,-0.27359679341316223

