2020-12-07 19:08:15,917 - callbacks - DEBUG - graphing 24hr
2020-12-07 19:09:08,128 - callbacks - DEBUG - graphing 24hr
2020-12-07 19:10:48,918 - callbacks - DEBUG - graphing 24hr
2020-12-07 19:11:40,494 - callbacks - DEBUG - graphing 24hr
2020-12-07 19:11:40,768 - callbacks - DEBUG - starting reads
2020-12-07 19:13:44,202 - callbacks - DEBUG - graphing 24hr
2020-12-07 19:13:44,507 - callbacks - DEBUG - starting reads
2020-12-07 19:14:37,470 - callbacks - ERROR - [Errno 2] No such file or directory: 'data0038.csv'
Traceback (most recent call last):
  File "/home/bradleynordin/Documents/GraphingData/callbacks.py", line 89, in updateData
    df = pd.read_csv(file)
  File "/home/bradleynordin/.local/share/virtualenvs/GraphingData-0ufmG3h2/lib/python3.8/site-packages/pandas/io/parsers.py", line 688, in read_csv
    return _read(filepath_or_buffer, kwds)
  File "/home/bradleynordin/.local/share/virtualenvs/GraphingData-0ufmG3h2/lib/python3.8/site-packages/pandas/io/parsers.py", line 454, in _read
    parser = TextFileReader(fp_or_buf, **kwds)
  File "/home/bradleynordin/.local/share/virtualenvs/GraphingData-0ufmG3h2/lib/python3.8/site-packages/pandas/io/parsers.py", line 948, in __init__
    self._make_engine(self.engine)
  File "/home/bradleynordin/.local/share/virtualenvs/GraphingData-0ufmG3h2/lib/python3.8/site-packages/pandas/io/parsers.py", line 1180, in _make_engine
    self._engine = CParserWrapper(self.f, **self.options)
  File "/home/bradleynordin/.local/share/virtualenvs/GraphingData-0ufmG3h2/lib/python3.8/site-packages/pandas/io/parsers.py", line 2010, in __init__
    self._reader = parsers.TextReader(src, **kwds)
  File "pandas/_libs/parsers.pyx", line 382, in pandas._libs.parsers.TextReader.__cinit__
  File "pandas/_libs/parsers.pyx", line 674, in pandas._libs.parsers.TextReader._setup_parser_source
FileNotFoundError: [Errno 2] No such file or directory: 'data0038.csv'
2020-12-07 19:14:48,604 - callbacks - DEBUG - done with read {'measurement_time': {'start': 6903656661983742976, 'stop': 6903656662847031296}, 'FORT': {'standard_deviation': 5.461094997579687, 'average': 4.040932141744548, 'min': -0.295536, 'max': 11.0877}}
2020-12-07 19:19:25,496 - callbacks - ERROR - write() argument must be str, not Index
Traceback (most recent call last):
  File "/home/bradleynordin/Documents/GraphingData/callbacks.py", line 92, in updateData
    f.write(df.columns)
TypeError: write() argument must be str, not Index
2020-12-07 19:19:33,822 - callbacks - ERROR - write() argument must be str, not Index
Traceback (most recent call last):
  File "/home/bradleynordin/Documents/GraphingData/callbacks.py", line 92, in updateData
    f.write(df.columns)
TypeError: write() argument must be str, not Index
2020-12-07 19:19:35,837 - callbacks - ERROR - write() argument must be str, not Index
Traceback (most recent call last):
  File "/home/bradleynordin/Documents/GraphingData/callbacks.py", line 92, in updateData
    f.write(df.columns)
TypeError: write() argument must be str, not Index
2020-12-07 19:19:37,824 - callbacks - ERROR - write() argument must be str, not Index
Traceback (most recent call last):
  File "/home/bradleynordin/Documents/GraphingData/callbacks.py", line 92, in updateData
    f.write(df.columns)
TypeError: write() argument must be str, not Index
2020-12-07 19:19:39,825 - callbacks - ERROR - write() argument must be str, not Index
Traceback (most recent call last):
  File "/home/bradleynordin/Documents/GraphingData/callbacks.py", line 92, in updateData
    f.write(df.columns)
TypeError: write() argument must be str, not Index
2020-12-07 19:19:41,822 - callbacks - ERROR - write() argument must be str, not Index
Traceback (most recent call last):
  File "/home/bradleynordin/Documents/GraphingData/callbacks.py", line 92, in updateData
    f.write(df.columns)
TypeError: write() argument must be str, not Index
2020-12-07 19:19:43,823 - callbacks - ERROR - write() argument must be str, not Index
Traceback (most recent call last):
  File "/home/bradleynordin/Documents/GraphingData/callbacks.py", line 92, in updateData
    f.write(df.columns)
TypeError: write() argument must be str, not Index
2020-12-07 19:19:45,823 - callbacks - ERROR - write() argument must be str, not Index
Traceback (most recent call last):
  File "/home/bradleynordin/Documents/GraphingData/callbacks.py", line 92, in updateData
    f.write(df.columns)
TypeError: write() argument must be str, not Index
2020-12-07 19:19:47,823 - callbacks - ERROR - write() argument must be str, not Index
Traceback (most recent call last):
  File "/home/bradleynordin/Documents/GraphingData/callbacks.py", line 92, in updateData
    f.write(df.columns)
TypeError: write() argument must be str, not Index
2020-12-07 19:25:49,930 - callbacks - ERROR - 'measurement_time'
Traceback (most recent call last):
  File "/home/bradleynordin/.local/share/virtualenvs/GraphingData-0ufmG3h2/lib/python3.8/site-packages/pandas/core/indexes/base.py", line 2898, in get_loc
    return self._engine.get_loc(casted_key)
  File "pandas/_libs/index.pyx", line 70, in pandas._libs.index.IndexEngine.get_loc
  File "pandas/_libs/index.pyx", line 101, in pandas._libs.index.IndexEngine.get_loc
  File "pandas/_libs/hashtable_class_helper.pxi", line 1675, in pandas._libs.hashtable.PyObjectHashTable.get_item
  File "pandas/_libs/hashtable_class_helper.pxi", line 1683, in pandas._libs.hashtable.PyObjectHashTable.get_item
KeyError: 'measurement_time'

The above exception was the direct cause of the following exception:

Traceback (most recent call last):
  File "/home/bradleynordin/Documents/GraphingData/callbacks.py", line 97, in updateData
    df['measurement_time'] = pd.to_datetime(df['measurement_time']/(2**32),unit='s')
  File "/home/bradleynordin/.local/share/virtualenvs/GraphingData-0ufmG3h2/lib/python3.8/site-packages/pandas/core/frame.py", line 2906, in __getitem__
    indexer = self.columns.get_loc(key)
  File "/home/bradleynordin/.local/share/virtualenvs/GraphingData-0ufmG3h2/lib/python3.8/site-packages/pandas/core/indexes/base.py", line 2900, in get_loc
    raise KeyError(key) from err
KeyError: 'measurement_time'
2020-12-07 19:26:04,423 - callbacks - ERROR - 'measurement_time'
Traceback (most recent call last):
  File "/home/bradleynordin/.local/share/virtualenvs/GraphingData-0ufmG3h2/lib/python3.8/site-packages/pandas/core/indexes/base.py", line 2898, in get_loc
    return self._engine.get_loc(casted_key)
  File "pandas/_libs/index.pyx", line 70, in pandas._libs.index.IndexEngine.get_loc
  File "pandas/_libs/index.pyx", line 101, in pandas._libs.index.IndexEngine.get_loc
  File "pandas/_libs/hashtable_class_helper.pxi", line 1675, in pandas._libs.hashtable.PyObjectHashTable.get_item
  File "pandas/_libs/hashtable_class_helper.pxi", line 1683, in pandas._libs.hashtable.PyObjectHashTable.get_item
KeyError: 'measurement_time'

The above exception was the direct cause of the following exception:

Traceback (most recent call last):
  File "/home/bradleynordin/Documents/GraphingData/callbacks.py", line 97, in updateData
    df['measurement_time'] = pd.to_datetime(df['measurement_time']/(2**32),unit='s')
  File "/home/bradleynordin/.local/share/virtualenvs/GraphingData-0ufmG3h2/lib/python3.8/site-packages/pandas/core/frame.py", line 2906, in __getitem__
    indexer = self.columns.get_loc(key)
  File "/home/bradleynordin/.local/share/virtualenvs/GraphingData-0ufmG3h2/lib/python3.8/site-packages/pandas/core/indexes/base.py", line 2900, in get_loc
    raise KeyError(key) from err
KeyError: 'measurement_time'
2020-12-07 19:26:06,424 - callbacks - ERROR - 'measurement_time'
Traceback (most recent call last):
  File "/home/bradleynordin/.local/share/virtualenvs/GraphingData-0ufmG3h2/lib/python3.8/site-packages/pandas/core/indexes/base.py", line 2898, in get_loc
    return self._engine.get_loc(casted_key)
  File "pandas/_libs/index.pyx", line 70, in pandas._libs.index.IndexEngine.get_loc
  File "pandas/_libs/index.pyx", line 101, in pandas._libs.index.IndexEngine.get_loc
  File "pandas/_libs/hashtable_class_helper.pxi", line 1675, in pandas._libs.hashtable.PyObjectHashTable.get_item
  File "pandas/_libs/hashtable_class_helper.pxi", line 1683, in pandas._libs.hashtable.PyObjectHashTable.get_item
KeyError: 'measurement_time'

The above exception was the direct cause of the following exception:

Traceback (most recent call last):
  File "/home/bradleynordin/Documents/GraphingData/callbacks.py", line 97, in updateData
    df['measurement_time'] = pd.to_datetime(df['measurement_time']/(2**32),unit='s')
  File "/home/bradleynordin/.local/share/virtualenvs/GraphingData-0ufmG3h2/lib/python3.8/site-packages/pandas/core/frame.py", line 2906, in __getitem__
    indexer = self.columns.get_loc(key)
  File "/home/bradleynordin/.local/share/virtualenvs/GraphingData-0ufmG3h2/lib/python3.8/site-packages/pandas/core/indexes/base.py", line 2900, in get_loc
    raise KeyError(key) from err
KeyError: 'measurement_time'
2020-12-07 19:26:08,443 - callbacks - ERROR - 'measurement_time'
Traceback (most recent call last):
  File "/home/bradleynordin/.local/share/virtualenvs/GraphingData-0ufmG3h2/lib/python3.8/site-packages/pandas/core/indexes/base.py", line 2898, in get_loc
    return self._engine.get_loc(casted_key)
  File "pandas/_libs/index.pyx", line 70, in pandas._libs.index.IndexEngine.get_loc
  File "pandas/_libs/index.pyx", line 101, in pandas._libs.index.IndexEngine.get_loc
  File "pandas/_libs/hashtable_class_helper.pxi", line 1675, in pandas._libs.hashtable.PyObjectHashTable.get_item
  File "pandas/_libs/hashtable_class_helper.pxi", line 1683, in pandas._libs.hashtable.PyObjectHashTable.get_item
KeyError: 'measurement_time'

The above exception was the direct cause of the following exception:

Traceback (most recent call last):
  File "/home/bradleynordin/Documents/GraphingData/callbacks.py", line 97, in updateData
    df['measurement_time'] = pd.to_datetime(df['measurement_time']/(2**32),unit='s')
  File "/home/bradleynordin/.local/share/virtualenvs/GraphingData-0ufmG3h2/lib/python3.8/site-packages/pandas/core/frame.py", line 2906, in __getitem__
    indexer = self.columns.get_loc(key)
  File "/home/bradleynordin/.local/share/virtualenvs/GraphingData-0ufmG3h2/lib/python3.8/site-packages/pandas/core/indexes/base.py", line 2900, in get_loc
    raise KeyError(key) from err
KeyError: 'measurement_time'
2020-12-07 19:26:10,423 - callbacks - ERROR - 'measurement_time'
Traceback (most recent call last):
  File "/home/bradleynordin/.local/share/virtualenvs/GraphingData-0ufmG3h2/lib/python3.8/site-packages/pandas/core/indexes/base.py", line 2898, in get_loc
    return self._engine.get_loc(casted_key)
  File "pandas/_libs/index.pyx", line 70, in pandas._libs.index.IndexEngine.get_loc
  File "pandas/_libs/index.pyx", line 101, in pandas._libs.index.IndexEngine.get_loc
  File "pandas/_libs/hashtable_class_helper.pxi", line 1675, in pandas._libs.hashtable.PyObjectHashTable.get_item
  File "pandas/_libs/hashtable_class_helper.pxi", line 1683, in pandas._libs.hashtable.PyObjectHashTable.get_item
KeyError: 'measurement_time'

The above exception was the direct cause of the following exception:

Traceback (most recent call last):
  File "/home/bradleynordin/Documents/GraphingData/callbacks.py", line 97, in updateData
    df['measurement_time'] = pd.to_datetime(df['measurement_time']/(2**32),unit='s')
  File "/home/bradleynordin/.local/share/virtualenvs/GraphingData-0ufmG3h2/lib/python3.8/site-packages/pandas/core/frame.py", line 2906, in __getitem__
    indexer = self.columns.get_loc(key)
  File "/home/bradleynordin/.local/share/virtualenvs/GraphingData-0ufmG3h2/lib/python3.8/site-packages/pandas/core/indexes/base.py", line 2900, in get_loc
    raise KeyError(key) from err
KeyError: 'measurement_time'
2020-12-07 19:26:12,429 - callbacks - ERROR - 'measurement_time'
Traceback (most recent call last):
  File "/home/bradleynordin/.local/share/virtualenvs/GraphingData-0ufmG3h2/lib/python3.8/site-packages/pandas/core/indexes/base.py", line 2898, in get_loc
    return self._engine.get_loc(casted_key)
  File "pandas/_libs/index.pyx", line 70, in pandas._libs.index.IndexEngine.get_loc
  File "pandas/_libs/index.pyx", line 101, in pandas._libs.index.IndexEngine.get_loc
  File "pandas/_libs/hashtable_class_helper.pxi", line 1675, in pandas._libs.hashtable.PyObjectHashTable.get_item
  File "pandas/_libs/hashtable_class_helper.pxi", line 1683, in pandas._libs.hashtable.PyObjectHashTable.get_item
KeyError: 'measurement_time'

The above exception was the direct cause of the following exception:

Traceback (most recent call last):
  File "/home/bradleynordin/Documents/GraphingData/callbacks.py", line 97, in updateData
    df['measurement_time'] = pd.to_datetime(df['measurement_time']/(2**32),unit='s')
  File "/home/bradleynordin/.local/share/virtualenvs/GraphingData-0ufmG3h2/lib/python3.8/site-packages/pandas/core/frame.py", line 2906, in __getitem__
    indexer = self.columns.get_loc(key)
  File "/home/bradleynordin/.local/share/virtualenvs/GraphingData-0ufmG3h2/lib/python3.8/site-packages/pandas/core/indexes/base.py", line 2900, in get_loc
    raise KeyError(key) from err
KeyError: 'measurement_time'
2020-12-07 19:26:14,445 - callbacks - ERROR - 'measurement_time'
Traceback (most recent call last):
  File "/home/bradleynordin/.local/share/virtualenvs/GraphingData-0ufmG3h2/lib/python3.8/site-packages/pandas/core/indexes/base.py", line 2898, in get_loc
    return self._engine.get_loc(casted_key)
  File "pandas/_libs/index.pyx", line 70, in pandas._libs.index.IndexEngine.get_loc
  File "pandas/_libs/index.pyx", line 101, in pandas._libs.index.IndexEngine.get_loc
  File "pandas/_libs/hashtable_class_helper.pxi", line 1675, in pandas._libs.hashtable.PyObjectHashTable.get_item
  File "pandas/_libs/hashtable_class_helper.pxi", line 1683, in pandas._libs.hashtable.PyObjectHashTable.get_item
KeyError: 'measurement_time'

The above exception was the direct cause of the following exception:

Traceback (most recent call last):
  File "/home/bradleynordin/Documents/GraphingData/callbacks.py", line 97, in updateData
    df['measurement_time'] = pd.to_datetime(df['measurement_time']/(2**32),unit='s')
  File "/home/bradleynordin/.local/share/virtualenvs/GraphingData-0ufmG3h2/lib/python3.8/site-packages/pandas/core/frame.py", line 2906, in __getitem__
    indexer = self.columns.get_loc(key)
  File "/home/bradleynordin/.local/share/virtualenvs/GraphingData-0ufmG3h2/lib/python3.8/site-packages/pandas/core/indexes/base.py", line 2900, in get_loc
    raise KeyError(key) from err
KeyError: 'measurement_time'
2020-12-07 19:26:16,431 - callbacks - ERROR - 'measurement_time'
Traceback (most recent call last):
  File "/home/bradleynordin/.local/share/virtualenvs/GraphingData-0ufmG3h2/lib/python3.8/site-packages/pandas/core/indexes/base.py", line 2898, in get_loc
    return self._engine.get_loc(casted_key)
  File "pandas/_libs/index.pyx", line 70, in pandas._libs.index.IndexEngine.get_loc
  File "pandas/_libs/index.pyx", line 101, in pandas._libs.index.IndexEngine.get_loc
  File "pandas/_libs/hashtable_class_helper.pxi", line 1675, in pandas._libs.hashtable.PyObjectHashTable.get_item
  File "pandas/_libs/hashtable_class_helper.pxi", line 1683, in pandas._libs.hashtable.PyObjectHashTable.get_item
KeyError: 'measurement_time'

The above exception was the direct cause of the following exception:

Traceback (most recent call last):
  File "/home/bradleynordin/Documents/GraphingData/callbacks.py", line 97, in updateData
    df['measurement_time'] = pd.to_datetime(df['measurement_time']/(2**32),unit='s')
  File "/home/bradleynordin/.local/share/virtualenvs/GraphingData-0ufmG3h2/lib/python3.8/site-packages/pandas/core/frame.py", line 2906, in __getitem__
    indexer = self.columns.get_loc(key)
  File "/home/bradleynordin/.local/share/virtualenvs/GraphingData-0ufmG3h2/lib/python3.8/site-packages/pandas/core/indexes/base.py", line 2900, in get_loc
    raise KeyError(key) from err
KeyError: 'measurement_time'
2020-12-07 19:26:18,442 - callbacks - ERROR - 'measurement_time'
Traceback (most recent call last):
  File "/home/bradleynordin/.local/share/virtualenvs/GraphingData-0ufmG3h2/lib/python3.8/site-packages/pandas/core/indexes/base.py", line 2898, in get_loc
    return self._engine.get_loc(casted_key)
  File "pandas/_libs/index.pyx", line 70, in pandas._libs.index.IndexEngine.get_loc
  File "pandas/_libs/index.pyx", line 101, in pandas._libs.index.IndexEngine.get_loc
  File "pandas/_libs/hashtable_class_helper.pxi", line 1675, in pandas._libs.hashtable.PyObjectHashTable.get_item
  File "pandas/_libs/hashtable_class_helper.pxi", line 1683, in pandas._libs.hashtable.PyObjectHashTable.get_item
KeyError: 'measurement_time'

The above exception was the direct cause of the following exception:

Traceback (most recent call last):
  File "/home/bradleynordin/Documents/GraphingData/callbacks.py", line 97, in updateData
    df['measurement_time'] = pd.to_datetime(df['measurement_time']/(2**32),unit='s')
  File "/home/bradleynordin/.local/share/virtualenvs/GraphingData-0ufmG3h2/lib/python3.8/site-packages/pandas/core/frame.py", line 2906, in __getitem__
    indexer = self.columns.get_loc(key)
  File "/home/bradleynordin/.local/share/virtualenvs/GraphingData-0ufmG3h2/lib/python3.8/site-packages/pandas/core/indexes/base.py", line 2900, in get_loc
    raise KeyError(key) from err
KeyError: 'measurement_time'
2020-12-07 19:26:20,432 - callbacks - ERROR - 'measurement_time'
Traceback (most recent call last):
  File "/home/bradleynordin/.local/share/virtualenvs/GraphingData-0ufmG3h2/lib/python3.8/site-packages/pandas/core/indexes/base.py", line 2898, in get_loc
    return self._engine.get_loc(casted_key)
  File "pandas/_libs/index.pyx", line 70, in pandas._libs.index.IndexEngine.get_loc
  File "pandas/_libs/index.pyx", line 101, in pandas._libs.index.IndexEngine.get_loc
  File "pandas/_libs/hashtable_class_helper.pxi", line 1675, in pandas._libs.hashtable.PyObjectHashTable.get_item
  File "pandas/_libs/hashtable_class_helper.pxi", line 1683, in pandas._libs.hashtable.PyObjectHashTable.get_item
KeyError: 'measurement_time'

The above exception was the direct cause of the following exception:

Traceback (most recent call last):
  File "/home/bradleynordin/Documents/GraphingData/callbacks.py", line 97, in updateData
    df['measurement_time'] = pd.to_datetime(df['measurement_time']/(2**32),unit='s')
  File "/home/bradleynordin/.local/share/virtualenvs/GraphingData-0ufmG3h2/lib/python3.8/site-packages/pandas/core/frame.py", line 2906, in __getitem__
    indexer = self.columns.get_loc(key)
  File "/home/bradleynordin/.local/share/virtualenvs/GraphingData-0ufmG3h2/lib/python3.8/site-packages/pandas/core/indexes/base.py", line 2900, in get_loc
    raise KeyError(key) from err
KeyError: 'measurement_time'
2020-12-07 19:26:22,454 - callbacks - ERROR - 'measurement_time'
Traceback (most recent call last):
  File "/home/bradleynordin/.local/share/virtualenvs/GraphingData-0ufmG3h2/lib/python3.8/site-packages/pandas/core/indexes/base.py", line 2898, in get_loc
    return self._engine.get_loc(casted_key)
  File "pandas/_libs/index.pyx", line 70, in pandas._libs.index.IndexEngine.get_loc
  File "pandas/_libs/index.pyx", line 101, in pandas._libs.index.IndexEngine.get_loc
  File "pandas/_libs/hashtable_class_helper.pxi", line 1675, in pandas._libs.hashtable.PyObjectHashTable.get_item
  File "pandas/_libs/hashtable_class_helper.pxi", line 1683, in pandas._libs.hashtable.PyObjectHashTable.get_item
KeyError: 'measurement_time'

The above exception was the direct cause of the following exception:

Traceback (most recent call last):
  File "/home/bradleynordin/Documents/GraphingData/callbacks.py", line 97, in updateData
    df['measurement_time'] = pd.to_datetime(df['measurement_time']/(2**32),unit='s')
  File "/home/bradleynordin/.local/share/virtualenvs/GraphingData-0ufmG3h2/lib/python3.8/site-packages/pandas/core/frame.py", line 2906, in __getitem__
    indexer = self.columns.get_loc(key)
  File "/home/bradleynordin/.local/share/virtualenvs/GraphingData-0ufmG3h2/lib/python3.8/site-packages/pandas/core/indexes/base.py", line 2900, in get_loc
    raise KeyError(key) from err
KeyError: 'measurement_time'
2020-12-07 19:26:24,429 - callbacks - ERROR - 'measurement_time'
Traceback (most recent call last):
  File "/home/bradleynordin/.local/share/virtualenvs/GraphingData-0ufmG3h2/lib/python3.8/site-packages/pandas/core/indexes/base.py", line 2898, in get_loc
    return self._engine.get_loc(casted_key)
  File "pandas/_libs/index.pyx", line 70, in pandas._libs.index.IndexEngine.get_loc
  File "pandas/_libs/index.pyx", line 101, in pandas._libs.index.IndexEngine.get_loc
  File "pandas/_libs/hashtable_class_helper.pxi", line 1675, in pandas._libs.hashtable.PyObjectHashTable.get_item
  File "pandas/_libs/hashtable_class_helper.pxi", line 1683, in pandas._libs.hashtable.PyObjectHashTable.get_item
KeyError: 'measurement_time'

The above exception was the direct cause of the following exception:

Traceback (most recent call last):
  File "/home/bradleynordin/Documents/GraphingData/callbacks.py", line 97, in updateData
    df['measurement_time'] = pd.to_datetime(df['measurement_time']/(2**32),unit='s')
  File "/home/bradleynordin/.local/share/virtualenvs/GraphingData-0ufmG3h2/lib/python3.8/site-packages/pandas/core/frame.py", line 2906, in __getitem__
    indexer = self.columns.get_loc(key)
  File "/home/bradleynordin/.local/share/virtualenvs/GraphingData-0ufmG3h2/lib/python3.8/site-packages/pandas/core/indexes/base.py", line 2900, in get_loc
    raise KeyError(key) from err
KeyError: 'measurement_time'
2020-12-07 19:27:32,453 - callbacks - DEBUG - 6903689170217544704,-0.26419433951377876903690771415711744,-0.273596793413162236903690787801012224,-0.267328500747680666903690796326522880,-0.270462632179260256903690804916457472,-0.27673095464706426903690813506392064,-0.267328500747680666903690822096326656,-0.27986511588096626903690830931074048,-0.273596793413162236903690839276195840,-0.27986511588096626903690847861834752,-0.27673095464706426903690856464654336,-0.270462632179260256903690864191300608,-0.267328500747680666903690873790553088,-0.2641943395137787
2020-12-07 19:27:32,454 - callbacks - ERROR - 'measurement_time'
Traceback (most recent call last):
  File "/home/bradleynordin/.local/share/virtualenvs/GraphingData-0ufmG3h2/lib/python3.8/site-packages/pandas/core/indexes/base.py", line 2898, in get_loc
    return self._engine.get_loc(casted_key)
  File "pandas/_libs/index.pyx", line 70, in pandas._libs.index.IndexEngine.get_loc
  File "pandas/_libs/index.pyx", line 101, in pandas._libs.index.IndexEngine.get_loc
  File "pandas/_libs/hashtable_class_helper.pxi", line 1675, in pandas._libs.hashtable.PyObjectHashTable.get_item
  File "pandas/_libs/hashtable_class_helper.pxi", line 1683, in pandas._libs.hashtable.PyObjectHashTable.get_item
KeyError: 'measurement_time'

The above exception was the direct cause of the following exception:

Traceback (most recent call last):
  File "/home/bradleynordin/Documents/GraphingData/callbacks.py", line 99, in updateData
    df['measurement_time'] = pd.to_datetime(df['measurement_time']/(2**32),unit='s')
  File "/home/bradleynordin/.local/share/virtualenvs/GraphingData-0ufmG3h2/lib/python3.8/site-packages/pandas/core/frame.py", line 2906, in __getitem__
    indexer = self.columns.get_loc(key)
  File "/home/bradleynordin/.local/share/virtualenvs/GraphingData-0ufmG3h2/lib/python3.8/site-packages/pandas/core/indexes/base.py", line 2900, in get_loc
    raise KeyError(key) from err
KeyError: 'measurement_time'
2020-12-07 19:27:39,603 - callbacks - DEBUG - 6903689170217544704,-0.26419433951377876903690771415711744,-0.273596793413162236903690787801012224,-0.267328500747680666903690796326522880,-0.270462632179260256903690804916457472,-0.27673095464706426903690813506392064,-0.267328500747680666903690822096326656,-0.27986511588096626903690830931074048,-0.273596793413162236903690839276195840,-0.27986511588096626903690847861834752,-0.27673095464706426903690856464654336,-0.270462632179260256903690864191300608,-0.267328500747680666903690873790553088,-0.26419433951377876903691182882168832,-0.26732850074768066
2020-12-07 19:27:39,604 - callbacks - ERROR - 'measurement_time'
Traceback (most recent call last):
  File "/home/bradleynordin/.local/share/virtualenvs/GraphingData-0ufmG3h2/lib/python3.8/site-packages/pandas/core/indexes/base.py", line 2898, in get_loc
    return self._engine.get_loc(casted_key)
  File "pandas/_libs/index.pyx", line 70, in pandas._libs.index.IndexEngine.get_loc
  File "pandas/_libs/index.pyx", line 101, in pandas._libs.index.IndexEngine.get_loc
  File "pandas/_libs/hashtable_class_helper.pxi", line 1675, in pandas._libs.hashtable.PyObjectHashTable.get_item
  File "pandas/_libs/hashtable_class_helper.pxi", line 1683, in pandas._libs.hashtable.PyObjectHashTable.get_item
KeyError: 'measurement_time'

The above exception was the direct cause of the following exception:

Traceback (most recent call last):
  File "/home/bradleynordin/Documents/GraphingData/callbacks.py", line 99, in updateData
    df['measurement_time'] = pd.to_datetime(df['measurement_time']/(2**32),unit='s')
  File "/home/bradleynordin/.local/share/virtualenvs/GraphingData-0ufmG3h2/lib/python3.8/site-packages/pandas/core/frame.py", line 2906, in __getitem__
    indexer = self.columns.get_loc(key)
  File "/home/bradleynordin/.local/share/virtualenvs/GraphingData-0ufmG3h2/lib/python3.8/site-packages/pandas/core/indexes/base.py", line 2900, in get_loc
    raise KeyError(key) from err
KeyError: 'measurement_time'
2020-12-07 19:27:41,605 - callbacks - DEBUG - 6903689170217544704,-0.26419433951377876903690771415711744,-0.273596793413162236903690787801012224,-0.267328500747680666903690796326522880,-0.270462632179260256903690804916457472,-0.27673095464706426903690813506392064,-0.267328500747680666903690822096326656,-0.27986511588096626903690830931074048,-0.273596793413162236903690839276195840,-0.27986511588096626903690847861834752,-0.27673095464706426903690856464654336,-0.270462632179260256903690864191300608,-0.267328500747680666903690873790553088,-0.26419433951377876903691182882168832,-0.267328500747680666903691195908804608,-0.27046263217926025
2020-12-07 19:27:41,605 - callbacks - ERROR - 'measurement_time'
Traceback (most recent call last):
  File "/home/bradleynordin/.local/share/virtualenvs/GraphingData-0ufmG3h2/lib/python3.8/site-packages/pandas/core/indexes/base.py", line 2898, in get_loc
    return self._engine.get_loc(casted_key)
  File "pandas/_libs/index.pyx", line 70, in pandas._libs.index.IndexEngine.get_loc
  File "pandas/_libs/index.pyx", line 101, in pandas._libs.index.IndexEngine.get_loc
  File "pandas/_libs/hashtable_class_helper.pxi", line 1675, in pandas._libs.hashtable.PyObjectHashTable.get_item
  File "pandas/_libs/hashtable_class_helper.pxi", line 1683, in pandas._libs.hashtable.PyObjectHashTable.get_item
KeyError: 'measurement_time'

The above exception was the direct cause of the following exception:

Traceback (most recent call last):
  File "/home/bradleynordin/Documents/GraphingData/callbacks.py", line 99, in updateData
    df['measurement_time'] = pd.to_datetime(df['measurement_time']/(2**32),unit='s')
  File "/home/bradleynordin/.local/share/virtualenvs/GraphingData-0ufmG3h2/lib/python3.8/site-packages/pandas/core/frame.py", line 2906, in __getitem__
    indexer = self.columns.get_loc(key)
  File "/home/bradleynordin/.local/share/virtualenvs/GraphingData-0ufmG3h2/lib/python3.8/site-packages/pandas/core/indexes/base.py", line 2900, in get_loc
    raise KeyError(key) from err
KeyError: 'measurement_time'
2020-12-07 19:27:43,606 - callbacks - DEBUG - 6903689170217544704,-0.26419433951377876903690771415711744,-0.273596793413162236903690787801012224,-0.267328500747680666903690796326522880,-0.270462632179260256903690804916457472,-0.27673095464706426903690813506392064,-0.267328500747680666903690822096326656,-0.27986511588096626903690830931074048,-0.273596793413162236903690839276195840,-0.27986511588096626903690847861834752,-0.27673095464706426903690856464654336,-0.270462632179260256903690864191300608,-0.267328500747680666903690873790553088,-0.26419433951377876903691182882168832,-0.267328500747680666903691195908804608,-0.270462632179260256903691205211704320,-0.2641943395137787
2020-12-07 19:27:43,606 - callbacks - ERROR - 'measurement_time'
Traceback (most recent call last):
  File "/home/bradleynordin/.local/share/virtualenvs/GraphingData-0ufmG3h2/lib/python3.8/site-packages/pandas/core/indexes/base.py", line 2898, in get_loc
    return self._engine.get_loc(casted_key)
  File "pandas/_libs/index.pyx", line 70, in pandas._libs.index.IndexEngine.get_loc
  File "pandas/_libs/index.pyx", line 101, in pandas._libs.index.IndexEngine.get_loc
  File "pandas/_libs/hashtable_class_helper.pxi", line 1675, in pandas._libs.hashtable.PyObjectHashTable.get_item
  File "pandas/_libs/hashtable_class_helper.pxi", line 1683, in pandas._libs.hashtable.PyObjectHashTable.get_item
KeyError: 'measurement_time'

The above exception was the direct cause of the following exception:

Traceback (most recent call last):
  File "/home/bradleynordin/Documents/GraphingData/callbacks.py", line 99, in updateData
    df['measurement_time'] = pd.to_datetime(df['measurement_time']/(2**32),unit='s')
  File "/home/bradleynordin/.local/share/virtualenvs/GraphingData-0ufmG3h2/lib/python3.8/site-packages/pandas/core/frame.py", line 2906, in __getitem__
    indexer = self.columns.get_loc(key)
  File "/home/bradleynordin/.local/share/virtualenvs/GraphingData-0ufmG3h2/lib/python3.8/site-packages/pandas/core/indexes/base.py", line 2900, in get_loc
    raise KeyError(key) from err
KeyError: 'measurement_time'
2020-12-07 19:28:10,188 - callbacks - ERROR - [Errno 2] No such file or directory: 'data0038.csv'
Traceback (most recent call last):
  File "/home/bradleynordin/Documents/GraphingData/callbacks.py", line 89, in updateData
    df = pd.read_csv(fileName)
  File "/home/bradleynordin/.local/share/virtualenvs/GraphingData-0ufmG3h2/lib/python3.8/site-packages/pandas/io/parsers.py", line 688, in read_csv
    return _read(filepath_or_buffer, kwds)
  File "/home/bradleynordin/.local/share/virtualenvs/GraphingData-0ufmG3h2/lib/python3.8/site-packages/pandas/io/parsers.py", line 454, in _read
    parser = TextFileReader(fp_or_buf, **kwds)
  File "/home/bradleynordin/.local/share/virtualenvs/GraphingData-0ufmG3h2/lib/python3.8/site-packages/pandas/io/parsers.py", line 948, in __init__
    self._make_engine(self.engine)
  File "/home/bradleynordin/.local/share/virtualenvs/GraphingData-0ufmG3h2/lib/python3.8/site-packages/pandas/io/parsers.py", line 1180, in _make_engine
    self._engine = CParserWrapper(self.f, **self.options)
  File "/home/bradleynordin/.local/share/virtualenvs/GraphingData-0ufmG3h2/lib/python3.8/site-packages/pandas/io/parsers.py", line 2010, in __init__
    self._reader = parsers.TextReader(src, **kwds)
  File "pandas/_libs/parsers.pyx", line 382, in pandas._libs.parsers.TextReader.__cinit__
  File "pandas/_libs/parsers.pyx", line 674, in pandas._libs.parsers.TextReader._setup_parser_source
FileNotFoundError: [Errno 2] No such file or directory: 'data0038.csv'
2020-12-07 19:28:11,634 - callbacks - ERROR - [Errno 2] No such file or directory: 'data0038.csv'
Traceback (most recent call last):
  File "/home/bradleynordin/Documents/GraphingData/callbacks.py", line 89, in updateData
    df = pd.read_csv(fileName)
  File "/home/bradleynordin/.local/share/virtualenvs/GraphingData-0ufmG3h2/lib/python3.8/site-packages/pandas/io/parsers.py", line 688, in read_csv
    return _read(filepath_or_buffer, kwds)
  File "/home/bradleynordin/.local/share/virtualenvs/GraphingData-0ufmG3h2/lib/python3.8/site-packages/pandas/io/parsers.py", line 454, in _read
    parser = TextFileReader(fp_or_buf, **kwds)
  File "/home/bradleynordin/.local/share/virtualenvs/GraphingData-0ufmG3h2/lib/python3.8/site-packages/pandas/io/parsers.py", line 948, in __init__
    self._make_engine(self.engine)
  File "/home/bradleynordin/.local/share/virtualenvs/GraphingData-0ufmG3h2/lib/python3.8/site-packages/pandas/io/parsers.py", line 1180, in _make_engine
    self._engine = CParserWrapper(self.f, **self.options)
  File "/home/bradleynordin/.local/share/virtualenvs/GraphingData-0ufmG3h2/lib/python3.8/site-packages/pandas/io/parsers.py", line 2010, in __init__
    self._reader = parsers.TextReader(src, **kwds)
  File "pandas/_libs/parsers.pyx", line 382, in pandas._libs.parsers.TextReader.__cinit__
  File "pandas/_libs/parsers.pyx", line 674, in pandas._libs.parsers.TextReader._setup_parser_source
FileNotFoundError: [Errno 2] No such file or directory: 'data0038.csv'
2020-12-07 19:28:20,134 - callbacks - DEBUG - measurement_time,FORT
2020-12-07 19:28:22,137 - callbacks - DEBUG - measurement_time,FORT6903691371001736192,-0.26732850074768066
2020-12-07 19:28:24,135 - callbacks - DEBUG - measurement_time,FORT6903691371001736192,-0.267328500747680666903691378745563136,-0.27359679341316223
2020-12-07 19:29:00,144 - callbacks - DEBUG - measurement_time,FORT6903691371001736192,-0.267328500747680666903691378745563136,-0.273596793413162236903691387318317056,-0.25479185581207275

2020-12-07 19:29:18,219 - callbacks - DEBUG - measurement_time,FORT6903691371001736192,-0.267328500747680666903691378745563136,-0.273596793413162236903691387318317056,-0.254791855812072756903691557403317248,-0.27359679341316223

2020-12-07 19:29:20,220 - callbacks - DEBUG - measurement_time,FORT6903691371001736192,-0.267328500747680666903691378745563136,-0.273596793413162236903691387318317056,-0.254791855812072756903691557403317248,-0.273596793413162236903691620165673984,-0.25792601704597473

2020-12-07 19:29:22,222 - callbacks - DEBUG - measurement_time,FORT6903691371001736192,-0.267328500747680666903691378745563136,-0.273596793413162236903691387318317056,-0.254791855812072756903691557403317248,-0.273596793413162236903691620165673984,-0.257926017045974736903691628695479296,-0.27359679341316223

2020-12-07 19:29:43,164 - callbacks - DEBUG - measurement_time,FORT

2020-12-07 19:29:45,164 - callbacks - DEBUG - measurement_time,FORT6903691727505497088,-0.2641943395137787

2020-12-07 19:29:47,173 - callbacks - DEBUG - measurement_time,FORT6903691727505497088,-0.26419433951377876903691735210668032,-0.27046263217926025

2020-12-07 19:29:49,254 - callbacks - DEBUG - measurement_time,FORT6903691727505497088,-0.26419433951377876903691735210668032,-0.270462632179260256903691744659596288,-0.26732850074768066

2020-12-07 19:29:51,166 - callbacks - DEBUG - measurement_time,FORT6903691727505497088,-0.26419433951377876903691735210668032,-0.270462632179260256903691744659596288,-0.267328500747680666903691753249530880,-0.27359679341316223

2020-12-07 19:38:34,724 - callbacks - ERROR - [Errno 2] No such file or directory: 'data0038.csv'
Traceback (most recent call last):
  File "/home/bradleynordin/Documents/GraphingData/callbacks.py", line 89, in updateData
    df = pd.read_csv(fileName)
  File "/home/bradleynordin/.local/share/virtualenvs/GraphingData-0ufmG3h2/lib/python3.8/site-packages/pandas/io/parsers.py", line 688, in read_csv
    return _read(filepath_or_buffer, kwds)
  File "/home/bradleynordin/.local/share/virtualenvs/GraphingData-0ufmG3h2/lib/python3.8/site-packages/pandas/io/parsers.py", line 454, in _read
    parser = TextFileReader(fp_or_buf, **kwds)
  File "/home/bradleynordin/.local/share/virtualenvs/GraphingData-0ufmG3h2/lib/python3.8/site-packages/pandas/io/parsers.py", line 948, in __init__
    self._make_engine(self.engine)
  File "/home/bradleynordin/.local/share/virtualenvs/GraphingData-0ufmG3h2/lib/python3.8/site-packages/pandas/io/parsers.py", line 1180, in _make_engine
    self._engine = CParserWrapper(self.f, **self.options)
  File "/home/bradleynordin/.local/share/virtualenvs/GraphingData-0ufmG3h2/lib/python3.8/site-packages/pandas/io/parsers.py", line 2010, in __init__
    self._reader = parsers.TextReader(src, **kwds)
  File "pandas/_libs/parsers.pyx", line 382, in pandas._libs.parsers.TextReader.__cinit__
  File "pandas/_libs/parsers.pyx", line 674, in pandas._libs.parsers.TextReader._setup_parser_source
FileNotFoundError: [Errno 2] No such file or directory: 'data0038.csv'
2020-12-07 19:38:56,115 - callbacks - DEBUG - graphing 24hr
2020-12-07 19:38:56,412 - callbacks - DEBUG - starting reads
2020-12-07 19:38:58,390 - callbacks - DEBUG - done with read {'measurement_time': {'start': 6903663155252740096, 'stop': 6903663156167568384}, 'FORT': {'standard_deviation': 2.956286658540307, 'average': 0.5672454716666666, 'min': -0.295536, 'max': 11.072}}
2020-12-07 19:39:00,227 - callbacks - DEBUG - done with read {'measurement_time': {'start': 6903647693520798720, 'stop': 6903647694379792384}, 'FORT': {'standard_deviation': 2.5243819037017294, 'average': 10.336979211080179, 'min': -0.351951, 'max': 11.0877}}
2020-12-07 19:39:01,987 - callbacks - DEBUG - done with read {'measurement_time': {'start': 6903632232364382208, 'stop': 6903632233090232320}, 'FORT': {'standard_deviation': 0.27585023640385326, 'average': -0.2640176453494833, 'min': -0.355085, 'max': 12.9024}}
2020-12-07 19:39:04,165 - callbacks - DEBUG - done with read {'measurement_time': {'start': 6903616770104159232, 'stop': 6903616770958858240}, 'FORT': {'standard_deviation': 3.2772076000047026, 'average': 18.273437162073563, 'min': -0.292402, 'max': 19.0829}}
2020-12-07 19:39:06,493 - callbacks - DEBUG - done with read {'measurement_time': {'start': 6903601308488181760, 'stop': 6903601309304225792}, 'FORT': {'standard_deviation': 0.23528423786130742, 'average': 19.038081643424636, 'min': 18.5815, 'max': 19.7537}}
2020-12-07 19:39:08,708 - callbacks - DEBUG - done with read {'measurement_time': {'start': 6903585846270909440, 'stop': 6903585847220097024}, 'FORT': {'standard_deviation': 0.19006503099960206, 'average': 19.34123813545197, 'min': 18.9356, 'max': 19.9166}}
2020-12-07 19:39:11,652 - callbacks - DEBUG - done with read {'measurement_time': {'start': 6903570384139535360, 'stop': 6903570384994233344}, 'FORT': {'standard_deviation': 0.09414594570357666, 'average': 19.048572287414494, 'min': 18.7006, 'max': 19.3713}}
2020-12-07 19:39:14,540 - callbacks - DEBUG - done with read {'measurement_time': {'start': 6903554922068291584, 'stop': 6903554922927284224}, 'FORT': {'standard_deviation': 0.06218009547440402, 'average': 18.91435921871527, 'min': 18.6692, 'max': 19.1832}}
2020-12-07 19:39:17,342 - callbacks - DEBUG - done with read {'measurement_time': {'start': 6903539460538212352, 'stop': 6903539461307012096}, 'FORT': {'standard_deviation': 0.06330539012071876, 'average': 18.928047023842606, 'min': 18.6316, 'max': 19.1394}}
2020-12-07 19:39:20,125 - callbacks - DEBUG - done with read {'measurement_time': {'start': 6903523998479853568, 'stop': 6903523999244357632}, 'FORT': {'standard_deviation': 0.06401059097254402, 'average': 18.971607416055146, 'min': 18.7131, 'max': 19.1989}}
2020-12-07 19:39:23,031 - callbacks - DEBUG - done with read {'measurement_time': {'start': 6903508537284783104, 'stop': 6903508538040696832}, 'FORT': {'standard_deviation': 0.06413764892303678, 'average': 19.01219052619881, 'min': 18.7162, 'max': 19.2585}}
2020-12-07 19:39:26,095 - callbacks - DEBUG - done with read {'measurement_time': {'start': 6903493074659487744, 'stop': 6903493075514186752}, 'FORT': {'standard_deviation': 0.06323752956480932, 'average': 19.032346501417216, 'min': 18.7413, 'max': 19.271}}
2020-12-07 19:39:29,107 - callbacks - DEBUG - done with read {'measurement_time': {'start': 6903477612957611008, 'stop': 6903477613872439296}, 'FORT': {'standard_deviation': 0.06330730710689705, 'average': 19.023930760682337, 'min': 18.7413, 'max': 19.3588}}
2020-12-07 19:39:31,111 - callbacks - DEBUG - done with read {'measurement_time': {'start': 6903468032685164544, 'stop': 6903468121526562816}, 'FORT': {'standard_deviation': 0.06438977237283676, 'average': 19.035549537708484, 'min': 18.7789, 'max': 19.3149}}
2020-12-07 19:39:33,747 - callbacks - DEBUG - done with read {'measurement_time': {'start': 6903446688995511296, 'stop': 6903446689858799616}, 'FORT': {'standard_deviation': 0.062358129774657704, 'average': 19.074969496055804, 'min': 18.8479, 'max': 19.3525}}
2020-12-07 19:39:36,458 - callbacks - DEBUG - done with read {'measurement_time': {'start': 6903431227856274432, 'stop': 6903431228625074176}, 'FORT': {'standard_deviation': 0.07205735952163461, 'average': 19.097762951439048, 'min': 18.8385, 'max': 19.365}}
2020-12-07 19:39:39,511 - callbacks - DEBUG - done with read {'measurement_time': {'start': 6903415765230980096, 'stop': 6903415766218822656}, 'FORT': {'standard_deviation': 0.10552668651799908, 'average': 19.3320875854404, 'min': 18.9983, 'max': 19.7066}}
2020-12-07 19:39:42,336 - callbacks - DEBUG - done with read {'measurement_time': {'start': 6903400303593527296, 'stop': 6903400304495470592}, 'FORT': {'standard_deviation': 0.13104422099883725, 'average': 19.621431892432494, 'min': 19.2208, 'max': 20.0545}}
2020-12-07 19:39:45,078 - callbacks - DEBUG - done with read {'measurement_time': {'start': 6903384841556642816, 'stop': 6903384842454291456}, 'FORT': {'standard_deviation': 0.4162260992708043, 'average': 20.443422363009894, 'min': 19.622, 'max': 21.4022}}
2020-12-07 19:39:47,503 - callbacks - DEBUG - done with read {'measurement_time': {'start': 6903369380322917376, 'stop': 6903369381177616384}, 'FORT': {'standard_deviation': 0.22923055410786114, 'average': 21.765853114407957, 'min': 21.0324, 'max': 22.2578}}
2020-12-07 19:39:50,364 - callbacks - DEBUG - done with read {'measurement_time': {'start': 6903353917856536576, 'stop': 6903353918711234560}, 'FORT': {'standard_deviation': 0.07923935399085553, 'average': 21.75639397222222, 'min': 21.4179, 'max': 22.0416}}
2020-12-07 19:39:52,841 - callbacks - DEBUG - done with read {'measurement_time': {'start': 6903338455763817472, 'stop': 6903338456678645760}, 'FORT': {'standard_deviation': 0.11161936633580577, 'average': 21.59934553283698, 'min': 21.1672, 'max': 21.9319}}
2020-12-07 19:39:55,991 - callbacks - DEBUG - done with read {'measurement_time': {'start': 6903322994074825728, 'stop': 6903322994920933376}, 'FORT': {'standard_deviation': 0.18723280562307285, 'average': 21.133247699744416, 'min': 20.6626, 'max': 21.6686}}
2020-12-07 19:39:59,153 - callbacks - DEBUG - done with read {'measurement_time': {'start': 6903307532012171264, 'stop': 6903307532875459584}, 'FORT': {'standard_deviation': 0.15912924524387997, 'average': 20.608602428182472, 'min': 20.1423, 'max': 21.0982}}
